Workbook
Name lst_Anios: Parametros!$P$2:$P$28
Name lst_Categorias: Parametros!$F$4:$F$19
Name lst_Conceptos: Parametros!$H$4:$H$28
Name lst_Estados: Parametros!$J$9:$J$13
Name lst_Medios: Parametros!$D$12:$D$17
Name lst_Meses: Parametros!$B$4:$B$15
Name lst_Secciones: Parametros!$M$4:$M$9
Name lst_Tipos: Parametros!$D$4:$D$9

Sheet Inicio
B1: PLANTILLA DE FINANZAS PERSONALES
B2: Control mensual de ingresos, gastos, ahorros, inversiones y deudas
D4: CÓMO USARLA
D5: 1 | E5: En Presupuesto Mensual selecciona el año en D2 y el mes en F2 con desplegable.
D6: 2 | E6: Carga cada presupuesto mensual en Plan Mensual. Cada fila guarda año, mes, sección, tipo, categoría, concepto y presupuesto.
D7: 3 | E7: Registra los movimientos reales en Movimientos. El mes y el año se calculan solos desde la fecha.
D8: 4 | E8: Ahorros e inversiones se muestran acumulados hasta el mes seleccionado; gastos, ingresos y deudas se muestran por mes.
D9: 5 | E9: En Resumen Anual selecciona el año de forma independiente en B3.

Sheet Presupuesto Mensual
A1: FINANZAS PERSONALES | H1: SUMATORIA INGRESOS | K1: SUMATORIA GASTOS | O1: SALDO REAL
A2: Botonera Presupuesto Mensual → | C2: Año | D2: 2026 | E2: Mes | F2: Enero | H2: =C32 -> 2500000 | K2: =C66+J56+Q82+SUMIFS(Movimientos!$J$2:$J$2000,Movimientos!$C$2:$C$2000,$A$119,Movimientos!$E$2:$E$2000,$D$2,Movimientos!$F$2:$F$2000,"Ahorros",Movimientos!$K$2:$K$2000,"<>Anulado")+SUMIFS(Movimientos!$J$2:$J$2000,Movimientos!$C$2:$C$2000,$A$119,Movimientos!$E$2:$E$2000,$D$2,Movimientos!$F$2:$F$2000,"Inversiones",Movimientos!$K$2:$K$2000,"<>Anulado") -> 1030000 | O2: =H2-K2 -> 1470000 | T2: Necesidades | U2: =Q20 -> 1030000 | V2: =R20 -> 1030000
A3: =UPPER($F$2) -> ENERO | T3: Deseos | U3: =Q21 -> 0 | V3: =R21 -> 0
A4: VERSIÓN LISTA PARA USO | T4: Ahorros+Inv. | U4: =Q22 -> 0 | V4: =R22 -> 0
A5: Selecciona año y mes. Presupuesto se carga desde Plan Mensual; movimientos reales desde Movimientos. Ahorros e inversiones se muestran acumulados al mes seleccionado. | H5: PRESUPUESTO POR ASIGNAR | K5: TOTAL GASTADO | O5: % AHORRO REAL | T5: Deudas | U5: =P82 -> 0 | V5: =Q82 -> 0
H6: =B32-(B66+I56+P82+SUMIFS('Plan Mensual'!$I$2:$I$2000,'Plan Mensual'!$B$2:$B$2000,$D$2,'Plan Mensual'!$C$2:$C$2000,$A$119,'Plan Mensual'!$E$2:$E$2000,"Ahorros")+SUMIFS('Plan Mensual'!$I$2:$I$2000,'Plan Mensual'!$B$2:$B$2000,$D$2,'Plan Mensual'!$C$2:$C$2000,$A$119,'Plan Mensual'!$E$2:$E$2000,"Inversiones")) -> 1470000 | K6: =K2 -> 1030000 | O6: =IFERROR((C91+J81)/SUMIFS(Movimientos!$J$2:$J$2000,Movimientos!$C$2:$C$2000,"<="&$A$119,Movimientos!$E$2:$E$2000,$D$2,Movimientos!$F$2:$F$2000,"Ingreso",Movimientos!$K$2:$K$2000,"<>Anulado"),0) -> 0
T8: ¿EN QUÉ SE TE VA LA PLATA? | Y8: __helper (no editar)
T9: Tus 5 mayores gastos del mes, del más grande al más chico | Y9: Hogar | Z9: =SUMIF($E$36:$E$65,$Y9,$C$36:$C$65)+SUMIF($L$26:$L$55,$Y9,$J$26:$J$55)+SUMIF($S$62:$S$81,$Y9,$Q$62:$Q$81) -> 1000000 | AA9: =$Z9-ROW()*0.0001 -> 1000000
A10: INGRESOS | O10: OBJETIVO | T10: Categoría | U10: Gastaste | V10: Comparación | Y10: Servicios | Z10: =SUMIF($E$36:$E$65,$Y10,$C$36:$C$65)+SUMIF($L$26:$L$55,$Y10,$J$26:$J$55)+SUMIF($S$62:$S$81,$Y10,$Q$62:$Q$81) -> 30000 | AA10: =$Z10-ROW()*0.0001 -> 29999.999
A11: Concepto | B11: Presupuesto | C11: Actual | D11: Tipo | E11: Categoría | O11: Tipo | P11: % | Q11: Presupuesto | R11: Por asignar | T11: =IFERROR(IF(LARGE($Z$9:$Z$21,1)<=0,"",INDEX($Y$9:$Y$21,MATCH(LARGE($AA$9:$AA$21,1),$AA$9:$AA$21,0))),"") -> Hogar | U11: =IFERROR(IF(LARGE($Z$9:$Z$21,1)<=0,"",INDEX($Z$9:$Z$21,MATCH(LARGE($AA$9:$AA$21,1),$AA$9:$AA$21,0))),"") -> 1000000 | V11: =IFERROR(IF(LARGE($Z$9:$Z$21,1)<=0,"",REPT("█",MAX(1,ROUND(INDEX($Z$9:$Z$21,MATCH(LARGE($AA$9:$AA$21,1),$AA$9:$AA$21,0))/MAX($Z$9:$Z$21)*10,0)))),"") -> ██████████ | Y11: Suscripciones | Z11: =SUMIF($E$36:$E$65,$Y11,$C$36:$C$65)+SUMIF($L$26:$L$55,$Y11,$J$26:$J$55)+SUMIF($S$62:$S$81,$Y11,$Q$62:$Q$81) -> 0 | AA11: =$Z11-ROW()*0.0001 -> -0.0011
A12: Sueldo | B12: =IF($A12="","",SUMIFS('Plan Mensual'!$I$2:$I$2000,'Plan Mensual'!$B$2:$B$2000,$D$2,'Plan Mensual'!$C$2:$C$2000,$A$119,'Plan Mensual'!$E$2:$E$2000,"Ingresos",'Plan Mensual'!$F$2:$F$2000,$D12,'Plan Mensual'!$G$2:$G$2000,$E12,'Plan Mensual'!$H$2:$H$2000,$A12)) -> 2000000 | C12: =IF($A12="","",SUMIFS(Movimientos!$J$2:$J$2000,Movimientos!$C$2:$C$2000,$A$119,Movimientos!$E$2:$E$2000,$D$2,Movimientos!$F$2:$F$2000,$D12,Movimientos!$G$2:$G$2000,$E12,Movimientos!$H$2:$H$2000,$A12,Movimientos!$K$2:$K$2000,"<>Anulado")) -> 2000000 | D12: Ingreso | E12: Sueldo | O12: Necesidades | P12: =Parametros!K4 -> 0.5 | Q12: =$B$32*P12 -> 1250000 | R12: =Q12-SUMIFS('Plan Mensual'!$I$2:$I$2000,'Plan Mensual'!$B$2:$B$2000,$D$2,'Plan Mensual'!$C$2:$C$2000,$A$119,'Plan Mensual'!$F$2:$F$2000,O12) -> 220000 | T12: =IFERROR(IF(LARGE($Z$9:$Z$21,2)<=0,"",INDEX($Y$9:$Y$21,MATCH(LARGE($AA$9:$AA$21,2),$AA$9:$AA$21,0))),"") -> Servicios | U12: =IFERROR(IF(LARGE($Z$9:$Z$21,2)<=0,"",INDEX($Z$9:$Z$21,MATCH(LARGE($AA$9:$AA$21,2),$AA$9:$AA$21,0))),"") -> 30000 | V12: =IFERROR(IF(LARGE($Z$9:$Z$21,2)<=0,"",REPT("█",MAX(1,ROUND(INDEX($Z$9:$Z$21,MATCH(LARGE($AA$9:$AA$21,2),$AA$9:$AA$21,0))/MAX($Z$9:$Z$21)*10,0)))),"") -> █ | Y12: Alimentación | Z12: =SUMIF($E$36:$E$65,$Y12,$C$36:$C$65)+SUMIF($L$26:$L$55,$Y12,$J$26:$J$55)+SUMIF($S$62:$S$81,$Y12,$Q$62:$Q$81) -> 0 | AA12: =$Z12-ROW()*0.0001 -> -0.0012
A13: Freelance | B13: =IF($A13="","",SUMIFS('Plan Mensual'!$I$2:$I$2000,'Plan Mensual'!$B$2:$B$2000,$D$2,'Plan Mensual'!$C$2:$C$2000,$A$119,'Plan Mensual'!$E$2:$E$2000,"Ingresos",'Plan Mensual'!$F$2:$F$2000,$D13,'Plan Mensual'!$G$2:$G$2000,$E13,'Plan Mensual'!$H$2:$H$2000,$A13)) -> 500000 | C13: =IF($A13="","",SUMIFS(Movimientos!$J$2:$J$2000,Movimientos!$C$2:$C$2000,$A$119,Movimientos!$E$2:$E$2000,$D$2,Movimientos!$F$2:$F$2000,$D13,Movimientos!$G$2:$G$2000,$E13,Movimientos!$H$2:$H$2000,$A13,Movimientos!$K$2:$K$2000,"<>Anulado")) -> 500000 | D13: Ingreso | E13: Freelance | O13: Deseos | P13: =Parametros!K5 -> 0.3 | Q13: =$B$32*P13 -> 750000 | R13: =Q13-SUMIFS('Plan Mensual'!$I$2:$I$2000,'Plan Mensual'!$B$2:$B$2000,$D$2,'Plan Mensual'!$C$2:$C$2000,$A$119,'Plan Mensual'!$F$2:$F$2000,O13) -> 750000 | T13: =IFERROR(IF(LARGE($Z$9:$Z$21,3)<=0,"",INDEX($Y$9:$Y$21,MATCH(LARGE($AA$9:$AA$21,3),$AA$9:$AA$21,0))),"") | U13: =IFERROR(IF(LARGE($Z$9:$Z$21,3)<=0,"",INDEX($Z$9:$Z$21,MATCH(LARGE($AA$9:$AA$21,3),$AA$9:$AA$21,0))),"") | V13: =IFERROR(IF(LARGE($Z$9:$Z$21,3)<=0,"",REPT("█",MAX(1,ROUND(INDEX($Z$9:$Z$21,MATCH(LARGE($AA$9:$AA$21,3),$AA$9:$AA$21,0))/MAX($Z$9:$Z$21)*10,0)))),"") | Y13: Transporte | Z13: =SUMIF($E$36:$E$65,$Y13,$C$36:$C$65)+SUMIF($L$26:$L$55,$Y13,$J$26:$J$55)+SUMIF($S$62:$S$81,$Y13,$Q$62:$Q$81) -> 0 | AA13: =$Z13-ROW()*0.0001 -> -0.0013
A14: Ingreso extra | B14: =IF($A14="","",SUMIFS('Plan Mensual'!$I$2:$I$2000,'Plan Mensual'!$B$2:$B$2000,$D$2,'Plan Mensual'!$C$2:$C$2000,$A$119,'Plan Mensual'!$E$2:$E$2000,"Ingresos",'Plan Mensual'!$F$2:$F$2000,$D14,'Plan Mensual'!$G$2:$G$2000,$E14,'Plan Mensual'!$H$2:$H$2000,$A14)) -> 0 | C14: =IF($A14="","",SUMIFS(Movimientos!$J$2:$J$2000,Movimientos!$C$2:$C$2000,$A$119,Movimientos!$E$2:$E$2000,$D$2,Movimientos!$F$2:$F$2000,$D14,Movimientos!$G$2:$G$2000,$E14,Movimientos!$H$2:$H$2000,$A14,Movimientos!$K$2:$K$2000,"<>Anulado")) -> 0 | D14: Ingreso | E14: Otro | O14: Ahorros | P14: =Parametros!K6 -> 0.2 | Q14: =$B$32*P14 -> 500000 | R14: =Q14-SUMIFS('Plan Mensual'!$I$2:$I$2000,'Plan Mensual'!$B$2:$B$2000,$D$2,'Plan Mensual'!$C$2:$C$2000,$A$119,'Plan Mensual'!$F$2:$F$2000,"Ahorros")-SUMIFS('Plan Mensual'!$I$2:$I$2000,'Plan Mensual'!$B$2:$B$2000,$D$2,'Plan Mensual'!$C$2:$C$2000,$A$119,'Plan Mensual'!$F$2:$F$2000,"Inversiones") -> 500000 | T14: =IFERROR(IF(LARGE($Z$9:$Z$21,4)<=0,"",INDEX($Y$9:$Y$21,MATCH(LARGE($AA$9:$AA$21,4),$AA$9:$AA$21,0))),"") | U14: =IFERROR(IF(LARGE($Z$9:$Z$21,4)<=0,"",INDEX($Z$9:$Z$21,MATCH(LARGE($AA$9:$AA$21,4),$AA$9:$AA$21,0))),"") | V14: =IFERROR(IF(LARGE($Z$9:$Z$21,4)<=0,"",REPT("█",MAX(1,ROUND(INDEX($Z$9:$Z$21,MATCH(LARGE($AA$9:$AA$21,4),$AA$9:$AA$21,0))/MAX($Z$9:$Z$21)*10,0)))),"") | Y14: Entretenimiento | Z14: =SUMIF($E$36:$E$65,$Y14,$C$36:$C$65)+SUMIF($L$26:$L$55,$Y14,$J$26:$J$55)+SUMIF($S$62:$S$81,$Y14,$Q$62:$Q$81) -> 0 | AA14: =$Z14-ROW()*0.0001 -> -0.0014
B15: =IF($A15="","",SUMIFS('Plan Mensual'!$I$2:$I$2000,'Plan Mensual'!$B$2:$B$2000,$D$2,'Plan Mensual'!$C$2:$C$2000,$A$119,'Plan Mensual'!$E$2:$E$2000,"Ingresos",'Plan Mensual'!$F$2:$F$2000,$D15,'Plan Mensual'!$G$2:$G$2000,$E15,'Plan Mensual'!$H$2:$H$2000,$A15)) | C15: =IF($A15="","",SUMIFS(Movimientos!$J$2:$J$2000,Movimientos!$C$2:$C$2000,$A$119,Movimientos!$E$2:$E$2000,$D$2,Movimientos!$F$2:$F$2000,$D15,Movimientos!$G$2:$G$2000,$E15,Movimientos!$H$2:$H$2000,$A15,Movimientos!$K$2:$K$2000,"<>Anulado")) | D15: Ingreso | E15: Otro | O15: TOTAL | P15: =SUM(P12:P14) -> 1 | Q15: =SUM(Q12:Q14) -> 2500000 | R15: =SUM(R12:R14) -> 1470000 | T15: =IFERROR(IF(LARGE($Z$9:$Z$21,5)<=0,"",INDEX($Y$9:$Y$21,MATCH(LARGE($AA$9:$AA$21,5),$AA$9:$AA$21,0))),"") | U15: =IFERROR(IF(LARGE($Z$9:$Z$21,5)<=0,"",INDEX($Z$9:$Z$21,MATCH(LARGE($AA$9:$AA$21,5),$AA$9:$AA$21,0))),"") | V15: =IFERROR(IF(LARGE($Z$9:$Z$21,5)<=0,"",REPT("█",MAX(1,ROUND(INDEX($Z$9:$Z$21,MATCH(LARGE($AA$9:$AA$21,5),$AA$9:$AA$21,0))/MAX($Z$9:$Z$21)*10,0)))),"") | Y15: Salud | Z15: =SUMIF($E$36:$E$65,$Y15,$C$36:$C$65)+SUMIF($L$26:$L$55,$Y15,$J$26:$J$55)+SUMIF($S$62:$S$81,$Y15,$Q$62:$Q$81) -> 0 | AA15: =$Z15-ROW()*0.0001 -> -0.0015
B16: =IF($A16="","",SUMIFS('Plan Mensual'!$I$2:$I$2000,'Plan Mensual'!$B$2:$B$2000,$D$2,'Plan Mensual'!$C$2:$C$2000,$A$119,'Plan Mensual'!$E$2:$E$2000,"Ingresos",'Plan Mensual'!$F$2:$F$2000,$D16,'Plan Mensual'!$G$2:$G$2000,$E16,'Plan Mensual'!$H$2:$H$2000,$A16)) | C16: =IF($A16="","",SUMIFS(Movimientos!$J$2:$J$2000,Movimientos!$C$2:$C$2000,$A$119,Movimientos!$E$2:$E$2000,$D$2,Movimientos!$F$2:$F$2000,$D16,Movimientos!$G$2:$G$2000,$E16,Movimientos!$H$2:$H$2000,$A16,Movimientos!$K$2:$K$2000,"<>Anulado")) | D16: Ingreso | E16: Otro | Y16: Educación | Z16: =SUMIF($E$36:$E$65,$Y16,$C$36:$C$65)+SUMIF($L$26:$L$55,$Y16,$J$26:$J$55)+SUMIF($S$62:$S$81,$Y16,$Q$62:$Q$81) -> 0 | AA16: =$Z16-ROW()*0.0001 -> -0.0016
B17: =IF($A17="","",SUMIFS('Plan Mensual'!$I$2:$I$2000,'Plan Mensual'!$B$2:$B$2000,$D$2,'Plan Mensual'!$C$2:$C$2000,$A$119,'Plan Mensual'!$E$2:$E$2000,"Ingresos",'Plan Mensual'!$F$2:$F$2000,$D17,'Plan Mensual'!$G$2:$G$2000,$E17,'Plan Mensual'!$H$2:$H$2000,$A17)) | C17: =IF($A17="","",SUMIFS(Movimientos!$J$2:$J$2000,Movimientos!$C$2:$C$2000,$A$119,Movimientos!$E$2:$E$2000,$D$2,Movimientos!$F$2:$F$2000,$D17,Movimientos!$G$2:$G$2000,$E17,Movimientos!$H$2:$H$2000,$A17,Movimientos!$K$2:$K$2000,"<>Anulado")) | D17: Ingreso | E17: Otro | T17: TU MES EN SIMPLE | Y17: Cuidado Personal | Z17: =SUMIF($E$36:$E$65,$Y17,$C$36:$C$65)+SUMIF($L$26:$L$55,$Y17,$J$26:$J$55)+SUMIF($S$62:$S$81,$Y17,$Q$62:$Q$81) -> 0 | AA17: =$Z17-ROW()*0.0001 -> -0.0017
B18: =IF($A18="","",SUMIFS('Plan Mensual'!$I$2:$I$2000,'Plan Mensual'!$B$2:$B$2000,$D$2,'Plan Mensual'!$C$2:$C$2000,$A$119,'Plan Mensual'!$E$2:$E$2000,"Ingresos",'Plan Mensual'!$F$2:$F$2000,$D18,'Plan Mensual'!$G$2:$G$2000,$E18,'Plan Mensual'!$H$2:$H$2000,$A18)) | C18: =IF($A18="","",SUMIFS(Movimientos!$J$2:$J$2000,Movimientos!$C$2:$C$2000,$A$119,Movimientos!$E$2:$E$2000,$D$2,Movimientos!$F$2:$F$2000,$D18,Movimientos!$G$2:$G$2000,$E18,Movimientos!$H$2:$H$2000,$A18,Movimientos!$K$2:$K$2000,"<>Anulado")) | D18: Ingreso | E18: Otro | O18: SUMATORIA | T18: Gastaste en total | U18: =$C$66+$J$56+$Q$82 -> 1030000 | V18: fijos + diario + deudas | Y18: Ocio | Z18: =SUMIF($E$36:$E$65,$Y18,$C$36:$C$65)+SUMIF($L$26:$L$55,$Y18,$J$26:$J$55)+SUMIF($S$62:$S$81,$Y18,$Q$62:$Q$81) -> 0 | AA18: =$Z18-ROW()*0.0001 -> -0.0018
B19: =IF($A19="","",SUMIFS('Plan Mensual'!$I$2:$I$2000,'Plan Mensual'!$B$2:$B$2000,$D$2,'Plan Mensual'!$C$2:$C$2000,$A$119,'Plan Mensual'!$E$2:$E$2000,"Ingresos",'Plan Mensual'!$F$2:$F$2000,$D19,'Plan Mensual'!$G$2:$G$2000,$E19,'Plan Mensual'!$H$2:$H$2000,$A19)) | C19: =IF($A19="","",SUMIFS(Movimientos!$J$2:$J$2000,Movimientos!$C$2:$C$2000,$A$119,Movimientos!$E$2:$E$2000,$D$2,Movimientos!$F$2:$F$2000,$D19,Movimientos!$G$2:$G$2000,$E19,Movimientos!$H$2:$H$2000,$A19,Movimientos!$K$2:$K$2000,"<>Anulado")) | D19: Ingreso | E19: Otro | O19: Tipo | P19: % | Q19: Presupuesto | R19: Gastado | T19: Guardaste | U19: =SUMIFS(Movimientos!$J$2:$J$2000,Movimientos!$C$2:$C$2000,$A$119,Movimientos!$E$2:$E$2000,$D$2,Movimientos!$F$2:$F$2000,"Ahorros",Movimientos!$K$2:$K$2000,"<>Anulado")+SUMIFS(Movimientos!$J$2:$J$2000,Movimientos!$C$2:$C$2000,$A$119,Movimientos!$E$2:$E$2000,$D$2,Movimientos!$F$2:$F$2000,"Inversiones",Movimientos!$K$2:$K$2000,"<>Anulado") -> 0 | V19: ahorro + inversión | Y19: Tarjeta Crédito | Z19: =SUMIF($E$36:$E$65,$Y19,$C$36:$C$65)+SUMIF($L$26:$L$55,$Y19,$J$26:$J$55)+SUMIF($S$62:$S$81,$Y19,$Q$62:$Q$81) -> 0 | AA19: =$Z19-ROW()*0.0001 -> -0.0019
B20: =IF($A20="","",SUMIFS('Plan Mensual'!$I$2:$I$2000,'Plan Mensual'!$B$2:$B$2000,$D$2,'Plan Mensual'!$C$2:$C$2000,$A$119,'Plan Mensual'!$E$2:$E$2000,"Ingresos",'Plan Mensual'!$F$2:$F$2000,$D20,'Plan Mensual'!$G$2:$G$2000,$E20,'Plan Mensual'!$H$2:$H$2000,$A20)) | C20: =IF($A20="","",SUMIFS(Movimientos!$J$2:$J$2000,Movimientos!$C$2:$C$2000,$A$119,Movimientos!$E$2:$E$2000,$D$2,Movimientos!$F$2:$F$2000,$D20,Movimientos!$G$2:$G$2000,$E20,Movimientos!$H$2:$H$2000,$A20,Movimientos!$K$2:$K$2000,"<>Anulado")) | D20: Ingreso | E20: Otro | O20: Necesidades | P20: =IFERROR(Q20/$B$32,0) -> 0.412 | Q20: =SUMIFS('Plan Mensual'!$I$2:$I$2000,'Plan Mensual'!$B$2:$B$2000,$D$2,'Plan Mensual'!$C$2:$C$2000,$A$119,'Plan Mensual'!$F$2:$F$2000,"Necesidades") -> 1030000 | R20: =SUMIFS(Movimientos!$J$2:$J$2000,Movimientos!$C$2:$C$2000,$A$119,Movimientos!$E$2:$E$2000,$D$2,Movimientos!$F$2:$F$2000,"Necesidades",Movimientos!$K$2:$K$2000,"<>Anulado") -> 1030000 | T20: Te quedó disponible | U20: =$O$2 -> 1470000 | V20: =IF($O$2>=0,"Te sobró este mes","Te faltó: gastaste de más") -> Te sobró este mes | Y20: Préstamo | Z20: =SUMIF($E$36:$E$65,$Y20,$C$36:$C$65)+SUMIF($L$26:$L$55,$Y20,$J$26:$J$55)+SUMIF($S$62:$S$81,$Y20,$Q$62:$Q$81) -> 0 | AA20: =$Z20-ROW()*0.0001 -> -0.002
B21: =IF($A21="","",SUMIFS('Plan Mensual'!$I$2:$I$2000,'Plan Mensual'!$B$2:$B$2000,$D$2,'Plan Mensual'!$C$2:$C$2000,$A$119,'Plan Mensual'!$E$2:$E$2000,"Ingresos",'Plan Mensual'!$F$2:$F$2000,$D21,'Plan Mensual'!$G$2:$G$2000,$E21,'Plan Mensual'!$H$2:$H$2000,$A21)) | C21: =IF($A21="","",SUMIFS(Movimientos!$J$2:$J$2000,Movimientos!$C$2:$C$2000,$A$119,Movimientos!$E$2:$E$2000,$D$2,Movimientos!$F$2:$F$2000,$D21,Movimientos!$G$2:$G$2000,$E21,Movimientos!$H$2:$H$2000,$A21,Movimientos!$K$2:$K$2000,"<>Anulado")) | D21: Ingreso | E21: Otro | O21: Deseos | P21: =IFERROR(Q21/$B$32,0) -> 0 | Q21: =SUMIFS('Plan Mensual'!$I$2:$I$2000,'Plan Mensual'!$B$2:$B$2000,$D$2,'Plan Mensual'!$C$2:$C$2000,$A$119,'Plan Mensual'!$F$2:$F$2000,"Deseos") -> 0 | R21: =SUMIFS(Movimientos!$J$2:$J$2000,Movimientos!$C$2:$C$2000,$A$119,Movimientos!$E$2:$E$2000,$D$2,Movimientos!$F$2:$F$2000,"Deseos",Movimientos!$K$2:$K$2000,"<>Anulado") -> 0 | T21: Inversión | U21: =IF($T21="","",SUMIF($E$36:$E$65,$T21,$B$36:$B$65)+SUMIF($L$26:$L$55,$T21,$I$26:$I$55)+SUMIF($E$71:$E$90,$T21,$B$71:$B$90)+SUMIF($L$61:$L$80,$T21,$I$61:$I$80)+SUMIF($S$62:$S$81,$T21,$P$62:$P$81)) -> 0 | V21: =IF($T21="","",SUMIF($E$36:$E$65,$T21,$C$36:$C$65)+SUMIF($L$26:$L$55,$T21,$J$26:$J$55)+SUMIF($E$71:$E$90,$T21,$C$71:$C$90)+SUMIF($L$61:$L$80,$T21,$J$61:$J$80)+SUMIF($S$62:$S$81,$T21,$Q$62:$Q$81)) -> 0 | W21: =IFERROR(V21/$H$2,0) -> 0 | Y21: Otro | Z21: =SUMIF($E$36:$E$65,$Y21,$C$36:$C$65)+SUMIF($L$26:$L$55,$Y21,$J$26:$J$55)+SUMIF($S$62:$S$81,$Y21,$Q$62:$Q$81) -> 0 | AA21: =$Z21-ROW()*0.0001 -> -0.0021
B22: =IF($A22="","",SUMIFS('Plan Mensual'!$I$2:$I$2000,'Plan Mensual'!$B$2:$B$2000,$D$2,'Plan Mensual'!$C$2:$C$2000,$A$119,'Plan Mensual'!$E$2:$E$2000,"Ingresos",'Plan Mensual'!$F$2:$F$2000,$D22,'Plan Mensual'!$G$2:$G$2000,$E22,'Plan Mensual'!$H$2:$H$2000,$A22)) | C22: =IF($A22="","",SUMIFS(Movimientos!$J$2:$J$2000,Movimientos!$C$2:$C$2000,$A$119,Movimientos!$E$2:$E$2000,$D$2,Movimientos!$F$2:$F$2000,$D22,Movimientos!$G$2:$G$2000,$E22,Movimientos!$H$2:$H$2000,$A22,Movimientos!$K$2:$K$2000,"<>Anulado")) | D22: Ingreso | E22: Otro | O22: Ahorros+Inv. | P22: =IFERROR(Q22/$B$32,0) -> 0 | Q22: =SUMIFS('Plan Mensual'!$I$2:$I$2000,'Plan Mensual'!$B$2:$B$2000,$D$2,'Plan Mensual'!$C$2:$C$2000,"<="&$A$119,'Plan Mensual'!$F$2:$F$2000,"Ahorros")+SUMIFS('Plan Mensual'!$I$2:$I$2000,'Plan Mensual'!$B$2:$B$2000,$D$2,'Plan Mensual'!$C$2:$C$2000,"<="&$A$119,'Plan Mensual'!$F$2:$F$2000,"Inversiones") -> 0 | R22: =SUMIFS(Movimientos!$J$2:$J$2000,Movimientos!$C$2:$C$2000,"<="&$A$119,Movimientos!$E$2:$E$2000,$D$2,Movimientos!$F$2:$F$2000,"Ahorros",Movimientos!$K$2:$K$2000,"<>Anulado")+SUMIFS(Movimientos!$J$2:$J$2000,Movimientos!$C$2:$C$2000,"<="&$A$119,Movimientos!$E$2:$E$2000,$D$2,Movimientos!$F$2:$F$2000,"Inversiones",Movimientos!$K$2:$K$2000,"<>Anulado") -> 0 | T22: Tarjeta Crédito | U22: =IF($T22="","",SUMIF($E$36:$E$65,$T22,$B$36:$B$65)+SUMIF($L$26:$L$55,$T22,$I$26:$I$55)+SUMIF($E$71:$E$90,$T22,$B$71:$B$90)+SUMIF($L$61:$L$80,$T22,$I$61:$I$80)+SUMIF($S$62:$S$81,$T22,$P$62:$P$81)) -> 0 | V22: =IF($T22="","",SUMIF($E$36:$E$65,$T22,$C$36:$C$65)+SUMIF($L$26:$L$55,$T22,$J$26:$J$55)+SUMIF($E$71:$E$90,$T22,$C$71:$C$90)+SUMIF($L$61:$L$80,$T22,$J$61:$J$80)+SUMIF($S$62:$S$81,$T22,$Q$62:$Q$81)) -> 0 | W22: =IFERROR(V22/$H$2,0) -> 0
B23: =IF($A23="","",SUMIFS('Plan Mensual'!$I$2:$I$2000,'Plan Mensual'!$B$2:$B$2000,$D$2,'Plan Mensual'!$C$2:$C$2000,$A$119,'Plan Mensual'!$E$2:$E$2000,"Ingresos",'Plan Mensual'!$F$2:$F$2000,$D23,'Plan Mensual'!$G$2:$G$2000,$E23,'Plan Mensual'!$H$2:$H$2000,$A23)) | C23: =IF($A23="","",SUMIFS(Movimientos!$J$2:$J$2000,Movimientos!$C$2:$C$2000,$A$119,Movimientos!$E$2:$E$2000,$D$2,Movimientos!$F$2:$F$2000,$D23,Movimientos!$G$2:$G$2000,$E23,Movimientos!$H$2:$H$2000,$A23,Movimientos!$K$2:$K$2000,"<>Anulado")) | D23: Ingreso | E23: Otro | O23: TOTAL | P23: =SUM(P20:P22) -> 0.412 | Q23: =SUM(Q20:Q22) -> 1030000 | R23: =SUM(R20:R22) -> 1030000 | T23: Préstamo | U23: =IF($T23="","",SUMIF($E$36:$E$65,$T23,$B$36:$B$65)+SUMIF($L$26:$L$55,$T23,$I$26:$I$55)+SUMIF($E$71:$E$90,$T23,$B$71:$B$90)+SUMIF($L$61:$L$80,$T23,$I$61:$I$80)+SUMIF($S$62:$S$81,$T23,$P$62:$P$81)) -> 0 | V23: =IF($T23="","",SUMIF($E$36:$E$65,$T23,$C$36:$C$65)+SUMIF($L$26:$L$55,$T23,$J$26:$J$55)+SUMIF($E$71:$E$90,$T23,$C$71:$C$90)+SUMIF($L$61:$L$80,$T23,$J$61:$J$80)+SUMIF($S$62:$S$81,$T23,$Q$62:$Q$81)) -> 0 | W23: =IFERROR(V23/$H$2,0) -> 0
B24: =IF($A24="","",SUMIFS('Plan Mensual'!$I$2:$I$2000,'Plan Mensual'!$B$2:$B$2000,$D$2,'Plan Mensual'!$C$2:$C$2000,$A$119,'Plan Mensual'!$E$2:$E$2000,"Ingresos",'Plan Mensual'!$F$2:$F$2000,$D24,'Plan Mensual'!$G$2:$G$2000,$E24,'Plan Mensual'!$H$2:$H$2000,$A24)) | C24: =IF($A24="","",SUMIFS(Movimientos!$J$2:$J$2000,Movimientos!$C$2:$C$2000,$A$119,Movimientos!$E$2:$E$2000,$D$2,Movimientos!$F$2:$F$2000,$D24,Movimientos!$G$2:$G$2000,$E24,Movimientos!$H$2:$H$2000,$A24,Movimientos!$K$2:$K$2000,"<>Anulado")) | D24: Ingreso | E24: Otro | H24: GASTOS VARIABLES | T24: Otro | U24: =IF($T24="","",SUMIF($E$36:$E$65,$T24,$B$36:$B$65)+SUMIF($L$26:$L$55,$T24,$I$26:$I$55)+SUMIF($E$71:$E$90,$T24,$B$71:$B$90)+SUMIF($L$61:$L$80,$T24,$I$61:$I$80)+SUMIF($S$62:$S$81,$T24,$P$62:$P$81)) -> 0 | V24: =IF($T24="","",SUMIF($E$36:$E$65,$T24,$C$36:$C$65)+SUMIF($L$26:$L$55,$T24,$J$26:$J$55)+SUMIF($E$71:$E$90,$T24,$C$71:$C$90)+SUMIF($L$61:$L$80,$T24,$J$61:$J$80)+SUMIF($S$62:$S$81,$T24,$Q$62:$Q$81)) -> 0 | W24: =IFERROR(V24/$H$2,0) -> 0
B25: =IF($A25="","",SUMIFS('Plan Mensual'!$I$2:$I$2000,'Plan Mensual'!$B$2:$B$2000,$D$2,'Plan Mensual'!$C$2:$C$2000,$A$119,'Plan Mensual'!$E$2:$E$2000,"Ingresos",'Plan Mensual'!$F$2:$F$2000,$D25,'Plan Mensual'!$G$2:$G$2000,$E25,'Plan Mensual'!$H$2:$H$2000,$A25)) | C25: =IF($A25="","",SUMIFS(Movimientos!$J$2:$J$2000,Movimientos!$C$2:$C$2000,$A$119,Movimientos!$E$2:$E$2000,$D$2,Movimientos!$F$2:$F$2000,$D25,Movimientos!$G$2:$G$2000,$E25,Movimientos!$H$2:$H$2000,$A25,Movimientos!$K$2:$K$2000,"<>Anulado")) | D25: Ingreso | E25: Otro | H25: Concepto | I25: Presupuesto | J25: Gastado | K25: Tipo | L25: Categoría | M25: Control | T25: TOTAL | U25: =SUM(U10:U24) -> 3530000 | V25: =SUM(V10:V24) -> 0 | W25: =IFERROR(V25/$H$2,0) -> 0
B26: =IF($A26="","",SUMIFS('Plan Mensual'!$I$2:$I$2000,'Plan Mensual'!$B$2:$B$2000,$D$2,'Plan Mensual'!$C$2:$C$2000,$A$119,'Plan Mensual'!$E$2:$E$2000,"Ingresos",'Plan Mensual'!$F$2:$F$2000,$D26,'Plan Mensual'!$G$2:$G$2000,$E26,'Plan Mensual'!$H$2:$H$2000,$A26)) | C26: =IF($A26="","",SUMIFS(Movimientos!$J$2:$J$2000,Movimientos!$C$2:$C$2000,$A$119,Movimientos!$E$2:$E$2000,$D$2,Movimientos!$F$2:$F$2000,$D26,Movimientos!$G$2:$G$2000,$E26,Movimientos!$H$2:$H$2000,$A26,Movimientos!$K$2:$K$2000,"<>Anulado")) | D26: Ingreso | E26: Otro | H26: Mercado | I26: =IF($H26="","",SUMIFS('Plan Mensual'!$I$2:$I$2000,'Plan Mensual'!$B$2:$B$2000,$D$2,'Plan Mensual'!$C$2:$C$2000,$A$119,'Plan Mensual'!$E$2:$E$2000,"Gastos Variables",'Plan Mensual'!$F$2:$F$2000,$K26,'Plan Mensual'!$G$2:$G$2000,$L26,'Plan Mensual'!$H$2:$H$2000,$H26)) -> 0 | J26: =IF($H26="","",SUMIFS(Movimientos!$J$2:$J$2000,Movimientos!$C$2:$C$2000,$A$119,Movimientos!$E$2:$E$2000,$D$2,Movimientos!$F$2:$F$2000,$K26,Movimientos!$G$2:$G$2000,$L26,Movimientos!$H$2:$H$2000,$H26,Movimientos!$K$2:$K$2000,"<>Anulado")) -> 0 | K26: Necesidades | L26: Alimentación | M26: =IF(H26="","",IF(I26=0,IF(J26=0,"Sin dato","Sin presupuesto"),IF(J26>I26,"Excede",IF(J26=I26,"Exacto","Dentro")))) -> Sin dato
B27: =IF($A27="","",SUMIFS('Plan Mensual'!$I$2:$I$2000,'Plan Mensual'!$B$2:$B$2000,$D$2,'Plan Mensual'!$C$2:$C$2000,$A$119,'Plan Mensual'!$E$2:$E$2000,"Ingresos",'Plan Mensual'!$F$2:$F$2000,$D27,'Plan Mensual'!$G$2:$G$2000,$E27,'Plan Mensual'!$H$2:$H$2000,$A27)) | C27: =IF($A27="","",SUMIFS(Movimientos!$J$2:$J$2000,Movimientos!$C$2:$C$2000,$A$119,Movimientos!$E$2:$E$2000,$D$2,Movimientos!$F$2:$F$2000,$D27,Movimientos!$G$2:$G$2000,$E27,Movimientos!$H$2:$H$2000,$A27,Movimientos!$K$2:$K$2000,"<>Anulado")) | D27: Ingreso | E27: Otro | H27: Transporte | I27: =IF($H27="","",SUMIFS('Plan Mensual'!$I$2:$I$2000,'Plan Mensual'!$B$2:$B$2000,$D$2,'Plan Mensual'!$C$2:$C$2000,$A$119,'Plan Mensual'!$E$2:$E$2000,"Gastos Variables",'Plan Mensual'!$F$2:$F$2000,$K27,'Plan Mensual'!$G$2:$G$2000,$L27,'Plan Mensual'!$H$2:$H$2000,$H27)) -> 0 | J27: =IF($H27="","",SUMIFS(Movimientos!$J$2:$J$2000,Movimientos!$C$2:$C$2000,$A$119,Movimientos!$E$2:$E$2000,$D$2,Movimientos!$F$2:$F$2000,$K27,Movimientos!$G$2:$G$2000,$L27,Movimientos!$H$2:$H$2000,$H27,Movimientos!$K$2:$K$2000,"<>Anulado")) -> 0 | K27: Necesidades | L27: Transporte | M27: =IF(H27="","",IF(I27=0,IF(J27=0,"Sin dato","Sin presupuesto"),IF(J27>I27,"Excede",IF(J27=I27,"Exacto","Dentro")))) -> Sin dato
B28: =IF($A28="","",SUMIFS('Plan Mensual'!$I$2:$I$2000,'Plan Mensual'!$B$2:$B$2000,$D$2,'Plan Mensual'!$C$2:$C$2000,$A$119,'Plan Mensual'!$E$2:$E$2000,"Ingresos",'Plan Mensual'!$F$2:$F$2000,$D28,'Plan Mensual'!$G$2:$G$2000,$E28,'Plan Mensual'!$H$2:$H$2000,$A28)) | C28: =IF($A28="","",SUMIFS(Movimientos!$J$2:$J$2000,Movimientos!$C$2:$C$2000,$A$119,Movimientos!$E$2:$E$2000,$D$2,Movimientos!$F$2:$F$2000,$D28,Movimientos!$G$2:$G$2000,$E28,Movimientos!$H$2:$H$2000,$A28,Movimientos!$K$2:$K$2000,"<>Anulado")) | D28: Ingreso | E28: Otro | H28: Restaurantes | I28: =IF($H28="","",SUMIFS('Plan Mensual'!$I$2:$I$2000,'Plan Mensual'!$B$2:$B$2000,$D$2,'Plan Mensual'!$C$2:$C$2000,$A$119,'Plan Mensual'!$E$2:$E$2000,"Gastos Variables",'Plan Mensual'!$F$2:$F$2000,$K28,'Plan Mensual'!$G$2:$G$2000,$L28,'Plan Mensual'!$H$2:$H$2000,$H28)) -> 0 | J28: =IF($H28="","",SUMIFS(Movimientos!$J$2:$J$2000,Movimientos!$C$2:$C$2000,$A$119,Movimientos!$E$2:$E$2000,$D$2,Movimientos!$F$2:$F$2000,$K28,Movimientos!$G$2:$G$2000,$L28,Movimientos!$H$2:$H$2000,$H28,Movimientos!$K$2:$K$2000,"<>Anulado")) -> 0 | K28: Deseos | L28: Ocio | M28: =IF(H28="","",IF(I28=0,IF(J28=0,"Sin dato","Sin presupuesto"),IF(J28>I28,"Excede",IF(J28=I28,"Exacto","Dentro")))) -> Sin dato
B29: =IF($A29="","",SUMIFS('Plan Mensual'!$I$2:$I$2000,'Plan Mensual'!$B$2:$B$2000,$D$2,'Plan Mensual'!$C$2:$C$2000,$A$119,'Plan Mensual'!$E$2:$E$2000,"Ingresos",'Plan Mensual'!$F$2:$F$2000,$D29,'Plan Mensual'!$G$2:$G$2000,$E29,'Plan Mensual'!$H$2:$H$2000,$A29)) | C29: =IF($A29="","",SUMIFS(Movimientos!$J$2:$J$2000,Movimientos!$C$2:$C$2000,$A$119,Movimientos!$E$2:$E$2000,$D$2,Movimientos!$F$2:$F$2000,$D29,Movimientos!$G$2:$G$2000,$E29,Movimientos!$H$2:$H$2000,$A29,Movimientos!$K$2:$K$2000,"<>Anulado")) | D29: Ingreso | E29: Otro | H29: Ocio | I29: =IF($H29="","",SUMIFS('Plan Mensual'!$I$2:$I$2000,'Plan Mensual'!$B$2:$B$2000,$D$2,'Plan Mensual'!$C$2:$C$2000,$A$119,'Plan Mensual'!$E$2:$E$2000,"Gastos Variables",'Plan Mensual'!$F$2:$F$2000,$K29,'Plan Mensual'!$G$2:$G$2000,$L29,'Plan Mensual'!$H$2:$H$2000,$H29)) -> 0 | J29: =IF($H29="","",SUMIFS(Movimientos!$J$2:$J$2000,Movimientos!$C$2:$C$2000,$A$119,Movimientos!$E$2:$E$2000,$D$2,Movimientos!$F$2:$F$2000,$K29,Movimientos!$G$2:$G$2000,$L29,Movimientos!$H$2:$H$2000,$H29,Movimientos!$K$2:$K$2000,"<>Anulado")) -> 0 | K29: Deseos | L29: Ocio | M29: =IF(H29="","",IF(I29=0,IF(J29=0,"Sin dato","Sin presupuesto"),IF(J29>I29,"Excede",IF(J29=I29,"Exacto","Dentro")))) -> Sin dato
B30: =IF($A30="","",SUMIFS('Plan Mensual'!$I$2:$I$2000,'Plan Mensual'!$B$2:$B$2000,$D$2,'Plan Mensual'!$C$2:$C$2000,$A$119,'Plan Mensual'!$E$2:$E$2000,"Ingresos",'Plan Mensual'!$F$2:$F$2000,$D30,'Plan Mensual'!$G$2:$G$2000,$E30,'Plan Mensual'!$H$2:$H$2000,$A30)) | C30: =IF($A30="","",SUMIFS(Movimientos!$J$2:$J$2000,Movimientos!$C$2:$C$2000,$A$119,Movimientos!$E$2:$E$2000,$D$2,Movimientos!$F$2:$F$2000,$D30,Movimientos!$G$2:$G$2000,$E30,Movimientos!$H$2:$H$2000,$A30,Movimientos!$K$2:$K$2000,"<>Anulado")) | D30: Ingreso | E30: Otro | H30: Ropa | I30: =IF($H30="","",SUMIFS('Plan Mensual'!$I$2:$I$2000,'Plan Mensual'!$B$2:$B$2000,$D$2,'Plan Mensual'!$C$2:$C$2000,$A$119,'Plan Mensual'!$E$2:$E$2000,"Gastos Variables",'Plan Mensual'!$F$2:$F$2000,$K30,'Plan Mensual'!$G$2:$G$2000,$L30,'Plan Mensual'!$H$2:$H$2000,$H30)) -> 0 | J30: =IF($H30="","",SUMIFS(Movimientos!$J$2:$J$2000,Movimientos!$C$2:$C$2000,$A$119,Movimientos!$E$2:$E$2000,$D$2,Movimientos!$F$2:$F$2000,$K30,Movimientos!$G$2:$G$2000,$L30,Movimientos!$H$2:$H$2000,$H30,Movimientos!$K$2:$K$2000,"<>Anulado")) -> 0 | K30: Deseos | L30: Cuidado Personal | M30: =IF(H30="","",IF(I30=0,IF(J30=0,"Sin dato","Sin presupuesto"),IF(J30>I30,"Excede",IF(J30=I30,"Exacto","Dentro")))) -> Sin dato
B31: =IF($A31="","",SUMIFS('Plan Mensual'!$I$2:$I$2000,'Plan Mensual'!$B$2:$B$2000,$D$2,'Plan Mensual'!$C$2:$C$2000,$A$119,'Plan Mensual'!$E$2:$E$2000,"Ingresos",'Plan Mensual'!$F$2:$F$2000,$D31,'Plan Mensual'!$G$2:$G$2000,$E31,'Plan Mensual'!$H$2:$H$2000,$A31)) | C31: =IF($A31="","",SUMIFS(Movimientos!$J$2:$J$2000,Movimientos!$C$2:$C$2000,$A$119,Movimientos!$E$2:$E$2000,$D$2,Movimientos!$F$2:$F$2000,$D31,Movimientos!$G$2:$G$2000,$E31,Movimientos!$H$2:$H$2000,$A31,Movimientos!$K$2:$K$2000,"<>Anulado")) | D31: Ingreso | E31: Otro | I31: =IF($H31="","",SUMIFS('Plan Mensual'!$I$2:$I$2000,'Plan Mensual'!$B$2:$B$2000,$D$2,'Plan Mensual'!$C$2:$C$2000,$A$119,'Plan Mensual'!$E$2:$E$2000,"Gastos Variables",'Plan Mensual'!$F$2:$F$2000,$K31,'Plan Mensual'!$G$2:$G$2000,$L31,'Plan Mensual'!$H$2:$H$2000,$H31)) | J31: =IF($H31="","",SUMIFS(Movimientos!$J$2:$J$2000,Movimientos!$C$2:$C$2000,$A$119,Movimientos!$E$2:$E$2000,$D$2,Movimientos!$F$2:$F$2000,$K31,Movimientos!$G$2:$G$2000,$L31,Movimientos!$H$2:$H$2000,$H31,Movimientos!$K$2:$K$2000,"<>Anulado")) | M31: =IF(H31="","",IF(I31=0,IF(J31=0,"Sin dato","Sin presupuesto"),IF(J31>I31,"Excede",IF(J31=I31,"Exacto","Dentro"))))
A32: TOTAL | B32: =SUM(B12:B31) -> 2500000 | C32: =SUM(C12:C31) -> 2500000 | I32: =IF($H32="","",SUMIFS('Plan Mensual'!$I$2:$I$2000,'Plan Mensual'!$B$2:$B$2000,$D$2,'Plan Mensual'!$C$2:$C$2000,$A$119,'Plan Mensual'!$E$2:$E$2000,"Gastos Variables",'Plan Mensual'!$F$2:$F$2000,$K32,'Plan Mensual'!$G$2:$G$2000,$L32,'Plan Mensual'!$H$2:$H$2000,$H32)) | J32: =IF($H32="","",SUMIFS(Movimientos!$J$2:$J$2000,Movimientos!$C$2:$C$2000,$A$119,Movimientos!$E$2:$E$2000,$D$2,Movimientos!$F$2:$F$2000,$K32,Movimientos!$G$2:$G$2000,$L32,Movimientos!$H$2:$H$2000,$H32,Movimientos!$K$2:$K$2000,"<>Anulado")) | M32: =IF(H32="","",IF(I32=0,IF(J32=0,"Sin dato","Sin presupuesto"),IF(J32>I32,"Excede",IF(J32=I32,"Exacto","Dentro"))))
I33: =IF($H33="","",SUMIFS('Plan Mensual'!$I$2:$I$2000,'Plan Mensual'!$B$2:$B$2000,$D$2,'Plan Mensual'!$C$2:$C$2000,$A$119,'Plan Mensual'!$E$2:$E$2000,"Gastos Variables",'Plan Mensual'!$F$2:$F$2000,$K33,'Plan Mensual'!$G$2:$G$2000,$L33,'Plan Mensual'!$H$2:$H$2000,$H33)) | J33: =IF($H33="","",SUMIFS(Movimientos!$J$2:$J$2000,Movimientos!$C$2:$C$2000,$A$119,Movimientos!$E$2:$E$2000,$D$2,Movimientos!$F$2:$F$2000,$K33,Movimientos!$G$2:$G$2000,$L33,Movimientos!$H$2:$H$2000,$H33,Movimientos!$K$2:$K$2000,"<>Anulado")) | M33: =IF(H33="","",IF(I33=0,IF(J33=0,"Sin dato","Sin presupuesto"),IF(J33>I33,"Excede",IF(J33=I33,"Exacto","Dentro"))))
A34: GASTOS FIJOS | I34: =IF($H34="","",SUMIFS('Plan Mensual'!$I$2:$I$2000,'Plan Mensual'!$B$2:$B$2000,$D$2,'Plan Mensual'!$C$2:$C$2000,$A$119,'Plan Mensual'!$E$2:$E$2000,"Gastos Variables",'Plan Mensual'!$F$2:$F$2000,$K34,'Plan Mensual'!$G$2:$G$2000,$L34,'Plan Mensual'!$H$2:$H$2000,$H34)) | J34: =IF($H34="","",SUMIFS(Movimientos!$J$2:$J$2000,Movimientos!$C$2:$C$2000,$A$119,Movimientos!$E$2:$E$2000,$D$2,Movimientos!$F$2:$F$2000,$K34,Movimientos!$G$2:$G$2000,$L34,Movimientos!$H$2:$H$2000,$H34,Movimientos!$K$2:$K$2000,"<>Anulado")) | M34: =IF(H34="","",IF(I34=0,IF(J34=0,"Sin dato","Sin presupuesto"),IF(J34>I34,"Excede",IF(J34=I34,"Exacto","Dentro"))))
A35: Concepto | B35: Presupuesto | C35: Gastado | D35: Tipo | E35: Categoría | F35: Control | I35: =IF($H35="","",SUMIFS('Plan Mensual'!$I$2:$I$2000,'Plan Mensual'!$B$2:$B$2000,$D$2,'Plan Mensual'!$C$2:$C$2000,$A$119,'Plan Mensual'!$E$2:$E$2000,"Gastos Variables",'Plan Mensual'!$F$2:$F$2000,$K35,'Plan Mensual'!$G$2:$G$2000,$L35,'Plan Mensual'!$H$2:$H$2000,$H35)) | J35: =IF($H35="","",SUMIFS(Movimientos!$J$2:$J$2000,Movimientos!$C$2:$C$2000,$A$119,Movimientos!$E$2:$E$2000,$D$2,Movimientos!$F$2:$F$2000,$K35,Movimientos!$G$2:$G$2000,$L35,Movimientos!$H$2:$H$2000,$H35,Movimientos!$K$2:$K$2000,"<>Anulado")) | M35: =IF(H35="","",IF(I35=0,IF(J35=0,"Sin dato","Sin presupuesto"),IF(J35>I35,"Excede",IF(J35=I35,"Exacto","Dentro"))))
A36: Arriendo | B36: =IF($A36="","",SUMIFS('Plan Mensual'!$I$2:$I$2000,'Plan Mensual'!$B$2:$B$2000,$D$2,'Plan Mensual'!$C$2:$C$2000,$A$119,'Plan Mensual'!$E$2:$E$2000,"Gastos Fijos",'Plan Mensual'!$F$2:$F$2000,$D36,'Plan Mensual'!$G$2:$G$2000,$E36,'Plan Mensual'!$H$2:$H$2000,$A36)) -> 1000000 | C36: =IF($A36="","",SUMIFS(Movimientos!$J$2:$J$2000,Movimientos!$C$2:$C$2000,$A$119,Movimientos!$E$2:$E$2000,$D$2,Movimientos!$F$2:$F$2000,$D36,Movimientos!$G$2:$G$2000,$E36,Movimientos!$H$2:$H$2000,$A36,Movimientos!$K$2:$K$2000,"<>Anulado")) -> 1000000 | D36: Necesidades | E36: Hogar | F36: =IF(A36="","",IF(B36=0,IF(C36=0,"Sin dato","Sin presupuesto"),IF(C36>B36,"Excede",IF(C36=B36,"Exacto","Dentro")))) -> Exacto | I36: =IF($H36="","",SUMIFS('Plan Mensual'!$I$2:$I$2000,'Plan Mensual'!$B$2:$B$2000,$D$2,'Plan Mensual'!$C$2:$C$2000,$A$119,'Plan Mensual'!$E$2:$E$2000,"Gastos Variables",'Plan Mensual'!$F$2:$F$2000,$K36,'Plan Mensual'!$G$2:$G$2000,$L36,'Plan Mensual'!$H$2:$H$2000,$H36)) | J36: =IF($H36="","",SUMIFS(Movimientos!$J$2:$J$2000,Movimientos!$C$2:$C$2000,$A$119,Movimientos!$E$2:$E$2000,$D$2,Movimientos!$F$2:$F$2000,$K36,Movimientos!$G$2:$G$2000,$L36,Movimientos!$H$2:$H$2000,$H36,Movimientos!$K$2:$K$2000,"<>Anulado")) | M36: =IF(H36="","",IF(I36=0,IF(J36=0,"Sin dato","Sin presupuesto"),IF(J36>I36,"Excede",IF(J36=I36,"Exacto","Dentro"))))
A37: Internet | B37: =IF($A37="","",SUMIFS('Plan Mensual'!$I$2:$I$2000,'Plan Mensual'!$B$2:$B$2000,$D$2,'Plan Mensual'!$C$2:$C$2000,$A$119,'Plan Mensual'!$E$2:$E$2000,"Gastos Fijos",'Plan Mensual'!$F$2:$F$2000,$D37,'Plan Mensual'!$G$2:$G$2000,$E37,'Plan Mensual'!$H$2:$H$2000,$A37)) -> 30000 | C37: =IF($A37="","",SUMIFS(Movimientos!$J$2:$J$2000,Movimientos!$C$2:$C$2000,$A$119,Movimientos!$E$2:$E$2000,$D$2,Movimientos!$F$2:$F$2000,$D37,Movimientos!$G$2:$G$2000,$E37,Movimientos!$H$2:$H$2000,$A37,Movimientos!$K$2:$K$2000,"<>Anulado")) -> 30000 | D37: Necesidades | E37: Servicios | F37: =IF(A37="","",IF(B37=0,IF(C37=0,"Sin dato","Sin presupuesto"),IF(C37>B37,"Excede",IF(C37=B37,"Exacto","Dentro")))) -> Exacto | I37: =IF($H37="","",SUMIFS('Plan Mensual'!$I$2:$I$2000,'Plan Mensual'!$B$2:$B$2000,$D$2,'Plan Mensual'!$C$2:$C$2000,$A$119,'Plan Mensual'!$E$2:$E$2000,"Gastos Variables",'Plan Mensual'!$F$2:$F$2000,$K37,'Plan Mensual'!$G$2:$G$2000,$L37,'Plan Mensual'!$H$2:$H$2000,$H37)) | J37: =IF($H37="","",SUMIFS(Movimientos!$J$2:$J$2000,Movimientos!$C$2:$C$2000,$A$119,Movimientos!$E$2:$E$2000,$D$2,Movimientos!$F$2:$F$2000,$K37,Movimientos!$G$2:$G$2000,$L37,Movimientos!$H$2:$H$2000,$H37,Movimientos!$K$2:$K$2000,"<>Anulado")) | M37: =IF(H37="","",IF(I37=0,IF(J37=0,"Sin dato","Sin presupuesto"),IF(J37>I37,"Excede",IF(J37=I37,"Exacto","Dentro"))))
A38: Movil | B38: =IF($A38="","",SUMIFS('Plan Mensual'!$I$2:$I$2000,'Plan Mensual'!$B$2:$B$2000,$D$2,'Plan Mensual'!$C$2:$C$2000,$A$119,'Plan Mensual'!$E$2:$E$2000,"Gastos Fijos",'Plan Mensual'!$F$2:$F$2000,$D38,'Plan Mensual'!$G$2:$G$2000,$E38,'Plan Mensual'!$H$2:$H$2000,$A38)) -> 0 | C38: =IF($A38="","",SUMIFS(Movimientos!$J$2:$J$2000,Movimientos!$C$2:$C$2000,$A$119,Movimientos!$E$2:$E$2000,$D$2,Movimientos!$F$2:$F$2000,$D38,Movimientos!$G$2:$G$2000,$E38,Movimientos!$H$2:$H$2000,$A38,Movimientos!$K$2:$K$2000,"<>Anulado")) -> 0 | D38: Necesidades | E38: Servicios | F38: =IF(A38="","",IF(B38=0,IF(C38=0,"Sin dato","Sin presupuesto"),IF(C38>B38,"Excede",IF(C38=B38,"Exacto","Dentro")))) -> Sin dato | I38: =IF($H38="","",SUMIFS('Plan Mensual'!$I$2:$I$2000,'Plan Mensual'!$B$2:$B$2000,$D$2,'Plan Mensual'!$C$2:$C$2000,$A$119,'Plan Mensual'!$E$2:$E$2000,"Gastos Variables",'Plan Mensual'!$F$2:$F$2000,$K38,'Plan Mensual'!$G$2:$G$2000,$L38,'Plan Mensual'!$H$2:$H$2000,$H38)) | J38: =IF($H38="","",SUMIFS(Movimientos!$J$2:$J$2000,Movimientos!$C$2:$C$2000,$A$119,Movimientos!$E$2:$E$2000,$D$2,Movimientos!$F$2:$F$2000,$K38,Movimientos!$G$2:$G$2000,$L38,Movimientos!$H$2:$H$2000,$H38,Movimientos!$K$2:$K$2000,"<>Anulado")) | M38: =IF(H38="","",IF(I38=0,IF(J38=0,"Sin dato","Sin presupuesto"),IF(J38>I38,"Excede",IF(J38=I38,"Exacto","Dentro"))))
A39: Servicios básicos | B39: =IF($A39="","",SUMIFS('Plan Mensual'!$I$2:$I$2000,'Plan Mensual'!$B$2:$B$2000,$D$2,'Plan Mensual'!$C$2:$C$2000,$A$119,'Plan Mensual'!$E$2:$E$2000,"Gastos Fijos",'Plan Mensual'!$F$2:$F$2000,$D39,'Plan Mensual'!$G$2:$G$2000,$E39,'Plan Mensual'!$H$2:$H$2000,$A39)) -> 0 | C39: =IF($A39="","",SUMIFS(Movimientos!$J$2:$J$2000,Movimientos!$C$2:$C$2000,$A$119,Movimientos!$E$2:$E$2000,$D$2,Movimientos!$F$2:$F$2000,$D39,Movimientos!$G$2:$G$2000,$E39,Movimientos!$H$2:$H$2000,$A39,Movimientos!$K$2:$K$2000,"<>Anulado")) -> 0 | D39: Necesidades | E39: Servicios | F39: =IF(A39="","",IF(B39=0,IF(C39=0,"Sin dato","Sin presupuesto"),IF(C39>B39,"Excede",IF(C39=B39,"Exacto","Dentro")))) -> Sin dato | I39: =IF($H39="","",SUMIFS('Plan Mensual'!$I$2:$I$2000,'Plan Mensual'!$B$2:$B$2000,$D$2,'Plan Mensual'!$C$2:$C$2000,$A$119,'Plan Mensual'!$E$2:$E$2000,"Gastos Variables",'Plan Mensual'!$F$2:$F$2000,$K39,'Plan Mensual'!$G$2:$G$2000,$L39,'Plan Mensual'!$H$2:$H$2000,$H39)) | J39: =IF($H39="","",SUMIFS(Movimientos!$J$2:$J$2000,Movimientos!$C$2:$C$2000,$A$119,Movimientos!$E$2:$E$2000,$D$2,Movimientos!$F$2:$F$2000,$K39,Movimientos!$G$2:$G$2000,$L39,Movimientos!$H$2:$H$2000,$H39,Movimientos!$K$2:$K$2000,"<>Anulado")) | M39: =IF(H39="","",IF(I39=0,IF(J39=0,"Sin dato","Sin presupuesto"),IF(J39>I39,"Excede",IF(J39=I39,"Exacto","Dentro"))))
A40: Netflix | B40: =IF($A40="","",SUMIFS('Plan Mensual'!$I$2:$I$2000,'Plan Mensual'!$B$2:$B$2000,$D$2,'Plan Mensual'!$C$2:$C$2000,$A$119,'Plan Mensual'!$E$2:$E$2000,"Gastos Fijos",'Plan Mensual'!$F$2:$F$2000,$D40,'Plan Mensual'!$G$2:$G$2000,$E40,'Plan Mensual'!$H$2:$H$2000,$A40)) -> 0 | C40: =IF($A40="","",SUMIFS(Movimientos!$J$2:$J$2000,Movimientos!$C$2:$C$2000,$A$119,Movimientos!$E$2:$E$2000,$D$2,Movimientos!$F$2:$F$2000,$D40,Movimientos!$G$2:$G$2000,$E40,Movimientos!$H$2:$H$2000,$A40,Movimientos!$K$2:$K$2000,"<>Anulado")) -> 0 | D40: Deseos | E40: Suscripciones | F40: =IF(A40="","",IF(B40=0,IF(C40=0,"Sin dato","Sin presupuesto"),IF(C40>B40,"Excede",IF(C40=B40,"Exacto","Dentro")))) -> Sin dato | I40: =IF($H40="","",SUMIFS('Plan Mensual'!$I$2:$I$2000,'Plan Mensual'!$B$2:$B$2000,$D$2,'Plan Mensual'!$C$2:$C$2000,$A$119,'Plan Mensual'!$E$2:$E$2000,"Gastos Variables",'Plan Mensual'!$F$2:$F$2000,$K40,'Plan Mensual'!$G$2:$G$2000,$L40,'Plan Mensual'!$H$2:$H$2000,$H40)) | J40: =IF($H40="","",SUMIFS(Movimientos!$J$2:$J$2000,Movimientos!$C$2:$C$2000,$A$119,Movimientos!$E$2:$E$2000,$D$2,Movimientos!$F$2:$F$2000,$K40,Movimientos!$G$2:$G$2000,$L40,Movimientos!$H$2:$H$2000,$H40,Movimientos!$K$2:$K$2000,"<>Anulado")) | M40: =IF(H40="","",IF(I40=0,IF(J40=0,"Sin dato","Sin presupuesto"),IF(J40>I40,"Excede",IF(J40=I40,"Exacto","Dentro"))))
A41: HBO Max | B41: =IF($A41="","",SUMIFS('Plan Mensual'!$I$2:$I$2000,'Plan Mensual'!$B$2:$B$2000,$D$2,'Plan Mensual'!$C$2:$C$2000,$A$119,'Plan Mensual'!$E$2:$E$2000,"Gastos Fijos",'Plan Mensual'!$F$2:$F$2000,$D41,'Plan Mensual'!$G$2:$G$2000,$E41,'Plan Mensual'!$H$2:$H$2000,$A41)) -> 0 | C41: =IF($A41="","",SUMIFS(Movimientos!$J$2:$J$2000,Movimientos!$C$2:$C$2000,$A$119,Movimientos!$E$2:$E$2000,$D$2,Movimientos!$F$2:$F$2000,$D41,Movimientos!$G$2:$G$2000,$E41,Movimientos!$H$2:$H$2000,$A41,Movimientos!$K$2:$K$2000,"<>Anulado")) -> 0 | D41: Deseos | E41: Suscripciones | F41: =IF(A41="","",IF(B41=0,IF(C41=0,"Sin dato","Sin presupuesto"),IF(C41>B41,"Excede",IF(C41=B41,"Exacto","Dentro")))) -> Sin dato | I41: =IF($H41="","",SUMIFS('Plan Mensual'!$I$2:$I$2000,'Plan Mensual'!$B$2:$B$2000,$D$2,'Plan Mensual'!$C$2:$C$2000,$A$119,'Plan Mensual'!$E$2:$E$2000,"Gastos Variables",'Plan Mensual'!$F$2:$F$2000,$K41,'Plan Mensual'!$G$2:$G$2000,$L41,'Plan Mensual'!$H$2:$H$2000,$H41)) | J41: =IF($H41="","",SUMIFS(Movimientos!$J$2:$J$2000,Movimientos!$C$2:$C$2000,$A$119,Movimientos!$E$2:$E$2000,$D$2,Movimientos!$F$2:$F$2000,$K41,Movimientos!$G$2:$G$2000,$L41,Movimientos!$H$2:$H$2000,$H41,Movimientos!$K$2:$K$2000,"<>Anulado")) | M41: =IF(H41="","",IF(I41=0,IF(J41=0,"Sin dato","Sin presupuesto"),IF(J41>I41,"Excede",IF(J41=I41,"Exacto","Dentro"))))
...

Sheet Plan Mensual
B1: Año | C1: Mes N° | D1: Mes | E1: Sección | F1: Tipo | G1: Categoría | H1: Concepto | I1: Presupuesto | J1: Nota
B2: 2026 | C2: =IF(D2="","",MATCH(D2,Parametros!$B$4:$B$15,0)) -> 1 | D2: Enero | E2: Ingresos | F2: Ingreso | G2: Sueldo | H2: Sueldo | I2: 2000000 | J2: Ejemplo
B3: 2026 | C3: =IF(D3="","",MATCH(D3,Parametros!$B$4:$B$15,0)) -> 1 | D3: Enero | E3: Ingresos | F3: Ingreso | G3: Freelance | H3: Freelance | I3: 500000 | J3: Ejemplo
B4: 2026 | C4: =IF(D4="","",MATCH(D4,Parametros!$B$4:$B$15,0)) -> 1 | D4: Enero | E4: Gastos Fijos | F4: Necesidades | G4: Hogar | H4: Arriendo | I4: 1000000 | J4: Ejemplo
B5: 2026 | C5: =IF(D5="","",MATCH(D5,Parametros!$B$4:$B$15,0)) -> 1 | D5: Enero | E5: Gastos Fijos | F5: Necesidades | G5: Servicios | H5: Internet | I5: 30000 | J5: Ejemplo
C6: =IF(D6="","",MATCH(D6,Parametros!$B$4:$B$15,0))
C7: =IF(D7="","",MATCH(D7,Parametros!$B$4:$B$15,0))
C8: =IF(D8="","",MATCH(D8,Parametros!$B$4:$B$15,0))
C9: =IF(D9="","",MATCH(D9,Parametros!$B$4:$B$15,0))
C10: =IF(D10="","",MATCH(D10,Parametros!$B$4:$B$15,0))
C11: =IF(D11="","",MATCH(D11,Parametros!$B$4:$B$15,0))
C12: =IF(D12="","",MATCH(D12,Parametros!$B$4:$B$15,0))
C13: =IF(D13="","",MATCH(D13,Parametros!$B$4:$B$15,0))
C14: =IF(D14="","",MATCH(D14,Parametros!$B$4:$B$15,0))
C15: =IF(D15="","",MATCH(D15,Parametros!$B$4:$B$15,0))
C16: =IF(D16="","",MATCH(D16,Parametros!$B$4:$B$15,0))
C17: =IF(D17="","",MATCH(D17,Parametros!$B$4:$B$15,0))
... C2000: =IF(D2000="","",MATCH(D2000,Parametros!$B$4:$B$15,0))

Sheet Movimientos
B1: Fecha | C1: Mes N° | D1: Mes | E1: Año | F1: Tipo | G1: Categoría | H1: Concepto | I1: Descripción | J1: Monto | K1: Estado | L1: Medio de pago | M1: Nota
B2: 46023 | C2: =IF(B2="","",MONTH(B2)) -> 1 | D2: =IF(B2="","",CHOOSE(C2,"Enero","Febrero","Marzo","Abril","Mayo","Junio","Julio","Agosto","Septiembre","Octubre","Noviembre","Diciembre")) -> Enero | E2: =IF(B2="","",YEAR(B2)) -> 2026 | F2: Ingreso | G2: Sueldo | H2: Sueldo | I2: Ingreso principal | J2: 2000000 | K2: Cobrado | L2: Transferencia | M2: Ejemplo
B3: 46027 | C3: =IF(B3="","",MONTH(B3)) -> 1 | D3: =IF(B3="","",CHOOSE(C3,"Enero","Febrero","Marzo","Abril","Mayo","Junio","Julio","Agosto","Septiembre","Octubre","Noviembre","Diciembre")) -> Enero | E3: =IF(B3="","",YEAR(B3)) -> 2026 | F3: Ingreso | G3: Freelance | H3: Freelance | I3: Ingreso secundario | J3: 500000 | K3: Cobrado | L3: Transferencia | M3: Ejemplo
B4: 46024 | C4: =IF(B4="","",MONTH(B4)) -> 1 | D4: =IF(B4="","",CHOOSE(C4,"Enero","Febrero","Marzo","Abril","Mayo","Junio","Julio","Agosto","Septiembre","Octubre","Noviembre","Diciembre")) -> Enero | E4: =IF(B4="","",YEAR(B4)) -> 2026 | F4: Necesidades | G4: Hogar | H4: Arriendo | I4: Pago arriendo mensual | J4: 1000000 | K4: Pagado | L4: Transferencia | M4: Ejemplo
B5: 46027 | C5: =IF(B5="","",MONTH(B5)) -> 1 | D5: =IF(B5="","",CHOOSE(C5,"Enero","Febrero","Marzo","Abril","Mayo","Junio","Julio","Agosto","Septiembre","Octubre","Noviembre","Diciembre")) -> Enero | E5: =IF(B5="","",YEAR(B5)) -> 2026 | F5: Necesidades | G5: Servicios | H5: Internet | I5: Internet hogar | J5: 30000 | K5: Pagado | L5: Automático | M5: Ejemplo
C6: =IF(B6="","",MONTH(B6)) | D6: =IF(B6="","",CHOOSE(C6,"Enero","Febrero","Marzo","Abril","Mayo","Junio","Julio","Agosto","Septiembre","Octubre","Noviembre","Diciembre")) | E6: =IF(B6="","",YEAR(B6))
C7: =IF(B7="","",MONTH(B7)) | D7: =IF(B7="","",CHOOSE(C7,"Enero","Febrero","Marzo","Abril","Mayo","Junio","Julio","Agosto","Septiembre","Octubre","Noviembre","Diciembre")) | E7: =IF(B7="","",YEAR(B7))
C8: =IF(B8="","",MONTH(B8)) | D8: =IF(B8="","",CHOOSE(C8,"Enero","Febrero","Marzo","Abril","Mayo","Junio","Julio","Agosto","Septiembre","Octubre","Noviembre","Diciembre")) | E8: =IF(B8="","",YEAR(B8))
C9: =IF(B9="","",MONTH(B9)) | D9: =IF(B9="","",CHOOSE(C9,"Enero","Febrero","Marzo","Abril","Mayo","Junio","Julio","Agosto","Septiembre","Octubre","Noviembre","Diciembre")) | E9: =IF(B9="","",YEAR(B9))
C10: =IF(B10="","",MONTH(B10)) | D10: =IF(B10="","",CHOOSE(C10,"Enero","Febrero","Marzo","Abril","Mayo","Junio","Julio","Agosto","Septiembre","Octubre","Noviembre","Diciembre")) | E10: =IF(B10="","",YEAR(B10))
C11: =IF(B11="","",MONTH(B11)) | D11: =IF(B11="","",CHOOSE(C11,"Enero","Febrero","Marzo","Abril","Mayo","Junio","Julio","Agosto","Septiembre","Octubre","Noviembre","Diciembre")) | E11: =IF(B11="","",YEAR(B11))
C12: =IF(B12="","",MONTH(B12)) | D12: =IF(B12="","",CHOOSE(C12,"Enero","Febrero","Marzo","Abril","Mayo","Junio","Julio","Agosto","Septiembre","Octubre","Noviembre","Diciembre")) | E12: =IF(B12="","",YEAR(B12))
C13: =IF(B13="","",MONTH(B13)) | D13: =IF(B13="","",CHOOSE(C13,"Enero","Febrero","Marzo","Abril","Mayo","Junio","Julio","Agosto","Septiembre","Octubre","Noviembre","Diciembre")) | E13: =IF(B13="","",YEAR(B13))
C14: =IF(B14="","",MONTH(B14)) | D14: =IF(B14="","",CHOOSE(C14,"Enero","Febrero","Marzo","Abril","Mayo","Junio","Julio","Agosto","Septiembre","Octubre","Noviembre","Diciembre")) | E14: =IF(B14="","",YEAR(B14))
C15: =IF(B15="","",MONTH(B15)) | D15: =IF(B15="","",CHOOSE(C15,"Enero","Febrero","Marzo","Abril","Mayo","Junio","Julio","Agosto","Septiembre","Octubre","Noviembre","Diciembre")) | E15: =IF(B15="","",YEAR(B15))
C16: =IF(B16="","",MONTH(B16)) | D16: =IF(B16="","",CHOOSE(C16,"Enero","Febrero","Marzo","Abril","Mayo","Junio","Julio","Agosto","Septiembre","Octubre","Noviembre","Diciembre")) | E16: =IF(B16="","",YEAR(B16))
C17: =IF(B17="","",MONTH(B17)) | D17: =IF(B17="","",CHOOSE(C17,"Enero","Febrero","Marzo","Abril","Mayo","Junio","Julio","Agosto","Septiembre","Octubre","Noviembre","Diciembre")) | E17: =IF(B17="","",YEAR(B17))
... C2000: =IF(B2000="","",MONTH(B2000)) | D2000: =IF(B2000="","",CHOOSE(C2000,"Enero","Febrero","Marzo","Abril","Mayo","Junio","Julio","Agosto","Septiembre","Octubre","Noviembre","Diciembre")) | E2000: =IF(B2000="","",YEAR(B2000))

Sheet Parametros
A1: PARÁMETROS Y LISTAS | M1: SECCIONES DE PRESUPUESTO | N1: USO | P1: Años
P2: 2024
A3: Mes N° | B3: Mes | D3: Tipo | F3: Categoría | H3: Concepto | J3: Objetivo | K3: % sugerido | M3: Sección | N3: Cómo usar | P3: 2025
A4: 1 | B4: Enero | D4: Ingreso | F4: Sueldo | H4: Sueldo | J4: Necesidades | K4: 0.5 | M4: Ingresos | N4: Carga presupuesto de ingresos por mes. | P4: 2026
A5: 2 | B5: Febrero | D5: Necesidades | F5: Freelance | H5: Freelance | J5: Deseos | K5: 0.3 | M5: Gastos Fijos | N5: Carga presupuesto de gastos fijos por mes. | P5: 2027
A6: 3 | B6: Marzo | D6: Deseos | F6: Hogar | H6: Ingreso extra | J6: Ahorros | K6: 0.2 | M6: Gastos Variables | N6: Carga presupuesto de gastos variables por mes. | P6: 2028
A7: 4 | B7: Abril | D7: Ahorros | F7: Servicios | H7: Arriendo | M7: Ahorros | N7: Ahorros se acumula hasta el mes seleccionado. | P7: 2029
A8: 5 | B8: Mayo | D8: Inversiones | F8: Suscripciones | H8: Internet | J8: Estado | M8: Inversiones | N8: Inversiones se acumula hasta el mes seleccionado. | P8: 2030
A9: 6 | B9: Junio | D9: Deudas | F9: Alimentación | H9: Movil | J9: Registrado | M9: Deudas | N9: Deudas se mantiene mensual. | P9: 2031
A10: 7 | B10: Julio | F10: Transporte | H10: Servicios básicos | J10: Pagado | P10: 2032
A11: 8 | B11: Agosto | D11: Medio de pago | F11: Entretenimiento | H11: Netflix | J11: Cobrado | P11: 2033
A12: 9 | B12: Septiembre | D12: Efectivo | F12: Salud | H12: HBO Max | J12: Pendiente | P12: 2034
A13: 10 | B13: Octubre | D13: Débito | F13: Educación | H13: YouTube Premium | J13: Anulado | P13: 2035
A14: 11 | B14: Noviembre | D14: Crédito | F14: Cuidado Personal | H14: Mercado | P14: 2036
A15: 12 | B15: Diciembre | D15: Transferencia | F15: Emergencia | H15: Transporte | P15: 2037
D16: Automático | F16: Inversión | H16: Restaurantes | P16: 2038
D17: Otro | F17: Tarjeta Crédito | H17: Ocio | P17: 2039
F18: Préstamo | H18: Viaje | P18: 2040
F19: Otro | H19: Cerro nieve | P19: 2041
F20: Ocio | H20: Fondo emergencia | P20: 2042
H21: Cuenta ahorro | P21: 2043
H22: Inversión 1 | P22: 2044
H23: Inversión 2 | P23: 2045
H24: Tarjeta Crédito 1 | P24: 2046
H25: Tarjeta Crédito 2 | P25: 2047
H26: Préstamo | P26: 2048
H27: Salud | P27: 2049
H28: Ropa | P28: 2050

Sheet Resumen Anual
B1: RESUMEN ANUAL FINANZAS PERSONALES
F3: Año seleccionado | G3: 2026 | H3: Filtro anual independiente
B5: Mes N° | C5: Mes | D5: Ingresos | E5: Necesidades | F5: Deseos | G5: Ahorros | H5: Inversiones | I5: Deudas | J5: Total egresos | K5: Saldo | L5: % Ahorro
B6: 1 | C6: Enero | D6: =SUMIFS(Movimientos!$J$2:$J$2000,Movimientos!$C$2:$C$2000,$B6,Movimientos!$E$2:$E$2000,$G$3,Movimientos!$F$2:$F$2000,"Ingreso",Movimientos!$K$2:$K$2000,"<>Anulado") -> 2500000 | E6: =SUMIFS(Movimientos!$J$2:$J$2000,Movimientos!$C$2:$C$2000,$B6,Movimientos!$E$2:$E$2000,$G$3,Movimientos!$F$2:$F$2000,"Necesidades",Movimientos!$K$2:$K$2000,"<>Anulado") -> 1030000 | F6: =SUMIFS(Movimientos!$J$2:$J$2000,Movimientos!$C$2:$C$2000,$B6,Movimientos!$E$2:$E$2000,$G$3,Movimientos!$F$2:$F$2000,"Deseos",Movimientos!$K$2:$K$2000,"<>Anulado") -> 0 | G6: =SUMIFS(Movimientos!$J$2:$J$2000,Movimientos!$C$2:$C$2000,$B6,Movimientos!$E$2:$E$2000,$G$3,Movimientos!$F$2:$F$2000,"Ahorros",Movimientos!$K$2:$K$2000,"<>Anulado") -> 0 | H6: =SUMIFS(Movimientos!$J$2:$J$2000,Movimientos!$C$2:$C$2000,$B6,Movimientos!$E$2:$E$2000,$G$3,Movimientos!$F$2:$F$2000,"Inversiones",Movimientos!$K$2:$K$2000,"<>Anulado") -> 0 | I6: =SUMIFS(Movimientos!$J$2:$J$2000,Movimientos!$C$2:$C$2000,$B6,Movimientos!$E$2:$E$2000,$G$3,Movimientos!$F$2:$F$2000,"Deudas",Movimientos!$K$2:$K$2000,"<>Anulado") -> 0 | J6: =SUM(E6:I6) -> 1030000 | K6: =D6-J6 -> 1470000 | L6: =IFERROR((G6+H6)/D6,0) -> 0
B7: 2 | C7: Febrero | D7: =SUMIFS(Movimientos!$J$2:$J$2000,Movimientos!$C$2:$C$2000,$B7,Movimientos!$E$2:$E$2000,$G$3,Movimientos!$F$2:$F$2000,"Ingreso",Movimientos!$K$2:$K$2000,"<>Anulado") -> 0 | E7: =SUMIFS(Movimientos!$J$2:$J$2000,Movimientos!$C$2:$C$2000,$B7,Movimientos!$E$2:$E$2000,$G$3,Movimientos!$F$2:$F$2000,"Necesidades",Movimientos!$K$2:$K$2000,"<>Anulado") -> 0 | F7: =SUMIFS(Movimientos!$J$2:$J$2000,Movimientos!$C$2:$C$2000,$B7,Movimientos!$E$2:$E$2000,$G$3,Movimientos!$F$2:$F$2000,"Deseos",Movimientos!$K$2:$K$2000,"<>Anulado") -> 0 | G7: =SUMIFS(Movimientos!$J$2:$J$2000,Movimientos!$C$2:$C$2000,$B7,Movimientos!$E$2:$E$2000,$G$3,Movimientos!$F$2:$F$2000,"Ahorros",Movimientos!$K$2:$K$2000,"<>Anulado") -> 0 | H7: =SUMIFS(Movimientos!$J$2:$J$2000,Movimientos!$C$2:$C$2000,$B7,Movimientos!$E$2:$E$2000,$G$3,Movimientos!$F$2:$F$2000,"Inversiones",Movimientos!$K$2:$K$2000,"<>Anulado") -> 0 | I7: =SUMIFS(Movimientos!$J$2:$J$2000,Movimientos!$C$2:$C$2000,$B7,Movimientos!$E$2:$E$2000,$G$3,Movimientos!$F$2:$F$2000,"Deudas",Movimientos!$K$2:$K$2000,"<>Anulado") -> 0 | J7: =SUM(E7:I7) -> 0 | K7: =D7-J7 -> 0 | L7: =IFERROR((G7+H7)/D7,0) -> 0
B8: 3 | C8: Marzo | D8: =SUMIFS(Movimientos!$J$2:$J$2000,Movimientos!$C$2:$C$2000,$B8,Movimientos!$E$2:$E$2000,$G$3,Movimientos!$F$2:$F$2000,"Ingreso",Movimientos!$K$2:$K$2000,"<>Anulado") -> 0 | E8: =SUMIFS(Movimientos!$J$2:$J$2000,Movimientos!$C$2:$C$2000,$B8,Movimientos!$E$2:$E$2000,$G$3,Movimientos!$F$2:$F$2000,"Necesidades",Movimientos!$K$2:$K$2000,"<>Anulado") -> 0 | F8: =SUMIFS(Movimientos!$J$2:$J$2000,Movimientos!$C$2:$C$2000,$B8,Movimientos!$E$2:$E$2000,$G$3,Movimientos!$F$2:$F$2000,"Deseos",Movimientos!$K$2:$K$2000,"<>Anulado") -> 0 | G8: =SUMIFS(Movimientos!$J$2:$J$2000,Movimientos!$C$2:$C$2000,$B8,Movimientos!$E$2:$E$2000,$G$3,Movimientos!$F$2:$F$2000,"Ahorros",Movimientos!$K$2:$K$2000,"<>Anulado") -> 0 | H8: =SUMIFS(Movimientos!$J$2:$J$2000,Movimientos!$C$2:$C$2000,$B8,Movimientos!$E$2:$E$2000,$G$3,Movimientos!$F$2:$F$2000,"Inversiones",Movimientos!$K$2:$K$2000,"<>Anulado") -> 0 | I8: =SUMIFS(Movimientos!$J$2:$J$2000,Movimientos!$C$2:$C$2000,$B8,Movimientos!$E$2:$E$2000,$G$3,Movimientos!$F$2:$F$2000,"Deudas",Movimientos!$K$2:$K$2000,"<>Anulado") -> 0 | J8: =SUM(E8:I8) -> 0 | K8: =D8-J8 -> 0 | L8: =IFERROR((G8+H8)/D8,0) -> 0
B9: 4 | C9: Abril | D9: =SUMIFS(Movimientos!$J$2:$J$2000,Movimientos!$C$2:$C$2000,$B9,Movimientos!$E$2:$E$2000,$G$3,Movimientos!$F$2:$F$2000,"Ingreso",Movimientos!$K$2:$K$2000,"<>Anulado") -> 0 | E9: =SUMIFS(Movimientos!$J$2:$J$2000,Movimientos!$C$2:$C$2000,$B9,Movimientos!$E$2:$E$2000,$G$3,Movimientos!$F$2:$F$2000,"Necesidades",Movimientos!$K$2:$K$2000,"<>Anulado") -> 0 | F9: =SUMIFS(Movimientos!$J$2:$J$2000,Movimientos!$C$2:$C$2000,$B9,Movimientos!$E$2:$E$2000,$G$3,Movimientos!$F$2:$F$2000,"Deseos",Movimientos!$K$2:$K$2000,"<>Anulado") -> 0 | G9: =SUMIFS(Movimientos!$J$2:$J$2000,Movimientos!$C$2:$C$2000,$B9,Movimientos!$E$2:$E$2000,$G$3,Movimientos!$F$2:$F$2000,"Ahorros",Movimientos!$K$2:$K$2000,"<>Anulado") -> 0 | H9: =SUMIFS(Movimientos!$J$2:$J$2000,Movimientos!$C$2:$C$2000,$B9,Movimientos!$E$2:$E$2000,$G$3,Movimientos!$F$2:$F$2000,"Inversiones",Movimientos!$K$2:$K$2000,"<>Anulado") -> 0 | I9: =SUMIFS(Movimientos!$J$2:$J$2000,Movimientos!$C$2:$C$2000,$B9,Movimientos!$E$2:$E$2000,$G$3,Movimientos!$F$2:$F$2000,"Deudas",Movimientos!$K$2:$K$2000,"<>Anulado") -> 0 | J9: =SUM(E9:I9) -> 0 | K9: =D9-J9 -> 0 | L9: =IFERROR((G9+H9)/D9,0) -> 0
B10: 5 | C10: Mayo | D10: =SUMIFS(Movimientos!$J$2:$J$2000,Movimientos!$C$2:$C$2000,$B10,Movimientos!$E$2:$E$2000,$G$3,Movimientos!$F$2:$F$2000,"Ingreso",Movimientos!$K$2:$K$2000,"<>Anulado") -> 0 | E10: =SUMIFS(Movimientos!$J$2:$J$2000,Movimientos!$C$2:$C$2000,$B10,Movimientos!$E$2:$E$2000,$G$3,Movimientos!$F$2:$F$2000,"Necesidades",Movimientos!$K$2:$K$2000,"<>Anulado") -> 0 | F10: =SUMIFS(Movimientos!$J$2:$J$2000,Movimientos!$C$2:$C$2000,$B10,Movimientos!$E$2:$E$2000,$G$3,Movimientos!$F$2:$F$2000,"Deseos",Movimientos!$K$2:$K$2000,"<>Anulado") -> 0 | G10: =SUMIFS(Movimientos!$J$2:$J$2000,Movimientos!$C$2:$C$2000,$B10,Movimientos!$E$2:$E$2000,$G$3,Movimientos!$F$2:$F$2000,"Ahorros",Movimientos!$K$2:$K$2000,"<>Anulado") -> 0 | H10: =SUMIFS(Movimientos!$J$2:$J$2000,Movimientos!$C$2:$C$2000,$B10,Movimientos!$E$2:$E$2000,$G$3,Movimientos!$F$2:$F$2000,"Inversiones",Movimientos!$K$2:$K$2000,"<>Anulado") -> 0 | I10: =SUMIFS(Movimientos!$J$2:$J$2000,Movimientos!$C$2:$C$2000,$B10,Movimientos!$E$2:$E$2000,$G$3,Movimientos!$F$2:$F$2000,"Deudas",Movimientos!$K$2:$K$2000,"<>Anulado") -> 0 | J10: =SUM(E10:I10) -> 0 | K10: =D10-J10 -> 0 | L10: =IFERROR((G10+H10)/D10,0) -> 0
B11: 6 | C11: Junio | D11: =SUMIFS(Movimientos!$J$2:$J$2000,Movimientos!$C$2:$C$2000,$B11,Movimientos!$E$2:$E$2000,$G$3,Movimientos!$F$2:$F$2000,"Ingreso",Movimientos!$K$2:$K$2000,"<>Anulado") -> 0 | E11: =SUMIFS(Movimientos!$J$2:$J$2000,Movimientos!$C$2:$C$2000,$B11,Movimientos!$E$2:$E$2000,$G$3,Movimientos!$F$2:$F$2000,"Necesidades",Movimientos!$K$2:$K$2000,"<>Anulado") -> 0 | F11: =SUMIFS(Movimientos!$J$2:$J$2000,Movimientos!$C$2:$C$2000,$B11,Movimientos!$E$2:$E$2000,$G$3,Movimientos!$F$2:$F$2000,"Deseos",Movimientos!$K$2:$K$2000,"<>Anulado") -> 0 | G11: =SUMIFS(Movimientos!$J$2:$J$2000,Movimientos!$C$2:$C$2000,$B11,Movimientos!$E$2:$E$2000,$G$3,Movimientos!$F$2:$F$2000,"Ahorros",Movimientos!$K$2:$K$2000,"<>Anulado") -> 0 | H11: =SUMIFS(Movimientos!$J$2:$J$2000,Movimientos!$C$2:$C$2000,$B11,Movimientos!$E$2:$E$2000,$G$3,Movimientos!$F$2:$F$2000,"Inversiones",Movimientos!$K$2:$K$2000,"<>Anulado") -> 0 | I11: =SUMIFS(Movimientos!$J$2:$J$2000,Movimientos!$C$2:$C$2000,$B11,Movimientos!$E$2:$E$2000,$G$3,Movimientos!$F$2:$F$2000,"Deudas",Movimientos!$K$2:$K$2000,"<>Anulado") -> 0 | J11: =SUM(E11:I11) -> 0 | K11: =D11-J11 -> 0 | L11: =IFERROR((G11+H11)/D11,0) -> 0
B12: 7 | C12: Julio | D12: =SUMIFS(Movimientos!$J$2:$J$2000,Movimientos!$C$2:$C$2000,$B12,Movimientos!$E$2:$E$2000,$G$3,Movimientos!$F$2:$F$2000,"Ingreso",Movimientos!$K$2:$K$2000,"<>Anulado") -> 0 | E12: =SUMIFS(Movimientos!$J$2:$J$2000,Movimientos!$C$2:$C$2000,$B12,Movimientos!$E$2:$E$2000,$G$3,Movimientos!$F$2:$F$2000,"Necesidades",Movimientos!$K$2:$K$2000,"<>Anulado") -> 0 | F12: =SUMIFS(Movimientos!$J$2:$J$2000,Movimientos!$C$2:$C$2000,$B12,Movimientos!$E$2:$E$2000,$G$3,Movimientos!$F$2:$F$2000,"Deseos",Movimientos!$K$2:$K$2000,"<>Anulado") -> 0 | G12: =SUMIFS(Movimientos!$J$2:$J$2000,Movimientos!$C$2:$C$2000,$B12,Movimientos!$E$2:$E$2000,$G$3,Movimientos!$F$2:$F$2000,"Ahorros",Movimientos!$K$2:$K$2000,"<>Anulado") -> 0 | H12: =SUMIFS(Movimientos!$J$2:$J$2000,Movimientos!$C$2:$C$2000,$B12,Movimientos!$E$2:$E$2000,$G$3,Movimientos!$F$2:$F$2000,"Inversiones",Movimientos!$K$2:$K$2000,"<>Anulado") -> 0 | I12: =SUMIFS(Movimientos!$J$2:$J$2000,Movimientos!$C$2:$C$2000,$B12,Movimientos!$E$2:$E$2000,$G$3,Movimientos!$F$2:$F$2000,"Deudas",Movimientos!$K$2:$K$2000,"<>Anulado") -> 0 | J12: =SUM(E12:I12) -> 0 | K12: =D12-J12 -> 0 | L12: =IFERROR((G12+H12)/D12,0) -> 0
B13: 8 | C13: Agosto | D13: =SUMIFS(Movimientos!$J$2:$J$2000,Movimientos!$C$2:$C$2000,$B13,Movimientos!$E$2:$E$2000,$G$3,Movimientos!$F$2:$F$2000,"Ingreso",Movimientos!$K$2:$K$2000,"<>Anulado") -> 0 | E13: =SUMIFS(Movimientos!$J$2:$J$2000,Movimientos!$C$2:$C$2000,$B13,Movimientos!$E$2:$E$2000,$G$3,Movimientos!$F$2:$F$2000,"Necesidades",Movimientos!$K$2:$K$2000,"<>Anulado") -> 0 | F13: =SUMIFS(Movimientos!$J$2:$J$2000,Movimientos!$C$2:$C$2000,$B13,Movimientos!$E$2:$E$2000,$G$3,Movimientos!$F$2:$F$2000,"Deseos",Movimientos!$K$2:$K$2000,"<>Anulado") -> 0 | G13: =SUMIFS(Movimientos!$J$2:$J$2000,Movimientos!$C$2:$C$2000,$B13,Movimientos!$E$2:$E$2000,$G$3,Movimientos!$F$2:$F$2000,"Ahorros",Movimientos!$K$2:$K$2000,"<>Anulado") -> 0 | H13: =SUMIFS(Movimientos!$J$2:$J$2000,Movimientos!$C$2:$C$2000,$B13,Movimientos!$E$2:$E$2000,$G$3,Movimientos!$F$2:$F$2000,"Inversiones",Movimientos!$K$2:$K$2000,"<>Anulado") -> 0 | I13: =SUMIFS(Movimientos!$J$2:$J$2000,Movimientos!$C$2:$C$2000,$B13,Movimientos!$E$2:$E$2000,$G$3,Movimientos!$F$2:$F$2000,"Deudas",Movimientos!$K$2:$K$2000,"<>Anulado") -> 0 | J13: =SUM(E13:I13) -> 0 | K13: =D13-J13 -> 0 | L13: =IFERROR((G13+H13)/D13,0) -> 0
B14: 9 | C14: Septiembre | D14: =SUMIFS(Movimientos!$J$2:$J$2000,Movimientos!$C$2:$C$2000,$B14,Movimientos!$E$2:$E$2000,$G$3,Movimientos!$F$2:$F$2000,"Ingreso",Movimientos!$K$2:$K$2000,"<>Anulado") -> 0 | E14: =SUMIFS(Movimientos!$J$2:$J$2000,Movimientos!$C$2:$C$2000,$B14,Movimientos!$E$2:$E$2000,$G$3,Movimientos!$F$2:$F$2000,"Necesidades",Movimientos!$K$2:$K$2000,"<>Anulado") -> 0 | F14: =SUMIFS(Movimientos!$J$2:$J$2000,Movimientos!$C$2:$C$2000,$B14,Movimientos!$E$2:$E$2000,$G$3,Movimientos!$F$2:$F$2000,"Deseos",Movimientos!$K$2:$K$2000,"<>Anulado") -> 0 | G14: =SUMIFS(Movimientos!$J$2:$J$2000,Movimientos!$C$2:$C$2000,$B14,Movimientos!$E$2:$E$2000,$G$3,Movimientos!$F$2:$F$2000,"Ahorros",Movimientos!$K$2:$K$2000,"<>Anulado") -> 0 | H14: =SUMIFS(Movimientos!$J$2:$J$2000,Movimientos!$C$2:$C$2000,$B14,Movimientos!$E$2:$E$2000,$G$3,Movimientos!$F$2:$F$2000,"Inversiones",Movimientos!$K$2:$K$2000,"<>Anulado") -> 0 | I14: =SUMIFS(Movimientos!$J$2:$J$2000,Movimientos!$C$2:$C$2000,$B14,Movimientos!$E$2:$E$2000,$G$3,Movimientos!$F$2:$F$2000,"Deudas",Movimientos!$K$2:$K$2000,"<>Anulado") -> 0 | J14: =SUM(E14:I14) -> 0 | K14: =D14-J14 -> 0 | L14: =IFERROR((G14+H14)/D14,0) -> 0
B15: 10 | C15: Octubre | D15: =SUMIFS(Movimientos!$J$2:$J$2000,Movimientos!$C$2:$C$2000,$B15,Movimientos!$E$2:$E$2000,$G$3,Movimientos!$F$2:$F$2000,"Ingreso",Movimientos!$K$2:$K$2000,"<>Anulado") -> 0 | E15: =SUMIFS(Movimientos!$J$2:$J$2000,Movimientos!$C$2:$C$2000,$B15,Movimientos!$E$2:$E$2000,$G$3,Movimientos!$F$2:$F$2000,"Necesidades",Movimientos!$K$2:$K$2000,"<>Anulado") -> 0 | F15: =SUMIFS(Movimientos!$J$2:$J$2000,Movimientos!$C$2:$C$2000,$B15,Movimientos!$E$2:$E$2000,$G$3,Movimientos!$F$2:$F$2000,"Deseos",Movimientos!$K$2:$K$2000,"<>Anulado") -> 0 | G15: =SUMIFS(Movimientos!$J$2:$J$2000,Movimientos!$C$2:$C$2000,$B15,Movimientos!$E$2:$E$2000,$G$3,Movimientos!$F$2:$F$2000,"Ahorros",Movimientos!$K$2:$K$2000,"<>Anulado") -> 0 | H15: =SUMIFS(Movimientos!$J$2:$J$2000,Movimientos!$C$2:$C$2000,$B15,Movimientos!$E$2:$E$2000,$G$3,Movimientos!$F$2:$F$2000,"Inversiones",Movimientos!$K$2:$K$2000,"<>Anulado") -> 0 | I15: =SUMIFS(Movimientos!$J$2:$J$2000,Movimientos!$C$2:$C$2000,$B15,Movimientos!$E$2:$E$2000,$G$3,Movimientos!$F$2:$F$2000,"Deudas",Movimientos!$K$2:$K$2000,"<>Anulado") -> 0 | J15: =SUM(E15:I15) -> 0 | K15: =D15-J15 -> 0 | L15: =IFERROR((G15+H15)/D15,0) -> 0
B16: 11 | C16: Noviembre | D16: =SUMIFS(Movimientos!$J$2:$J$2000,Movimientos!$C$2:$C$2000,$B16,Movimientos!$E$2:$E$2000,$G$3,Movimientos!$F$2:$F$2000,"Ingreso",Movimientos!$K$2:$K$2000,"<>Anulado") -> 0 | E16: =SUMIFS(Movimientos!$J$2:$J$2000,Movimientos!$C$2:$C$2000,$B16,Movimientos!$E$2:$E$2000,$G$3,Movimientos!$F$2:$F$2000,"Necesidades",Movimientos!$K$2:$K$2000,"<>Anulado") -> 0 | F16: =SUMIFS(Movimientos!$J$2:$J$2000,Movimientos!$C$2:$C$2000,$B16,Movimientos!$E$2:$E$2000,$G$3,Movimientos!$F$2:$F$2000,"Deseos",Movimientos!$K$2:$K$2000,"<>Anulado") -> 0 | G16: =SUMIFS(Movimientos!$J$2:$J$2000,Movimientos!$C$2:$C$2000,$B16,Movimientos!$E$2:$E$2000,$G$3,Movimientos!$F$2:$F$2000,"Ahorros",Movimientos!$K$2:$K$2000,"<>Anulado") -> 0 | H16: =SUMIFS(Movimientos!$J$2:$J$2000,Movimientos!$C$2:$C$2000,$B16,Movimientos!$E$2:$E$2000,$G$3,Movimientos!$F$2:$F$2000,"Inversiones",Movimientos!$K$2:$K$2000,"<>Anulado") -> 0 | I16: =SUMIFS(Movimientos!$J$2:$J$2000,Movimientos!$C$2:$C$2000,$B16,Movimientos!$E$2:$E$2000,$G$3,Movimientos!$F$2:$F$2000,"Deudas",Movimientos!$K$2:$K$2000,"<>Anulado") -> 0 | J16: =SUM(E16:I16) -> 0 | K16: =D16-J16 -> 0 | L16: =IFERROR((G16+H16)/D16,0) -> 0
