Workbook
Name LISTA_CATGASTO: Configuración!$F$6:$F$25
Name LISTA_CATVENTA: Configuración!$C$6:$C$25
Name LISTA_PRODUCTOS: Configuración!$B$6:$B$25
Name LISTA_REGIONES: Configuración!$D$6:$D$25
Name LISTA_VENDEDORES: Configuración!$E$6:$E$25

Sheet Inicio
B2: DASHBOARD FINANCIERO PYME · MULTI-AÑO
B3: Panel financiero multi-año. Ingresa todos los datos históricos y actuales en las tablas. El Dashboard y los gráficos se actualizan automáticamente con el año que selecciones.
B5: Estructura de la plantilla
B6: Hoja | C6: Propósito | D6: Qué hacer
B7: Datos Ventas | C7: Todas las ventas históricas | D7: Ingresa cada venta con Año, Mes, Producto, Región, Vendedor y Monto. Incluye datos 2023-2025.
B8: Datos Gastos | C8: Todos los gastos históricos | D8: Registra cada gasto con Año, Mes, Categoría, Descripción y Monto.
B9: Resumen Ventas | C9: Consolidado del año seleccionado | D9: Selecciona el año en la celda C5. Todo se recalcula automáticamente.
B10: Resumen Gastos | C10: Consolidado del año seleccionado | D10: Mismo selector de año. No editar las celdas de fórmula.
B11: Dashboard | C11: Panel de KPIs + comparativo anual | D11: Selecciona el año a analizar. Muestra evolución, comparativo vs año anterior y semáforos.
B12: Gráficos | C12: Gráficos dinámicos multi-año | D12: Líneas de evolución anual, barras por producto, torta por región, y comparativo inter-anual.

Sheet Configuración
B2: CONFIGURACIÓN · Listas maestras del sistema
B3: Edita aquí los nombres. Todo lo que escribas se refleja automáticamente en las listas desplegables de Datos Ventas / Datos Gastos, en los Resúmenes y en los Gráficos. No cambies los encabezados ni dejes huecos en medio de cada lista.
B5: PRODUCTOS | C5: CATEGORÍAS VENTA | D5: REGIONES | E5: VENDEDORES | F5: CATEGORÍAS GASTO
B6: Producto A | C6: Electrónica | D6: Norte | E6: Carlos Ríos | F6: Arriendo
B7: Producto B | C7: Ropa | D7: Sur | E7: María López | F7: Sueldos
B8: Producto C | C8: Alimentos | D8: Centro | E8: Juan Pérez | F8: Servicios básicos
B9: Producto D | C9: Servicios | D9: Oriente | E9: Ana Torres | F9: Insumos
B10: Producto E | C10: Otros | D10: Occidente | E10: Pedro Salas | F10: Publicidad
F11: Otros gastos
B27: Sugerencia: para añadir un producto nuevo, escríbelo en la primera celda amarilla vacía de la columna PRODUCTOS.

Sheet Datos Ventas
B2: DATOS DE VENTAS · HISTÓRICO MULTI-AÑO
B3: Ingresa aquí TODAS las ventas de todos los años. Usa la columna Año para diferenciar periodos.
B5: Fecha | C5: Año | D5: Mes | E5: Producto | F5: Región | G5: Vendedor | H5: Categoría | I5: Ventas ($) | J5: Unidades
B6: 44941 | C6: 2023 | D6: Enero | E6: Producto A | F6: Norte | G6: Carlos Ríos | H6: Electrónica | I6: 423000 | J6: 20
B7: 44972 | C7: 2023 | D7: Febrero | E7: Producto B | F7: Sur | G7: María López | H7: Ropa | I7: 473000 | J7: 25
B8: 45000 | C8: 2023 | D8: Marzo | E8: Producto C | F8: Centro | G8: Juan Pérez | H8: Alimentos | I8: 523000 | J8: 30
B9: 45306 | C9: 2024 | D9: Enero | E9: Producto A | F9: Norte | G9: Carlos Ríos | H9: Electrónica | I9: 424000 | J9: 20
B10: 45337 | C10: 2024 | D10: Febrero | E10: Producto B | F10: Sur | G10: María López | H10: Ropa | I10: 474000 | J10: 25
B11: 45366 | C11: 2024 | D11: Marzo | E11: Producto C | F11: Centro | G11: Juan Pérez | H11: Alimentos | I11: 524000 | J11: 30
B12: 45672 | C12: 2025 | D12: Enero | E12: Producto A | F12: Norte | G12: Carlos Ríos | H12: Electrónica | I12: 425000 | J12: 20
B13: 45703 | C13: 2025 | D13: Febrero | E13: Producto B | F13: Sur | G13: María López | H13: Ropa | I13: 475000 | J13: 25
B14: 45731 | C14: 2025 | D14: Marzo | E14: Producto C | F14: Centro | G14: Juan Pérez | H14: Alimentos | I14: 525000 | J14: 30

Sheet Datos Gastos
B2: DATOS DE GASTOS · HISTÓRICO MULTI-AÑO
B3: Registra aquí TODOS los gastos de todos los años. Usa la columna Año para diferenciar periodos.
B5: Fecha | C5: Año | D5: Mes | E5: Categoría | F5: Descripción | G5: Monto ($) | H5: Nota
B6: 44931 | C6: 2023 | D6: Enero | E6: Arriendo | F6: Local centro | G6: 318400 | H6: Ejemplo
B7: 44962 | C7: 2023 | D7: Febrero | E7: Sueldos | F7: Planilla mensual | G7: 358400 | H7: Ejemplo
B8: 44990 | C8: 2023 | D8: Marzo | E8: Insumos | F8: Materia prima | G8: 398400 | H8: Ejemplo
B9: 45296 | C9: 2024 | D9: Enero | E9: Arriendo | F9: Local centro | G9: 319200 | H9: Ejemplo
B10: 45327 | C10: 2024 | D10: Febrero | E10: Sueldos | F10: Planilla mensual | G10: 359200 | H10: Ejemplo
B11: 45356 | C11: 2024 | D11: Marzo | E11: Insumos | F11: Materia prima | G11: 399200 | H11: Ejemplo
B12: 45662 | C12: 2025 | D12: Enero | E12: Arriendo | F12: Local centro | G12: 320000 | H12: Ejemplo
B13: 45693 | C13: 2025 | D13: Febrero | E13: Sueldos | F13: Planilla mensual | G13: 360000 | H13: Ejemplo
B14: 45721 | C14: 2025 | D14: Marzo | E14: Insumos | F14: Materia prima | G14: 400000 | H14: Ejemplo

Sheet Resumen Ventas
B2: RESUMEN DE VENTAS · Consolidado por Año
B3: Selecciona el año a consultar. Los datos se consolidan automáticamente desde Datos Ventas con SUMIFS.
B5: Año a consultar: | C5: =Dashboard!$D$3 -> 2025 | D5: El año se controla desde la hoja Dashboard (celda D4)
B8: Producto / Mes | C8: Ene | D8: Feb | E8: Mar | F8: Abr | G8: May | H8: Jun | I8: Jul | J8: Ago | K8: Sep | L8: Oct | M8: Nov | N8: Dic | O8: Total Anual | P8: % del Total
B9: VENTAS POR PRODUCTO ($)
B10: =Configuración!$B$6 -> Producto A | C10: =SUMIFS('Datos Ventas'!$I$6:$I$605,'Datos Ventas'!$E$6:$E$605,$B10,'Datos Ventas'!$D$6:$D$605,"Enero",'Datos Ventas'!$C$6:$C$605,$C$5) -> 425000 | D10: =SUMIFS('Datos Ventas'!$I$6:$I$605,'Datos Ventas'!$E$6:$E$605,$B10,'Datos Ventas'!$D$6:$D$605,"Febrero",'Datos Ventas'!$C$6:$C$605,$C$5) -> 0 | E10: =SUMIFS('Datos Ventas'!$I$6:$I$605,'Datos Ventas'!$E$6:$E$605,$B10,'Datos Ventas'!$D$6:$D$605,"Marzo",'Datos Ventas'!$C$6:$C$605,$C$5) -> 0 | F10: =SUMIFS('Datos Ventas'!$I$6:$I$605,'Datos Ventas'!$E$6:$E$605,$B10,'Datos Ventas'!$D$6:$D$605,"Abril",'Datos Ventas'!$C$6:$C$605,$C$5) -> 0 | G10: =SUMIFS('Datos Ventas'!$I$6:$I$605,'Datos Ventas'!$E$6:$E$605,$B10,'Datos Ventas'!$D$6:$D$605,"Mayo",'Datos Ventas'!$C$6:$C$605,$C$5) -> 0 | H10: =SUMIFS('Datos Ventas'!$I$6:$I$605,'Datos Ventas'!$E$6:$E$605,$B10,'Datos Ventas'!$D$6:$D$605,"Junio",'Datos Ventas'!$C$6:$C$605,$C$5) -> 0 | I10: =SUMIFS('Datos Ventas'!$I$6:$I$605,'Datos Ventas'!$E$6:$E$605,$B10,'Datos Ventas'!$D$6:$D$605,"Julio",'Datos Ventas'!$C$6:$C$605,$C$5) -> 0 | J10: =SUMIFS('Datos Ventas'!$I$6:$I$605,'Datos Ventas'!$E$6:$E$605,$B10,'Datos Ventas'!$D$6:$D$605,"Agosto",'Datos Ventas'!$C$6:$C$605,$C$5) -> 0 | K10: =SUMIFS('Datos Ventas'!$I$6:$I$605,'Datos Ventas'!$E$6:$E$605,$B10,'Datos Ventas'!$D$6:$D$605,"Septiembre",'Datos Ventas'!$C$6:$C$605,$C$5) -> 0 | L10: =SUMIFS('Datos Ventas'!$I$6:$I$605,'Datos Ventas'!$E$6:$E$605,$B10,'Datos Ventas'!$D$6:$D$605,"Octubre",'Datos Ventas'!$C$6:$C$605,$C$5) -> 0 | M10: =SUMIFS('Datos Ventas'!$I$6:$I$605,'Datos Ventas'!$E$6:$E$605,$B10,'Datos Ventas'!$D$6:$D$605,"Noviembre",'Datos Ventas'!$C$6:$C$605,$C$5) -> 0 | N10: =SUMIFS('Datos Ventas'!$I$6:$I$605,'Datos Ventas'!$E$6:$E$605,$B10,'Datos Ventas'!$D$6:$D$605,"Diciembre",'Datos Ventas'!$C$6:$C$605,$C$5) -> 0 | O10: =SUM(C10:N10) -> 425000 | P10: =IF(O15=0,0,O10/O15) -> 0.29824561
B11: =Configuración!$B$7 -> Producto B | C11: =SUMIFS('Datos Ventas'!$I$6:$I$605,'Datos Ventas'!$E$6:$E$605,$B11,'Datos Ventas'!$D$6:$D$605,"Enero",'Datos Ventas'!$C$6:$C$605,$C$5) -> 0 | D11: =SUMIFS('Datos Ventas'!$I$6:$I$605,'Datos Ventas'!$E$6:$E$605,$B11,'Datos Ventas'!$D$6:$D$605,"Febrero",'Datos Ventas'!$C$6:$C$605,$C$5) -> 475000 | E11: =SUMIFS('Datos Ventas'!$I$6:$I$605,'Datos Ventas'!$E$6:$E$605,$B11,'Datos Ventas'!$D$6:$D$605,"Marzo",'Datos Ventas'!$C$6:$C$605,$C$5) -> 0 | F11: =SUMIFS('Datos Ventas'!$I$6:$I$605,'Datos Ventas'!$E$6:$E$605,$B11,'Datos Ventas'!$D$6:$D$605,"Abril",'Datos Ventas'!$C$6:$C$605,$C$5) -> 0 | G11: =SUMIFS('Datos Ventas'!$I$6:$I$605,'Datos Ventas'!$E$6:$E$605,$B11,'Datos Ventas'!$D$6:$D$605,"Mayo",'Datos Ventas'!$C$6:$C$605,$C$5) -> 0 | H11: =SUMIFS('Datos Ventas'!$I$6:$I$605,'Datos Ventas'!$E$6:$E$605,$B11,'Datos Ventas'!$D$6:$D$605,"Junio",'Datos Ventas'!$C$6:$C$605,$C$5) -> 0 | I11: =SUMIFS('Datos Ventas'!$I$6:$I$605,'Datos Ventas'!$E$6:$E$605,$B11,'Datos Ventas'!$D$6:$D$605,"Julio",'Datos Ventas'!$C$6:$C$605,$C$5) -> 0 | J11: =SUMIFS('Datos Ventas'!$I$6:$I$605,'Datos Ventas'!$E$6:$E$605,$B11,'Datos Ventas'!$D$6:$D$605,"Agosto",'Datos Ventas'!$C$6:$C$605,$C$5) -> 0 | K11: =SUMIFS('Datos Ventas'!$I$6:$I$605,'Datos Ventas'!$E$6:$E$605,$B11,'Datos Ventas'!$D$6:$D$605,"Septiembre",'Datos Ventas'!$C$6:$C$605,$C$5) -> 0 | L11: =SUMIFS('Datos Ventas'!$I$6:$I$605,'Datos Ventas'!$E$6:$E$605,$B11,'Datos Ventas'!$D$6:$D$605,"Octubre",'Datos Ventas'!$C$6:$C$605,$C$5) -> 0 | M11: =SUMIFS('Datos Ventas'!$I$6:$I$605,'Datos Ventas'!$E$6:$E$605,$B11,'Datos Ventas'!$D$6:$D$605,"Noviembre",'Datos Ventas'!$C$6:$C$605,$C$5) -> 0 | N11: =SUMIFS('Datos Ventas'!$I$6:$I$605,'Datos Ventas'!$E$6:$E$605,$B11,'Datos Ventas'!$D$6:$D$605,"Diciembre",'Datos Ventas'!$C$6:$C$605,$C$5) -> 0 | O11: =SUM(C11:N11) -> 475000 | P11: =IF(O15=0,0,O11/O15) -> 0.33333333
B12: =Configuración!$B$8 -> Producto C | C12: =SUMIFS('Datos Ventas'!$I$6:$I$605,'Datos Ventas'!$E$6:$E$605,$B12,'Datos Ventas'!$D$6:$D$605,"Enero",'Datos Ventas'!$C$6:$C$605,$C$5) -> 0 | D12: =SUMIFS('Datos Ventas'!$I$6:$I$605,'Datos Ventas'!$E$6:$E$605,$B12,'Datos Ventas'!$D$6:$D$605,"Febrero",'Datos Ventas'!$C$6:$C$605,$C$5) -> 0 | E12: =SUMIFS('Datos Ventas'!$I$6:$I$605,'Datos Ventas'!$E$6:$E$605,$B12,'Datos Ventas'!$D$6:$D$605,"Marzo",'Datos Ventas'!$C$6:$C$605,$C$5) -> 525000 | F12: =SUMIFS('Datos Ventas'!$I$6:$I$605,'Datos Ventas'!$E$6:$E$605,$B12,'Datos Ventas'!$D$6:$D$605,"Abril",'Datos Ventas'!$C$6:$C$605,$C$5) -> 0 | G12: =SUMIFS('Datos Ventas'!$I$6:$I$605,'Datos Ventas'!$E$6:$E$605,$B12,'Datos Ventas'!$D$6:$D$605,"Mayo",'Datos Ventas'!$C$6:$C$605,$C$5) -> 0 | H12: =SUMIFS('Datos Ventas'!$I$6:$I$605,'Datos Ventas'!$E$6:$E$605,$B12,'Datos Ventas'!$D$6:$D$605,"Junio",'Datos Ventas'!$C$6:$C$605,$C$5) -> 0 | I12: =SUMIFS('Datos Ventas'!$I$6:$I$605,'Datos Ventas'!$E$6:$E$605,$B12,'Datos Ventas'!$D$6:$D$605,"Julio",'Datos Ventas'!$C$6:$C$605,$C$5) -> 0 | J12: =SUMIFS('Datos Ventas'!$I$6:$I$605,'Datos Ventas'!$E$6:$E$605,$B12,'Datos Ventas'!$D$6:$D$605,"Agosto",'Datos Ventas'!$C$6:$C$605,$C$5) -> 0 | K12: =SUMIFS('Datos Ventas'!$I$6:$I$605,'Datos Ventas'!$E$6:$E$605,$B12,'Datos Ventas'!$D$6:$D$605,"Septiembre",'Datos Ventas'!$C$6:$C$605,$C$5) -> 0 | L12: =SUMIFS('Datos Ventas'!$I$6:$I$605,'Datos Ventas'!$E$6:$E$605,$B12,'Datos Ventas'!$D$6:$D$605,"Octubre",'Datos Ventas'!$C$6:$C$605,$C$5) -> 0 | M12: =SUMIFS('Datos Ventas'!$I$6:$I$605,'Datos Ventas'!$E$6:$E$605,$B12,'Datos Ventas'!$D$6:$D$605,"Noviembre",'Datos Ventas'!$C$6:$C$605,$C$5) -> 0 | N12: =SUMIFS('Datos Ventas'!$I$6:$I$605,'Datos Ventas'!$E$6:$E$605,$B12,'Datos Ventas'!$D$6:$D$605,"Diciembre",'Datos Ventas'!$C$6:$C$605,$C$5) -> 0 | O12: =SUM(C12:N12) -> 525000 | P12: =IF(O15=0,0,O12/O15) -> 0.36842105
B13: =Configuración!$B$9 -> Producto D | C13: =SUMIFS('Datos Ventas'!$I$6:$I$605,'Datos Ventas'!$E$6:$E$605,$B13,'Datos Ventas'!$D$6:$D$605,"Enero",'Datos Ventas'!$C$6:$C$605,$C$5) -> 0 | D13: =SUMIFS('Datos Ventas'!$I$6:$I$605,'Datos Ventas'!$E$6:$E$605,$B13,'Datos Ventas'!$D$6:$D$605,"Febrero",'Datos Ventas'!$C$6:$C$605,$C$5) -> 0 | E13: =SUMIFS('Datos Ventas'!$I$6:$I$605,'Datos Ventas'!$E$6:$E$605,$B13,'Datos Ventas'!$D$6:$D$605,"Marzo",'Datos Ventas'!$C$6:$C$605,$C$5) -> 0 | F13: =SUMIFS('Datos Ventas'!$I$6:$I$605,'Datos Ventas'!$E$6:$E$605,$B13,'Datos Ventas'!$D$6:$D$605,"Abril",'Datos Ventas'!$C$6:$C$605,$C$5) -> 0 | G13: =SUMIFS('Datos Ventas'!$I$6:$I$605,'Datos Ventas'!$E$6:$E$605,$B13,'Datos Ventas'!$D$6:$D$605,"Mayo",'Datos Ventas'!$C$6:$C$605,$C$5) -> 0 | H13: =SUMIFS('Datos Ventas'!$I$6:$I$605,'Datos Ventas'!$E$6:$E$605,$B13,'Datos Ventas'!$D$6:$D$605,"Junio",'Datos Ventas'!$C$6:$C$605,$C$5) -> 0 | I13: =SUMIFS('Datos Ventas'!$I$6:$I$605,'Datos Ventas'!$E$6:$E$605,$B13,'Datos Ventas'!$D$6:$D$605,"Julio",'Datos Ventas'!$C$6:$C$605,$C$5) -> 0 | J13: =SUMIFS('Datos Ventas'!$I$6:$I$605,'Datos Ventas'!$E$6:$E$605,$B13,'Datos Ventas'!$D$6:$D$605,"Agosto",'Datos Ventas'!$C$6:$C$605,$C$5) -> 0 | K13: =SUMIFS('Datos Ventas'!$I$6:$I$605,'Datos Ventas'!$E$6:$E$605,$B13,'Datos Ventas'!$D$6:$D$605,"Septiembre",'Datos Ventas'!$C$6:$C$605,$C$5) -> 0 | L13: =SUMIFS('Datos Ventas'!$I$6:$I$605,'Datos Ventas'!$E$6:$E$605,$B13,'Datos Ventas'!$D$6:$D$605,"Octubre",'Datos Ventas'!$C$6:$C$605,$C$5) -> 0 | M13: =SUMIFS('Datos Ventas'!$I$6:$I$605,'Datos Ventas'!$E$6:$E$605,$B13,'Datos Ventas'!$D$6:$D$605,"Noviembre",'Datos Ventas'!$C$6:$C$605,$C$5) -> 0 | N13: =SUMIFS('Datos Ventas'!$I$6:$I$605,'Datos Ventas'!$E$6:$E$605,$B13,'Datos Ventas'!$D$6:$D$605,"Diciembre",'Datos Ventas'!$C$6:$C$605,$C$5) -> 0 | O13: =SUM(C13:N13) -> 0 | P13: =IF(O15=0,0,O13/O15) -> 0
B14: =Configuración!$B$10 -> Producto E | C14: =SUMIFS('Datos Ventas'!$I$6:$I$605,'Datos Ventas'!$E$6:$E$605,$B14,'Datos Ventas'!$D$6:$D$605,"Enero",'Datos Ventas'!$C$6:$C$605,$C$5) -> 0 | D14: =SUMIFS('Datos Ventas'!$I$6:$I$605,'Datos Ventas'!$E$6:$E$605,$B14,'Datos Ventas'!$D$6:$D$605,"Febrero",'Datos Ventas'!$C$6:$C$605,$C$5) -> 0 | E14: =SUMIFS('Datos Ventas'!$I$6:$I$605,'Datos Ventas'!$E$6:$E$605,$B14,'Datos Ventas'!$D$6:$D$605,"Marzo",'Datos Ventas'!$C$6:$C$605,$C$5) -> 0 | F14: =SUMIFS('Datos Ventas'!$I$6:$I$605,'Datos Ventas'!$E$6:$E$605,$B14,'Datos Ventas'!$D$6:$D$605,"Abril",'Datos Ventas'!$C$6:$C$605,$C$5) -> 0 | G14: =SUMIFS('Datos Ventas'!$I$6:$I$605,'Datos Ventas'!$E$6:$E$605,$B14,'Datos Ventas'!$D$6:$D$605,"Mayo",'Datos Ventas'!$C$6:$C$605,$C$5) -> 0 | H14: =SUMIFS('Datos Ventas'!$I$6:$I$605,'Datos Ventas'!$E$6:$E$605,$B14,'Datos Ventas'!$D$6:$D$605,"Junio",'Datos Ventas'!$C$6:$C$605,$C$5) -> 0 | I14: =SUMIFS('Datos Ventas'!$I$6:$I$605,'Datos Ventas'!$E$6:$E$605,$B14,'Datos Ventas'!$D$6:$D$605,"Julio",'Datos Ventas'!$C$6:$C$605,$C$5) -> 0 | J14: =SUMIFS('Datos Ventas'!$I$6:$I$605,'Datos Ventas'!$E$6:$E$605,$B14,'Datos Ventas'!$D$6:$D$605,"Agosto",'Datos Ventas'!$C$6:$C$605,$C$5) -> 0 | K14: =SUMIFS('Datos Ventas'!$I$6:$I$605,'Datos Ventas'!$E$6:$E$605,$B14,'Datos Ventas'!$D$6:$D$605,"Septiembre",'Datos Ventas'!$C$6:$C$605,$C$5) -> 0 | L14: =SUMIFS('Datos Ventas'!$I$6:$I$605,'Datos Ventas'!$E$6:$E$605,$B14,'Datos Ventas'!$D$6:$D$605,"Octubre",'Datos Ventas'!$C$6:$C$605,$C$5) -> 0 | M14: =SUMIFS('Datos Ventas'!$I$6:$I$605,'Datos Ventas'!$E$6:$E$605,$B14,'Datos Ventas'!$D$6:$D$605,"Noviembre",'Datos Ventas'!$C$6:$C$605,$C$5) -> 0 | N14: =SUMIFS('Datos Ventas'!$I$6:$I$605,'Datos Ventas'!$E$6:$E$605,$B14,'Datos Ventas'!$D$6:$D$605,"Diciembre",'Datos Ventas'!$C$6:$C$605,$C$5) -> 0 | O14: =SUM(C14:N14) -> 0 | P14: =IF(O15=0,0,O14/O15) -> 0
B15: TOTAL VENTAS | C15: =SUM(C10:C14) -> 425000 | D15: =SUM(D10:D14) -> 475000 | E15: =SUM(E10:E14) -> 525000 | F15: =SUM(F10:F14) -> 0 | G15: =SUM(G10:G14) -> 0 | H15: =SUM(H10:H14) -> 0 | I15: =SUM(I10:I14) -> 0 | J15: =SUM(J10:J14) -> 0 | ... O15: =SUM(O10:O14) -> 1425000
B17: VENTAS POR REGIÓN ($)
B18: =Configuración!$D$6 -> Norte | C18: =SUMIFS('Datos Ventas'!$I$6:$I$605,'Datos Ventas'!$F$6:$F$605,$B18,'Datos Ventas'!$D$6:$D$605,"Enero",'Datos Ventas'!$C$6:$C$605,$C$5) -> 425000 | D18: =SUMIFS('Datos Ventas'!$I$6:$I$605,'Datos Ventas'!$F$6:$F$605,$B18,'Datos Ventas'!$D$6:$D$605,"Febrero",'Datos Ventas'!$C$6:$C$605,$C$5) -> 0 | E18: =SUMIFS('Datos Ventas'!$I$6:$I$605,'Datos Ventas'!$F$6:$F$605,$B18,'Datos Ventas'!$D$6:$D$605,"Marzo",'Datos Ventas'!$C$6:$C$605,$C$5) -> 0 | F18: =SUMIFS('Datos Ventas'!$I$6:$I$605,'Datos Ventas'!$F$6:$F$605,$B18,'Datos Ventas'!$D$6:$D$605,"Abril",'Datos Ventas'!$C$6:$C$605,$C$5) -> 0 | G18: =SUMIFS('Datos Ventas'!$I$6:$I$605,'Datos Ventas'!$F$6:$F$605,$B18,'Datos Ventas'!$D$6:$D$605,"Mayo",'Datos Ventas'!$C$6:$C$605,$C$5) -> 0 | H18: =SUMIFS('Datos Ventas'!$I$6:$I$605,'Datos Ventas'!$F$6:$F$605,$B18,'Datos Ventas'!$D$6:$D$605,"Junio",'Datos Ventas'!$C$6:$C$605,$C$5) -> 0 | I18: =SUMIFS('Datos Ventas'!$I$6:$I$605,'Datos Ventas'!$F$6:$F$605,$B18,'Datos Ventas'!$D$6:$D$605,"Julio",'Datos Ventas'!$C$6:$C$605,$C$5) -> 0 | J18: =SUMIFS('Datos Ventas'!$I$6:$I$605,'Datos Ventas'!$F$6:$F$605,$B18,'Datos Ventas'!$D$6:$D$605,"Agosto",'Datos Ventas'!$C$6:$C$605,$C$5) -> 0 | K18: =SUMIFS('Datos Ventas'!$I$6:$I$605,'Datos Ventas'!$F$6:$F$605,$B18,'Datos Ventas'!$D$6:$D$605,"Septiembre",'Datos Ventas'!$C$6:$C$605,$C$5) -> 0 | L18: =SUMIFS('Datos Ventas'!$I$6:$I$605,'Datos Ventas'!$F$6:$F$605,$B18,'Datos Ventas'!$D$6:$D$605,"Octubre",'Datos Ventas'!$C$6:$C$605,$C$5) -> 0 | M18: =SUMIFS('Datos Ventas'!$I$6:$I$605,'Datos Ventas'!$F$6:$F$605,$B18,'Datos Ventas'!$D$6:$D$605,"Noviembre",'Datos Ventas'!$C$6:$C$605,$C$5) -> 0 | N18: =SUMIFS('Datos Ventas'!$I$6:$I$605,'Datos Ventas'!$F$6:$F$605,$B18,'Datos Ventas'!$D$6:$D$605,"Diciembre",'Datos Ventas'!$C$6:$C$605,$C$5) -> 0 | O18: =SUM(C18:N18) -> 425000 | P18: =IF(O15=0,0,O18/O15) -> 0.29824561
B19: =Configuración!$D$7 -> Sur | C19: =SUMIFS('Datos Ventas'!$I$6:$I$605,'Datos Ventas'!$F$6:$F$605,$B19,'Datos Ventas'!$D$6:$D$605,"Enero",'Datos Ventas'!$C$6:$C$605,$C$5) -> 0 | D19: =SUMIFS('Datos Ventas'!$I$6:$I$605,'Datos Ventas'!$F$6:$F$605,$B19,'Datos Ventas'!$D$6:$D$605,"Febrero",'Datos Ventas'!$C$6:$C$605,$C$5) -> 475000 | E19: =SUMIFS('Datos Ventas'!$I$6:$I$605,'Datos Ventas'!$F$6:$F$605,$B19,'Datos Ventas'!$D$6:$D$605,"Marzo",'Datos Ventas'!$C$6:$C$605,$C$5) -> 0 | F19: =SUMIFS('Datos Ventas'!$I$6:$I$605,'Datos Ventas'!$F$6:$F$605,$B19,'Datos Ventas'!$D$6:$D$605,"Abril",'Datos Ventas'!$C$6:$C$605,$C$5) -> 0 | G19: =SUMIFS('Datos Ventas'!$I$6:$I$605,'Datos Ventas'!$F$6:$F$605,$B19,'Datos Ventas'!$D$6:$D$605,"Mayo",'Datos Ventas'!$C$6:$C$605,$C$5) -> 0 | H19: =SUMIFS('Datos Ventas'!$I$6:$I$605,'Datos Ventas'!$F$6:$F$605,$B19,'Datos Ventas'!$D$6:$D$605,"Junio",'Datos Ventas'!$C$6:$C$605,$C$5) -> 0 | I19: =SUMIFS('Datos Ventas'!$I$6:$I$605,'Datos Ventas'!$F$6:$F$605,$B19,'Datos Ventas'!$D$6:$D$605,"Julio",'Datos Ventas'!$C$6:$C$605,$C$5) -> 0 | J19: =SUMIFS('Datos Ventas'!$I$6:$I$605,'Datos Ventas'!$F$6:$F$605,$B19,'Datos Ventas'!$D$6:$D$605,"Agosto",'Datos Ventas'!$C$6:$C$605,$C$5) -> 0 | K19: =SUMIFS('Datos Ventas'!$I$6:$I$605,'Datos Ventas'!$F$6:$F$605,$B19,'Datos Ventas'!$D$6:$D$605,"Septiembre",'Datos Ventas'!$C$6:$C$605,$C$5) -> 0 | L19: =SUMIFS('Datos Ventas'!$I$6:$I$605,'Datos Ventas'!$F$6:$F$605,$B19,'Datos Ventas'!$D$6:$D$605,"Octubre",'Datos Ventas'!$C$6:$C$605,$C$5) -> 0 | M19: =SUMIFS('Datos Ventas'!$I$6:$I$605,'Datos Ventas'!$F$6:$F$605,$B19,'Datos Ventas'!$D$6:$D$605,"Noviembre",'Datos Ventas'!$C$6:$C$605,$C$5) -> 0 | N19: =SUMIFS('Datos Ventas'!$I$6:$I$605,'Datos Ventas'!$F$6:$F$605,$B19,'Datos Ventas'!$D$6:$D$605,"Diciembre",'Datos Ventas'!$C$6:$C$605,$C$5) -> 0 | O19: =SUM(C19:N19) -> 475000 | P19: =IF(O15=0,0,O19/O15) -> 0.33333333
B20: =Configuración!$D$8 -> Centro | C20: =SUMIFS('Datos Ventas'!$I$6:$I$605,'Datos Ventas'!$F$6:$F$605,$B20,'Datos Ventas'!$D$6:$D$605,"Enero",'Datos Ventas'!$C$6:$C$605,$C$5) -> 0 | D20: =SUMIFS('Datos Ventas'!$I$6:$I$605,'Datos Ventas'!$F$6:$F$605,$B20,'Datos Ventas'!$D$6:$D$605,"Febrero",'Datos Ventas'!$C$6:$C$605,$C$5) -> 0 | E20: =SUMIFS('Datos Ventas'!$I$6:$I$605,'Datos Ventas'!$F$6:$F$605,$B20,'Datos Ventas'!$D$6:$D$605,"Marzo",'Datos Ventas'!$C$6:$C$605,$C$5) -> 525000 | F20: =SUMIFS('Datos Ventas'!$I$6:$I$605,'Datos Ventas'!$F$6:$F$605,$B20,'Datos Ventas'!$D$6:$D$605,"Abril",'Datos Ventas'!$C$6:$C$605,$C$5) -> 0 | G20: =SUMIFS('Datos Ventas'!$I$6:$I$605,'Datos Ventas'!$F$6:$F$605,$B20,'Datos Ventas'!$D$6:$D$605,"Mayo",'Datos Ventas'!$C$6:$C$605,$C$5) -> 0 | H20: =SUMIFS('Datos Ventas'!$I$6:$I$605,'Datos Ventas'!$F$6:$F$605,$B20,'Datos Ventas'!$D$6:$D$605,"Junio",'Datos Ventas'!$C$6:$C$605,$C$5) -> 0 | I20: =SUMIFS('Datos Ventas'!$I$6:$I$605,'Datos Ventas'!$F$6:$F$605,$B20,'Datos Ventas'!$D$6:$D$605,"Julio",'Datos Ventas'!$C$6:$C$605,$C$5) -> 0 | J20: =SUMIFS('Datos Ventas'!$I$6:$I$605,'Datos Ventas'!$F$6:$F$605,$B20,'Datos Ventas'!$D$6:$D$605,"Agosto",'Datos Ventas'!$C$6:$C$605,$C$5) -> 0 | K20: =SUMIFS('Datos Ventas'!$I$6:$I$605,'Datos Ventas'!$F$6:$F$605,$B20,'Datos Ventas'!$D$6:$D$605,"Septiembre",'Datos Ventas'!$C$6:$C$605,$C$5) -> 0 | L20: =SUMIFS('Datos Ventas'!$I$6:$I$605,'Datos Ventas'!$F$6:$F$605,$B20,'Datos Ventas'!$D$6:$D$605,"Octubre",'Datos Ventas'!$C$6:$C$605,$C$5) -> 0 | M20: =SUMIFS('Datos Ventas'!$I$6:$I$605,'Datos Ventas'!$F$6:$F$605,$B20,'Datos Ventas'!$D$6:$D$605,"Noviembre",'Datos Ventas'!$C$6:$C$605,$C$5) -> 0 | N20: =SUMIFS('Datos Ventas'!$I$6:$I$605,'Datos Ventas'!$F$6:$F$605,$B20,'Datos Ventas'!$D$6:$D$605,"Diciembre",'Datos Ventas'!$C$6:$C$605,$C$5) -> 0 | O20: =SUM(C20:N20) -> 525000 | P20: =IF(O15=0,0,O20/O15) -> 0.36842105
B21: =Configuración!$D$9 -> Oriente | C21: =SUMIFS('Datos Ventas'!$I$6:$I$605,'Datos Ventas'!$F$6:$F$605,$B21,'Datos Ventas'!$D$6:$D$605,"Enero",'Datos Ventas'!$C$6:$C$605,$C$5) -> 0 | D21: =SUMIFS('Datos Ventas'!$I$6:$I$605,'Datos Ventas'!$F$6:$F$605,$B21,'Datos Ventas'!$D$6:$D$605,"Febrero",'Datos Ventas'!$C$6:$C$605,$C$5) -> 0 | E21: =SUMIFS('Datos Ventas'!$I$6:$I$605,'Datos Ventas'!$F$6:$F$605,$B21,'Datos Ventas'!$D$6:$D$605,"Marzo",'Datos Ventas'!$C$6:$C$605,$C$5) -> 0 | F21: =SUMIFS('Datos Ventas'!$I$6:$I$605,'Datos Ventas'!$F$6:$F$605,$B21,'Datos Ventas'!$D$6:$D$605,"Abril",'Datos Ventas'!$C$6:$C$605,$C$5) -> 0 | G21: =SUMIFS('Datos Ventas'!$I$6:$I$605,'Datos Ventas'!$F$6:$F$605,$B21,'Datos Ventas'!$D$6:$D$605,"Mayo",'Datos Ventas'!$C$6:$C$605,$C$5) -> 0 | H21: =SUMIFS('Datos Ventas'!$I$6:$I$605,'Datos Ventas'!$F$6:$F$605,$B21,'Datos Ventas'!$D$6:$D$605,"Junio",'Datos Ventas'!$C$6:$C$605,$C$5) -> 0 | I21: =SUMIFS('Datos Ventas'!$I$6:$I$605,'Datos Ventas'!$F$6:$F$605,$B21,'Datos Ventas'!$D$6:$D$605,"Julio",'Datos Ventas'!$C$6:$C$605,$C$5) -> 0 | J21: =SUMIFS('Datos Ventas'!$I$6:$I$605,'Datos Ventas'!$F$6:$F$605,$B21,'Datos Ventas'!$D$6:$D$605,"Agosto",'Datos Ventas'!$C$6:$C$605,$C$5) -> 0 | K21: =SUMIFS('Datos Ventas'!$I$6:$I$605,'Datos Ventas'!$F$6:$F$605,$B21,'Datos Ventas'!$D$6:$D$605,"Septiembre",'Datos Ventas'!$C$6:$C$605,$C$5) -> 0 | L21: =SUMIFS('Datos Ventas'!$I$6:$I$605,'Datos Ventas'!$F$6:$F$605,$B21,'Datos Ventas'!$D$6:$D$605,"Octubre",'Datos Ventas'!$C$6:$C$605,$C$5) -> 0 | M21: =SUMIFS('Datos Ventas'!$I$6:$I$605,'Datos Ventas'!$F$6:$F$605,$B21,'Datos Ventas'!$D$6:$D$605,"Noviembre",'Datos Ventas'!$C$6:$C$605,$C$5) -> 0 | N21: =SUMIFS('Datos Ventas'!$I$6:$I$605,'Datos Ventas'!$F$6:$F$605,$B21,'Datos Ventas'!$D$6:$D$605,"Diciembre",'Datos Ventas'!$C$6:$C$605,$C$5) -> 0 | O21: =SUM(C21:N21) -> 0 | P21: =IF(O15=0,0,O21/O15) -> 0
B22: =Configuración!$D$10 -> Occidente | C22: =SUMIFS('Datos Ventas'!$I$6:$I$605,'Datos Ventas'!$F$6:$F$605,$B22,'Datos Ventas'!$D$6:$D$605,"Enero",'Datos Ventas'!$C$6:$C$605,$C$5) -> 0 | D22: =SUMIFS('Datos Ventas'!$I$6:$I$605,'Datos Ventas'!$F$6:$F$605,$B22,'Datos Ventas'!$D$6:$D$605,"Febrero",'Datos Ventas'!$C$6:$C$605,$C$5) -> 0 | E22: =SUMIFS('Datos Ventas'!$I$6:$I$605,'Datos Ventas'!$F$6:$F$605,$B22,'Datos Ventas'!$D$6:$D$605,"Marzo",'Datos Ventas'!$C$6:$C$605,$C$5) -> 0 | F22: =SUMIFS('Datos Ventas'!$I$6:$I$605,'Datos Ventas'!$F$6:$F$605,$B22,'Datos Ventas'!$D$6:$D$605,"Abril",'Datos Ventas'!$C$6:$C$605,$C$5) -> 0 | G22: =SUMIFS('Datos Ventas'!$I$6:$I$605,'Datos Ventas'!$F$6:$F$605,$B22,'Datos Ventas'!$D$6:$D$605,"Mayo",'Datos Ventas'!$C$6:$C$605,$C$5) -> 0 | H22: =SUMIFS('Datos Ventas'!$I$6:$I$605,'Datos Ventas'!$F$6:$F$605,$B22,'Datos Ventas'!$D$6:$D$605,"Junio",'Datos Ventas'!$C$6:$C$605,$C$5) -> 0 | I22: =SUMIFS('Datos Ventas'!$I$6:$I$605,'Datos Ventas'!$F$6:$F$605,$B22,'Datos Ventas'!$D$6:$D$605,"Julio",'Datos Ventas'!$C$6:$C$605,$C$5) -> 0 | J22: =SUMIFS('Datos Ventas'!$I$6:$I$605,'Datos Ventas'!$F$6:$F$605,$B22,'Datos Ventas'!$D$6:$D$605,"Agosto",'Datos Ventas'!$C$6:$C$605,$C$5) -> 0 | K22: =SUMIFS('Datos Ventas'!$I$6:$I$605,'Datos Ventas'!$F$6:$F$605,$B22,'Datos Ventas'!$D$6:$D$605,"Septiembre",'Datos Ventas'!$C$6:$C$605,$C$5) -> 0 | L22: =SUMIFS('Datos Ventas'!$I$6:$I$605,'Datos Ventas'!$F$6:$F$605,$B22,'Datos Ventas'!$D$6:$D$605,"Octubre",'Datos Ventas'!$C$6:$C$605,$C$5) -> 0 | M22: =SUMIFS('Datos Ventas'!$I$6:$I$605,'Datos Ventas'!$F$6:$F$605,$B22,'Datos Ventas'!$D$6:$D$605,"Noviembre",'Datos Ventas'!$C$6:$C$605,$C$5) -> 0 | N22: =SUMIFS('Datos Ventas'!$I$6:$I$605,'Datos Ventas'!$F$6:$F$605,$B22,'Datos Ventas'!$D$6:$D$605,"Diciembre",'Datos Ventas'!$C$6:$C$605,$C$5) -> 0 | O22: =SUM(C22:N22) -> 0 | P22: =IF(O15=0,0,O22/O15) -> 0
B23: TOTAL REGIONES | C23: =SUM(C18:C22) -> 425000 | D23: =SUM(D18:D22) -> 475000 | E23: =SUM(E18:E22) -> 525000 | F23: =SUM(F18:F22) -> 0 | G23: =SUM(G18:G22) -> 0 | H23: =SUM(H18:H22) -> 0 | I23: =SUM(I18:I22) -> 0 | J23: =SUM(J18:J22) -> 0 | ... O23: =SUM(O18:O22) -> 1425000
B25: VENTAS POR VENDEDOR ($)
B26: =Configuración!$E$6 -> Carlos Ríos | C26: =SUMIFS('Datos Ventas'!$I$6:$I$605,'Datos Ventas'!$G$6:$G$605,$B26,'Datos Ventas'!$D$6:$D$605,"Enero",'Datos Ventas'!$C$6:$C$605,$C$5) -> 425000 | D26: =SUMIFS('Datos Ventas'!$I$6:$I$605,'Datos Ventas'!$G$6:$G$605,$B26,'Datos Ventas'!$D$6:$D$605,"Febrero",'Datos Ventas'!$C$6:$C$605,$C$5) -> 0 | E26: =SUMIFS('Datos Ventas'!$I$6:$I$605,'Datos Ventas'!$G$6:$G$605,$B26,'Datos Ventas'!$D$6:$D$605,"Marzo",'Datos Ventas'!$C$6:$C$605,$C$5) -> 0 | F26: =SUMIFS('Datos Ventas'!$I$6:$I$605,'Datos Ventas'!$G$6:$G$605,$B26,'Datos Ventas'!$D$6:$D$605,"Abril",'Datos Ventas'!$C$6:$C$605,$C$5) -> 0 | G26: =SUMIFS('Datos Ventas'!$I$6:$I$605,'Datos Ventas'!$G$6:$G$605,$B26,'Datos Ventas'!$D$6:$D$605,"Mayo",'Datos Ventas'!$C$6:$C$605,$C$5) -> 0 | H26: =SUMIFS('Datos Ventas'!$I$6:$I$605,'Datos Ventas'!$G$6:$G$605,$B26,'Datos Ventas'!$D$6:$D$605,"Junio",'Datos Ventas'!$C$6:$C$605,$C$5) -> 0 | I26: =SUMIFS('Datos Ventas'!$I$6:$I$605,'Datos Ventas'!$G$6:$G$605,$B26,'Datos Ventas'!$D$6:$D$605,"Julio",'Datos Ventas'!$C$6:$C$605,$C$5) -> 0 | J26: =SUMIFS('Datos Ventas'!$I$6:$I$605,'Datos Ventas'!$G$6:$G$605,$B26,'Datos Ventas'!$D$6:$D$605,"Agosto",'Datos Ventas'!$C$6:$C$605,$C$5) -> 0 | K26: =SUMIFS('Datos Ventas'!$I$6:$I$605,'Datos Ventas'!$G$6:$G$605,$B26,'Datos Ventas'!$D$6:$D$605,"Septiembre",'Datos Ventas'!$C$6:$C$605,$C$5) -> 0 | L26: =SUMIFS('Datos Ventas'!$I$6:$I$605,'Datos Ventas'!$G$6:$G$605,$B26,'Datos Ventas'!$D$6:$D$605,"Octubre",'Datos Ventas'!$C$6:$C$605,$C$5) -> 0 | M26: =SUMIFS('Datos Ventas'!$I$6:$I$605,'Datos Ventas'!$G$6:$G$605,$B26,'Datos Ventas'!$D$6:$D$605,"Noviembre",'Datos Ventas'!$C$6:$C$605,$C$5) -> 0 | N26: =SUMIFS('Datos Ventas'!$I$6:$I$605,'Datos Ventas'!$G$6:$G$605,$B26,'Datos Ventas'!$D$6:$D$605,"Diciembre",'Datos Ventas'!$C$6:$C$605,$C$5) -> 0 | O26: =SUM(C26:N26) -> 425000 | P26: =IF(O15=0,0,O26/O15) -> 0.29824561
B27: =Configuración!$E$7 -> María López | C27: =SUMIFS('Datos Ventas'!$I$6:$I$605,'Datos Ventas'!$G$6:$G$605,$B27,'Datos Ventas'!$D$6:$D$605,"Enero",'Datos Ventas'!$C$6:$C$605,$C$5) -> 0 | D27: =SUMIFS('Datos Ventas'!$I$6:$I$605,'Datos Ventas'!$G$6:$G$605,$B27,'Datos Ventas'!$D$6:$D$605,"Febrero",'Datos Ventas'!$C$6:$C$605,$C$5) -> 475000 | E27: =SUMIFS('Datos Ventas'!$I$6:$I$605,'Datos Ventas'!$G$6:$G$605,$B27,'Datos Ventas'!$D$6:$D$605,"Marzo",'Datos Ventas'!$C$6:$C$605,$C$5) -> 0 | F27: =SUMIFS('Datos Ventas'!$I$6:$I$605,'Datos Ventas'!$G$6:$G$605,$B27,'Datos Ventas'!$D$6:$D$605,"Abril",'Datos Ventas'!$C$6:$C$605,$C$5) -> 0 | G27: =SUMIFS('Datos Ventas'!$I$6:$I$605,'Datos Ventas'!$G$6:$G$605,$B27,'Datos Ventas'!$D$6:$D$605,"Mayo",'Datos Ventas'!$C$6:$C$605,$C$5) -> 0 | H27: =SUMIFS('Datos Ventas'!$I$6:$I$605,'Datos Ventas'!$G$6:$G$605,$B27,'Datos Ventas'!$D$6:$D$605,"Junio",'Datos Ventas'!$C$6:$C$605,$C$5) -> 0 | I27: =SUMIFS('Datos Ventas'!$I$6:$I$605,'Datos Ventas'!$G$6:$G$605,$B27,'Datos Ventas'!$D$6:$D$605,"Julio",'Datos Ventas'!$C$6:$C$605,$C$5) -> 0 | J27: =SUMIFS('Datos Ventas'!$I$6:$I$605,'Datos Ventas'!$G$6:$G$605,$B27,'Datos Ventas'!$D$6:$D$605,"Agosto",'Datos Ventas'!$C$6:$C$605,$C$5) -> 0 | K27: =SUMIFS('Datos Ventas'!$I$6:$I$605,'Datos Ventas'!$G$6:$G$605,$B27,'Datos Ventas'!$D$6:$D$605,"Septiembre",'Datos Ventas'!$C$6:$C$605,$C$5) -> 0 | L27: =SUMIFS('Datos Ventas'!$I$6:$I$605,'Datos Ventas'!$G$6:$G$605,$B27,'Datos Ventas'!$D$6:$D$605,"Octubre",'Datos Ventas'!$C$6:$C$605,$C$5) -> 0 | M27: =SUMIFS('Datos Ventas'!$I$6:$I$605,'Datos Ventas'!$G$6:$G$605,$B27,'Datos Ventas'!$D$6:$D$605,"Noviembre",'Datos Ventas'!$C$6:$C$605,$C$5) -> 0 | N27: =SUMIFS('Datos Ventas'!$I$6:$I$605,'Datos Ventas'!$G$6:$G$605,$B27,'Datos Ventas'!$D$6:$D$605,"Diciembre",'Datos Ventas'!$C$6:$C$605,$C$5) -> 0 | O27: =SUM(C27:N27) -> 475000 | P27: =IF(O15=0,0,O27/O15) -> 0.33333333
B28: =Configuración!$E$8 -> Juan Pérez | C28: =SUMIFS('Datos Ventas'!$I$6:$I$605,'Datos Ventas'!$G$6:$G$605,$B28,'Datos Ventas'!$D$6:$D$605,"Enero",'Datos Ventas'!$C$6:$C$605,$C$5) -> 0 | D28: =SUMIFS('Datos Ventas'!$I$6:$I$605,'Datos Ventas'!$G$6:$G$605,$B28,'Datos Ventas'!$D$6:$D$605,"Febrero",'Datos Ventas'!$C$6:$C$605,$C$5) -> 0 | E28: =SUMIFS('Datos Ventas'!$I$6:$I$605,'Datos Ventas'!$G$6:$G$605,$B28,'Datos Ventas'!$D$6:$D$605,"Marzo",'Datos Ventas'!$C$6:$C$605,$C$5) -> 525000 | F28: =SUMIFS('Datos Ventas'!$I$6:$I$605,'Datos Ventas'!$G$6:$G$605,$B28,'Datos Ventas'!$D$6:$D$605,"Abril",'Datos Ventas'!$C$6:$C$605,$C$5) -> 0 | G28: =SUMIFS('Datos Ventas'!$I$6:$I$605,'Datos Ventas'!$G$6:$G$605,$B28,'Datos Ventas'!$D$6:$D$605,"Mayo",'Datos Ventas'!$C$6:$C$605,$C$5) -> 0 | H28: =SUMIFS('Datos Ventas'!$I$6:$I$605,'Datos Ventas'!$G$6:$G$605,$B28,'Datos Ventas'!$D$6:$D$605,"Junio",'Datos Ventas'!$C$6:$C$605,$C$5) -> 0 | I28: =SUMIFS('Datos Ventas'!$I$6:$I$605,'Datos Ventas'!$G$6:$G$605,$B28,'Datos Ventas'!$D$6:$D$605,"Julio",'Datos Ventas'!$C$6:$C$605,$C$5) -> 0 | J28: =SUMIFS('Datos Ventas'!$I$6:$I$605,'Datos Ventas'!$G$6:$G$605,$B28,'Datos Ventas'!$D$6:$D$605,"Agosto",'Datos Ventas'!$C$6:$C$605,$C$5) -> 0 | K28: =SUMIFS('Datos Ventas'!$I$6:$I$605,'Datos Ventas'!$G$6:$G$605,$B28,'Datos Ventas'!$D$6:$D$605,"Septiembre",'Datos Ventas'!$C$6:$C$605,$C$5) -> 0 | L28: =SUMIFS('Datos Ventas'!$I$6:$I$605,'Datos Ventas'!$G$6:$G$605,$B28,'Datos Ventas'!$D$6:$D$605,"Octubre",'Datos Ventas'!$C$6:$C$605,$C$5) -> 0 | M28: =SUMIFS('Datos Ventas'!$I$6:$I$605,'Datos Ventas'!$G$6:$G$605,$B28,'Datos Ventas'!$D$6:$D$605,"Noviembre",'Datos Ventas'!$C$6:$C$605,$C$5) -> 0 | N28: =SUMIFS('Datos Ventas'!$I$6:$I$605,'Datos Ventas'!$G$6:$G$605,$B28,'Datos Ventas'!$D$6:$D$605,"Diciembre",'Datos Ventas'!$C$6:$C$605,$C$5) -> 0 | O28: =SUM(C28:N28) -> 525000 | P28: =IF(O15=0,0,O28/O15) -> 0.36842105
B29: =Configuración!$E$9 -> Ana Torres | C29: =SUMIFS('Datos Ventas'!$I$6:$I$605,'Datos Ventas'!$G$6:$G$605,$B29,'Datos Ventas'!$D$6:$D$605,"Enero",'Datos Ventas'!$C$6:$C$605,$C$5) -> 0 | D29: =SUMIFS('Datos Ventas'!$I$6:$I$605,'Datos Ventas'!$G$6:$G$605,$B29,'Datos Ventas'!$D$6:$D$605,"Febrero",'Datos Ventas'!$C$6:$C$605,$C$5) -> 0 | E29: =SUMIFS('Datos Ventas'!$I$6:$I$605,'Datos Ventas'!$G$6:$G$605,$B29,'Datos Ventas'!$D$6:$D$605,"Marzo",'Datos Ventas'!$C$6:$C$605,$C$5) -> 0 | F29: =SUMIFS('Datos Ventas'!$I$6:$I$605,'Datos Ventas'!$G$6:$G$605,$B29,'Datos Ventas'!$D$6:$D$605,"Abril",'Datos Ventas'!$C$6:$C$605,$C$5) -> 0 | G29: =SUMIFS('Datos Ventas'!$I$6:$I$605,'Datos Ventas'!$G$6:$G$605,$B29,'Datos Ventas'!$D$6:$D$605,"Mayo",'Datos Ventas'!$C$6:$C$605,$C$5) -> 0 | H29: =SUMIFS('Datos Ventas'!$I$6:$I$605,'Datos Ventas'!$G$6:$G$605,$B29,'Datos Ventas'!$D$6:$D$605,"Junio",'Datos Ventas'!$C$6:$C$605,$C$5) -> 0 | I29: =SUMIFS('Datos Ventas'!$I$6:$I$605,'Datos Ventas'!$G$6:$G$605,$B29,'Datos Ventas'!$D$6:$D$605,"Julio",'Datos Ventas'!$C$6:$C$605,$C$5) -> 0 | J29: =SUMIFS('Datos Ventas'!$I$6:$I$605,'Datos Ventas'!$G$6:$G$605,$B29,'Datos Ventas'!$D$6:$D$605,"Agosto",'Datos Ventas'!$C$6:$C$605,$C$5) -> 0 | K29: =SUMIFS('Datos Ventas'!$I$6:$I$605,'Datos Ventas'!$G$6:$G$605,$B29,'Datos Ventas'!$D$6:$D$605,"Septiembre",'Datos Ventas'!$C$6:$C$605,$C$5) -> 0 | L29: =SUMIFS('Datos Ventas'!$I$6:$I$605,'Datos Ventas'!$G$6:$G$605,$B29,'Datos Ventas'!$D$6:$D$605,"Octubre",'Datos Ventas'!$C$6:$C$605,$C$5) -> 0 | M29: =SUMIFS('Datos Ventas'!$I$6:$I$605,'Datos Ventas'!$G$6:$G$605,$B29,'Datos Ventas'!$D$6:$D$605,"Noviembre",'Datos Ventas'!$C$6:$C$605,$C$5) -> 0 | N29: =SUMIFS('Datos Ventas'!$I$6:$I$605,'Datos Ventas'!$G$6:$G$605,$B29,'Datos Ventas'!$D$6:$D$605,"Diciembre",'Datos Ventas'!$C$6:$C$605,$C$5) -> 0 | O29: =SUM(C29:N29) -> 0 | P29: =IF(O15=0,0,O29/O15) -> 0
B30: =Configuración!$E$10 -> Pedro Salas | C30: =SUMIFS('Datos Ventas'!$I$6:$I$605,'Datos Ventas'!$G$6:$G$605,$B30,'Datos Ventas'!$D$6:$D$605,"Enero",'Datos Ventas'!$C$6:$C$605,$C$5) -> 0 | D30: =SUMIFS('Datos Ventas'!$I$6:$I$605,'Datos Ventas'!$G$6:$G$605,$B30,'Datos Ventas'!$D$6:$D$605,"Febrero",'Datos Ventas'!$C$6:$C$605,$C$5) -> 0 | E30: =SUMIFS('Datos Ventas'!$I$6:$I$605,'Datos Ventas'!$G$6:$G$605,$B30,'Datos Ventas'!$D$6:$D$605,"Marzo",'Datos Ventas'!$C$6:$C$605,$C$5) -> 0 | F30: =SUMIFS('Datos Ventas'!$I$6:$I$605,'Datos Ventas'!$G$6:$G$605,$B30,'Datos Ventas'!$D$6:$D$605,"Abril",'Datos Ventas'!$C$6:$C$605,$C$5) -> 0 | G30: =SUMIFS('Datos Ventas'!$I$6:$I$605,'Datos Ventas'!$G$6:$G$605,$B30,'Datos Ventas'!$D$6:$D$605,"Mayo",'Datos Ventas'!$C$6:$C$605,$C$5) -> 0 | H30: =SUMIFS('Datos Ventas'!$I$6:$I$605,'Datos Ventas'!$G$6:$G$605,$B30,'Datos Ventas'!$D$6:$D$605,"Junio",'Datos Ventas'!$C$6:$C$605,$C$5) -> 0 | I30: =SUMIFS('Datos Ventas'!$I$6:$I$605,'Datos Ventas'!$G$6:$G$605,$B30,'Datos Ventas'!$D$6:$D$605,"Julio",'Datos Ventas'!$C$6:$C$605,$C$5) -> 0 | J30: =SUMIFS('Datos Ventas'!$I$6:$I$605,'Datos Ventas'!$G$6:$G$605,$B30,'Datos Ventas'!$D$6:$D$605,"Agosto",'Datos Ventas'!$C$6:$C$605,$C$5) -> 0 | K30: =SUMIFS('Datos Ventas'!$I$6:$I$605,'Datos Ventas'!$G$6:$G$605,$B30,'Datos Ventas'!$D$6:$D$605,"Septiembre",'Datos Ventas'!$C$6:$C$605,$C$5) -> 0 | L30: =SUMIFS('Datos Ventas'!$I$6:$I$605,'Datos Ventas'!$G$6:$G$605,$B30,'Datos Ventas'!$D$6:$D$605,"Octubre",'Datos Ventas'!$C$6:$C$605,$C$5) -> 0 | M30: =SUMIFS('Datos Ventas'!$I$6:$I$605,'Datos Ventas'!$G$6:$G$605,$B30,'Datos Ventas'!$D$6:$D$605,"Noviembre",'Datos Ventas'!$C$6:$C$605,$C$5) -> 0 | N30: =SUMIFS('Datos Ventas'!$I$6:$I$605,'Datos Ventas'!$G$6:$G$605,$B30,'Datos Ventas'!$D$6:$D$605,"Diciembre",'Datos Ventas'!$C$6:$C$605,$C$5) -> 0 | O30: =SUM(C30:N30) -> 0 | P30: =IF(O15=0,0,O30/O15) -> 0
B31: TOTAL VENDEDORES | C31: =SUM(C26:C30) -> 425000 | D31: =SUM(D26:D30) -> 475000 | E31: =SUM(E26:E30) -> 525000 | F31: =SUM(F26:F30) -> 0 | G31: =SUM(G26:G30) -> 0 | H31: =SUM(H26:H30) -> 0 | I31: =SUM(I26:I30) -> 0 | J31: =SUM(J26:J30) -> 0 | ... O31: =SUM(O26:O30) -> 1425000

Sheet Resumen Gastos
B2: RESUMEN DE GASTOS · Consolidado por Año
B3: Selecciona el año. Los gastos se consolidan automáticamente desde Datos Gastos con SUMIFS.
B5: Año a consultar: | C5: =Dashboard!$D$3 -> 2025 | D5: El año se controla desde la hoja Dashboard (celda D4)
B8: Categoría / Mes | C8: Ene | D8: Feb | E8: Mar | F8: Abr | G8: May | H8: Jun | I8: Jul | J8: Ago | K8: Sep | L8: Oct | M8: Nov | N8: Dic | O8: Total Anual | P8: % del Total
B9: GASTOS POR CATEGORÍA ($)
B10: =Configuración!$F$6 -> Arriendo | C10: =SUMIFS('Datos Gastos'!$G$6:$G$605,'Datos Gastos'!$E$6:$E$605,$B10,'Datos Gastos'!$D$6:$D$605,"Enero",'Datos Gastos'!$C$6:$C$605,$C$5) -> 320000 | D10: =SUMIFS('Datos Gastos'!$G$6:$G$605,'Datos Gastos'!$E$6:$E$605,$B10,'Datos Gastos'!$D$6:$D$605,"Febrero",'Datos Gastos'!$C$6:$C$605,$C$5) -> 0 | E10: =SUMIFS('Datos Gastos'!$G$6:$G$605,'Datos Gastos'!$E$6:$E$605,$B10,'Datos Gastos'!$D$6:$D$605,"Marzo",'Datos Gastos'!$C$6:$C$605,$C$5) -> 0 | F10: =SUMIFS('Datos Gastos'!$G$6:$G$605,'Datos Gastos'!$E$6:$E$605,$B10,'Datos Gastos'!$D$6:$D$605,"Abril",'Datos Gastos'!$C$6:$C$605,$C$5) -> 0 | G10: =SUMIFS('Datos Gastos'!$G$6:$G$605,'Datos Gastos'!$E$6:$E$605,$B10,'Datos Gastos'!$D$6:$D$605,"Mayo",'Datos Gastos'!$C$6:$C$605,$C$5) -> 0 | H10: =SUMIFS('Datos Gastos'!$G$6:$G$605,'Datos Gastos'!$E$6:$E$605,$B10,'Datos Gastos'!$D$6:$D$605,"Junio",'Datos Gastos'!$C$6:$C$605,$C$5) -> 0 | I10: =SUMIFS('Datos Gastos'!$G$6:$G$605,'Datos Gastos'!$E$6:$E$605,$B10,'Datos Gastos'!$D$6:$D$605,"Julio",'Datos Gastos'!$C$6:$C$605,$C$5) -> 0 | J10: =SUMIFS('Datos Gastos'!$G$6:$G$605,'Datos Gastos'!$E$6:$E$605,$B10,'Datos Gastos'!$D$6:$D$605,"Agosto",'Datos Gastos'!$C$6:$C$605,$C$5) -> 0 | K10: =SUMIFS('Datos Gastos'!$G$6:$G$605,'Datos Gastos'!$E$6:$E$605,$B10,'Datos Gastos'!$D$6:$D$605,"Septiembre",'Datos Gastos'!$C$6:$C$605,$C$5) -> 0 | L10: =SUMIFS('Datos Gastos'!$G$6:$G$605,'Datos Gastos'!$E$6:$E$605,$B10,'Datos Gastos'!$D$6:$D$605,"Octubre",'Datos Gastos'!$C$6:$C$605,$C$5) -> 0 | M10: =SUMIFS('Datos Gastos'!$G$6:$G$605,'Datos Gastos'!$E$6:$E$605,$B10,'Datos Gastos'!$D$6:$D$605,"Noviembre",'Datos Gastos'!$C$6:$C$605,$C$5) -> 0 | N10: =SUMIFS('Datos Gastos'!$G$6:$G$605,'Datos Gastos'!$E$6:$E$605,$B10,'Datos Gastos'!$D$6:$D$605,"Diciembre",'Datos Gastos'!$C$6:$C$605,$C$5) -> 0 | O10: =SUM(C10:N10) -> 320000 | P10: =IF(O16=0,0,O10/O16) -> 0.2962963
B11: =Configuración!$F$7 -> Sueldos | C11: =SUMIFS('Datos Gastos'!$G$6:$G$605,'Datos Gastos'!$E$6:$E$605,$B11,'Datos Gastos'!$D$6:$D$605,"Enero",'Datos Gastos'!$C$6:$C$605,$C$5) -> 0 | D11: =SUMIFS('Datos Gastos'!$G$6:$G$605,'Datos Gastos'!$E$6:$E$605,$B11,'Datos Gastos'!$D$6:$D$605,"Febrero",'Datos Gastos'!$C$6:$C$605,$C$5) -> 360000 | E11: =SUMIFS('Datos Gastos'!$G$6:$G$605,'Datos Gastos'!$E$6:$E$605,$B11,'Datos Gastos'!$D$6:$D$605,"Marzo",'Datos Gastos'!$C$6:$C$605,$C$5) -> 0 | F11: =SUMIFS('Datos Gastos'!$G$6:$G$605,'Datos Gastos'!$E$6:$E$605,$B11,'Datos Gastos'!$D$6:$D$605,"Abril",'Datos Gastos'!$C$6:$C$605,$C$5) -> 0 | G11: =SUMIFS('Datos Gastos'!$G$6:$G$605,'Datos Gastos'!$E$6:$E$605,$B11,'Datos Gastos'!$D$6:$D$605,"Mayo",'Datos Gastos'!$C$6:$C$605,$C$5) -> 0 | H11: =SUMIFS('Datos Gastos'!$G$6:$G$605,'Datos Gastos'!$E$6:$E$605,$B11,'Datos Gastos'!$D$6:$D$605,"Junio",'Datos Gastos'!$C$6:$C$605,$C$5) -> 0 | I11: =SUMIFS('Datos Gastos'!$G$6:$G$605,'Datos Gastos'!$E$6:$E$605,$B11,'Datos Gastos'!$D$6:$D$605,"Julio",'Datos Gastos'!$C$6:$C$605,$C$5) -> 0 | J11: =SUMIFS('Datos Gastos'!$G$6:$G$605,'Datos Gastos'!$E$6:$E$605,$B11,'Datos Gastos'!$D$6:$D$605,"Agosto",'Datos Gastos'!$C$6:$C$605,$C$5) -> 0 | K11: =SUMIFS('Datos Gastos'!$G$6:$G$605,'Datos Gastos'!$E$6:$E$605,$B11,'Datos Gastos'!$D$6:$D$605,"Septiembre",'Datos Gastos'!$C$6:$C$605,$C$5) -> 0 | L11: =SUMIFS('Datos Gastos'!$G$6:$G$605,'Datos Gastos'!$E$6:$E$605,$B11,'Datos Gastos'!$D$6:$D$605,"Octubre",'Datos Gastos'!$C$6:$C$605,$C$5) -> 0 | M11: =SUMIFS('Datos Gastos'!$G$6:$G$605,'Datos Gastos'!$E$6:$E$605,$B11,'Datos Gastos'!$D$6:$D$605,"Noviembre",'Datos Gastos'!$C$6:$C$605,$C$5) -> 0 | N11: =SUMIFS('Datos Gastos'!$G$6:$G$605,'Datos Gastos'!$E$6:$E$605,$B11,'Datos Gastos'!$D$6:$D$605,"Diciembre",'Datos Gastos'!$C$6:$C$605,$C$5) -> 0 | O11: =SUM(C11:N11) -> 360000 | P11: =IF(O16=0,0,O11/O16) -> 0.33333333
B12: =Configuración!$F$8 -> Servicios básicos | C12: =SUMIFS('Datos Gastos'!$G$6:$G$605,'Datos Gastos'!$E$6:$E$605,$B12,'Datos Gastos'!$D$6:$D$605,"Enero",'Datos Gastos'!$C$6:$C$605,$C$5) -> 0 | D12: =SUMIFS('Datos Gastos'!$G$6:$G$605,'Datos Gastos'!$E$6:$E$605,$B12,'Datos Gastos'!$D$6:$D$605,"Febrero",'Datos Gastos'!$C$6:$C$605,$C$5) -> 0 | E12: =SUMIFS('Datos Gastos'!$G$6:$G$605,'Datos Gastos'!$E$6:$E$605,$B12,'Datos Gastos'!$D$6:$D$605,"Marzo",'Datos Gastos'!$C$6:$C$605,$C$5) -> 0 | F12: =SUMIFS('Datos Gastos'!$G$6:$G$605,'Datos Gastos'!$E$6:$E$605,$B12,'Datos Gastos'!$D$6:$D$605,"Abril",'Datos Gastos'!$C$6:$C$605,$C$5) -> 0 | G12: =SUMIFS('Datos Gastos'!$G$6:$G$605,'Datos Gastos'!$E$6:$E$605,$B12,'Datos Gastos'!$D$6:$D$605,"Mayo",'Datos Gastos'!$C$6:$C$605,$C$5) -> 0 | H12: =SUMIFS('Datos Gastos'!$G$6:$G$605,'Datos Gastos'!$E$6:$E$605,$B12,'Datos Gastos'!$D$6:$D$605,"Junio",'Datos Gastos'!$C$6:$C$605,$C$5) -> 0 | I12: =SUMIFS('Datos Gastos'!$G$6:$G$605,'Datos Gastos'!$E$6:$E$605,$B12,'Datos Gastos'!$D$6:$D$605,"Julio",'Datos Gastos'!$C$6:$C$605,$C$5) -> 0 | J12: =SUMIFS('Datos Gastos'!$G$6:$G$605,'Datos Gastos'!$E$6:$E$605,$B12,'Datos Gastos'!$D$6:$D$605,"Agosto",'Datos Gastos'!$C$6:$C$605,$C$5) -> 0 | K12: =SUMIFS('Datos Gastos'!$G$6:$G$605,'Datos Gastos'!$E$6:$E$605,$B12,'Datos Gastos'!$D$6:$D$605,"Septiembre",'Datos Gastos'!$C$6:$C$605,$C$5) -> 0 | L12: =SUMIFS('Datos Gastos'!$G$6:$G$605,'Datos Gastos'!$E$6:$E$605,$B12,'Datos Gastos'!$D$6:$D$605,"Octubre",'Datos Gastos'!$C$6:$C$605,$C$5) -> 0 | M12: =SUMIFS('Datos Gastos'!$G$6:$G$605,'Datos Gastos'!$E$6:$E$605,$B12,'Datos Gastos'!$D$6:$D$605,"Noviembre",'Datos Gastos'!$C$6:$C$605,$C$5) -> 0 | N12: =SUMIFS('Datos Gastos'!$G$6:$G$605,'Datos Gastos'!$E$6:$E$605,$B12,'Datos Gastos'!$D$6:$D$605,"Diciembre",'Datos Gastos'!$C$6:$C$605,$C$5) -> 0 | O12: =SUM(C12:N12) -> 0 | P12: =IF(O16=0,0,O12/O16) -> 0
B13: =Configuración!$F$9 -> Insumos | C13: =SUMIFS('Datos Gastos'!$G$6:$G$605,'Datos Gastos'!$E$6:$E$605,$B13,'Datos Gastos'!$D$6:$D$605,"Enero",'Datos Gastos'!$C$6:$C$605,$C$5) -> 0 | D13: =SUMIFS('Datos Gastos'!$G$6:$G$605,'Datos Gastos'!$E$6:$E$605,$B13,'Datos Gastos'!$D$6:$D$605,"Febrero",'Datos Gastos'!$C$6:$C$605,$C$5) -> 0 | E13: =SUMIFS('Datos Gastos'!$G$6:$G$605,'Datos Gastos'!$E$6:$E$605,$B13,'Datos Gastos'!$D$6:$D$605,"Marzo",'Datos Gastos'!$C$6:$C$605,$C$5) -> 400000 | F13: =SUMIFS('Datos Gastos'!$G$6:$G$605,'Datos Gastos'!$E$6:$E$605,$B13,'Datos Gastos'!$D$6:$D$605,"Abril",'Datos Gastos'!$C$6:$C$605,$C$5) -> 0 | G13: =SUMIFS('Datos Gastos'!$G$6:$G$605,'Datos Gastos'!$E$6:$E$605,$B13,'Datos Gastos'!$D$6:$D$605,"Mayo",'Datos Gastos'!$C$6:$C$605,$C$5) -> 0 | H13: =SUMIFS('Datos Gastos'!$G$6:$G$605,'Datos Gastos'!$E$6:$E$605,$B13,'Datos Gastos'!$D$6:$D$605,"Junio",'Datos Gastos'!$C$6:$C$605,$C$5) -> 0 | I13: =SUMIFS('Datos Gastos'!$G$6:$G$605,'Datos Gastos'!$E$6:$E$605,$B13,'Datos Gastos'!$D$6:$D$605,"Julio",'Datos Gastos'!$C$6:$C$605,$C$5) -> 0 | J13: =SUMIFS('Datos Gastos'!$G$6:$G$605,'Datos Gastos'!$E$6:$E$605,$B13,'Datos Gastos'!$D$6:$D$605,"Agosto",'Datos Gastos'!$C$6:$C$605,$C$5) -> 0 | K13: =SUMIFS('Datos Gastos'!$G$6:$G$605,'Datos Gastos'!$E$6:$E$605,$B13,'Datos Gastos'!$D$6:$D$605,"Septiembre",'Datos Gastos'!$C$6:$C$605,$C$5) -> 0 | L13: =SUMIFS('Datos Gastos'!$G$6:$G$605,'Datos Gastos'!$E$6:$E$605,$B13,'Datos Gastos'!$D$6:$D$605,"Octubre",'Datos Gastos'!$C$6:$C$605,$C$5) -> 0 | M13: =SUMIFS('Datos Gastos'!$G$6:$G$605,'Datos Gastos'!$E$6:$E$605,$B13,'Datos Gastos'!$D$6:$D$605,"Noviembre",'Datos Gastos'!$C$6:$C$605,$C$5) -> 0 | N13: =SUMIFS('Datos Gastos'!$G$6:$G$605,'Datos Gastos'!$E$6:$E$605,$B13,'Datos Gastos'!$D$6:$D$605,"Diciembre",'Datos Gastos'!$C$6:$C$605,$C$5) -> 0 | O13: =SUM(C13:N13) -> 400000 | P13: =IF(O16=0,0,O13/O16) -> 0.37037037
B14: =Configuración!$F$10 -> Publicidad | C14: =SUMIFS('Datos Gastos'!$G$6:$G$605,'Datos Gastos'!$E$6:$E$605,$B14,'Datos Gastos'!$D$6:$D$605,"Enero",'Datos Gastos'!$C$6:$C$605,$C$5) -> 0 | D14: =SUMIFS('Datos Gastos'!$G$6:$G$605,'Datos Gastos'!$E$6:$E$605,$B14,'Datos Gastos'!$D$6:$D$605,"Febrero",'Datos Gastos'!$C$6:$C$605,$C$5) -> 0 | E14: =SUMIFS('Datos Gastos'!$G$6:$G$605,'Datos Gastos'!$E$6:$E$605,$B14,'Datos Gastos'!$D$6:$D$605,"Marzo",'Datos Gastos'!$C$6:$C$605,$C$5) -> 0 | F14: =SUMIFS('Datos Gastos'!$G$6:$G$605,'Datos Gastos'!$E$6:$E$605,$B14,'Datos Gastos'!$D$6:$D$605,"Abril",'Datos Gastos'!$C$6:$C$605,$C$5) -> 0 | G14: =SUMIFS('Datos Gastos'!$G$6:$G$605,'Datos Gastos'!$E$6:$E$605,$B14,'Datos Gastos'!$D$6:$D$605,"Mayo",'Datos Gastos'!$C$6:$C$605,$C$5) -> 0 | H14: =SUMIFS('Datos Gastos'!$G$6:$G$605,'Datos Gastos'!$E$6:$E$605,$B14,'Datos Gastos'!$D$6:$D$605,"Junio",'Datos Gastos'!$C$6:$C$605,$C$5) -> 0 | I14: =SUMIFS('Datos Gastos'!$G$6:$G$605,'Datos Gastos'!$E$6:$E$605,$B14,'Datos Gastos'!$D$6:$D$605,"Julio",'Datos Gastos'!$C$6:$C$605,$C$5) -> 0 | J14: =SUMIFS('Datos Gastos'!$G$6:$G$605,'Datos Gastos'!$E$6:$E$605,$B14,'Datos Gastos'!$D$6:$D$605,"Agosto",'Datos Gastos'!$C$6:$C$605,$C$5) -> 0 | K14: =SUMIFS('Datos Gastos'!$G$6:$G$605,'Datos Gastos'!$E$6:$E$605,$B14,'Datos Gastos'!$D$6:$D$605,"Septiembre",'Datos Gastos'!$C$6:$C$605,$C$5) -> 0 | L14: =SUMIFS('Datos Gastos'!$G$6:$G$605,'Datos Gastos'!$E$6:$E$605,$B14,'Datos Gastos'!$D$6:$D$605,"Octubre",'Datos Gastos'!$C$6:$C$605,$C$5) -> 0 | M14: =SUMIFS('Datos Gastos'!$G$6:$G$605,'Datos Gastos'!$E$6:$E$605,$B14,'Datos Gastos'!$D$6:$D$605,"Noviembre",'Datos Gastos'!$C$6:$C$605,$C$5) -> 0 | N14: =SUMIFS('Datos Gastos'!$G$6:$G$605,'Datos Gastos'!$E$6:$E$605,$B14,'Datos Gastos'!$D$6:$D$605,"Diciembre",'Datos Gastos'!$C$6:$C$605,$C$5) -> 0 | O14: =SUM(C14:N14) -> 0 | P14: =IF(O16=0,0,O14/O16) -> 0
B15: =Configuración!$F$11 -> Otros gastos | C15: =SUMIFS('Datos Gastos'!$G$6:$G$605,'Datos Gastos'!$E$6:$E$605,$B15,'Datos Gastos'!$D$6:$D$605,"Enero",'Datos Gastos'!$C$6:$C$605,$C$5) -> 0 | D15: =SUMIFS('Datos Gastos'!$G$6:$G$605,'Datos Gastos'!$E$6:$E$605,$B15,'Datos Gastos'!$D$6:$D$605,"Febrero",'Datos Gastos'!$C$6:$C$605,$C$5) -> 0 | E15: =SUMIFS('Datos Gastos'!$G$6:$G$605,'Datos Gastos'!$E$6:$E$605,$B15,'Datos Gastos'!$D$6:$D$605,"Marzo",'Datos Gastos'!$C$6:$C$605,$C$5) -> 0 | F15: =SUMIFS('Datos Gastos'!$G$6:$G$605,'Datos Gastos'!$E$6:$E$605,$B15,'Datos Gastos'!$D$6:$D$605,"Abril",'Datos Gastos'!$C$6:$C$605,$C$5) -> 0 | G15: =SUMIFS('Datos Gastos'!$G$6:$G$605,'Datos Gastos'!$E$6:$E$605,$B15,'Datos Gastos'!$D$6:$D$605,"Mayo",'Datos Gastos'!$C$6:$C$605,$C$5) -> 0 | H15: =SUMIFS('Datos Gastos'!$G$6:$G$605,'Datos Gastos'!$E$6:$E$605,$B15,'Datos Gastos'!$D$6:$D$605,"Junio",'Datos Gastos'!$C$6:$C$605,$C$5) -> 0 | I15: =SUMIFS('Datos Gastos'!$G$6:$G$605,'Datos Gastos'!$E$6:$E$605,$B15,'Datos Gastos'!$D$6:$D$605,"Julio",'Datos Gastos'!$C$6:$C$605,$C$5) -> 0 | J15: =SUMIFS('Datos Gastos'!$G$6:$G$605,'Datos Gastos'!$E$6:$E$605,$B15,'Datos Gastos'!$D$6:$D$605,"Agosto",'Datos Gastos'!$C$6:$C$605,$C$5) -> 0 | K15: =SUMIFS('Datos Gastos'!$G$6:$G$605,'Datos Gastos'!$E$6:$E$605,$B15,'Datos Gastos'!$D$6:$D$605,"Septiembre",'Datos Gastos'!$C$6:$C$605,$C$5) -> 0 | L15: =SUMIFS('Datos Gastos'!$G$6:$G$605,'Datos Gastos'!$E$6:$E$605,$B15,'Datos Gastos'!$D$6:$D$605,"Octubre",'Datos Gastos'!$C$6:$C$605,$C$5) -> 0 | M15: =SUMIFS('Datos Gastos'!$G$6:$G$605,'Datos Gastos'!$E$6:$E$605,$B15,'Datos Gastos'!$D$6:$D$605,"Noviembre",'Datos Gastos'!$C$6:$C$605,$C$5) -> 0 | N15: =SUMIFS('Datos Gastos'!$G$6:$G$605,'Datos Gastos'!$E$6:$E$605,$B15,'Datos Gastos'!$D$6:$D$605,"Diciembre",'Datos Gastos'!$C$6:$C$605,$C$5) -> 0 | O15: =SUM(C15:N15) -> 0 | P15: =IF(O16=0,0,O15/O16) -> 0
B16: TOTAL GASTOS | C16: =SUM(C10:C15) -> 320000 | D16: =SUM(D10:D15) -> 360000 | E16: =SUM(E10:E15) -> 400000 | F16: =SUM(F10:F15) -> 0 | G16: =SUM(G10:G15) -> 0 | H16: =SUM(H10:H15) -> 0 | I16: =SUM(I10:I15) -> 0 | J16: =SUM(J10:J15) -> 0 | ... O16: =SUM(O10:O15) -> 1080000

Sheet Dashboard
B1: DASHBOARD FINANCIERO PYME · MULTI-AÑO
B2: Resumen ejecutivo · Selecciona el año a analizar · Comparativo automático vs año anterior
B3: AÑO: | D3: 2025 | F3: ← Selecciona el año a analizar
B5: VENTAS AÑO | E5: GASTOS AÑO | H5: GANANCIA BRUTA | K5: MARGEN NETO | N5: VAR. VENTAS vs ANT. | Q5: VAR. GANANCIA vs ANT.
B6: =C49 -> 1425000 | E6: =C50 -> 1080000 | H6: =C51 -> 345000 | K6: =IF(C49=0,0,C51/C49) -> 0.24210526 | N6: =IF(C52=0,0,(C49-C52)/C52) -> 0.0021097046 | Q6: =IF(C54=0,0,(C51-C54)/C54) -> 0.0017421603
B9: VENTAS AÑO ANT. | E9: GASTOS AÑO ANT. | H9: GANANCIA AÑO ANT. | K9: VENTA PROM./MES | N9: GASTO PROM./MES | Q9: GANANCIA PROM./MES
B10: =C52 -> 1422000 | E10: =C53 -> 1077600 | H10: =C54 -> 344400 | K10: =C49/12 -> 118750 | N10: =C50/12 -> 90000 | Q10: =C51/12 -> 28750
B13: COMPARATIVO MENSUAL · AÑO SELECCIONADO vs AÑO ANTERIOR
B14: Mes | C14: Ventas | D14: Gastos | E14: Ganancia | F14: Margen % | G14: Vent. Ant. | H14: Gast. Ant. | I14: Gan. Ant. | J14: Var. Ventas | K14: Var. Gan. | L14: Estado
B15: Ene | C15: =C56 -> 425000 | D15: =D56 -> 320000 | E15: =E56 -> 105000 | F15: =IF(C15=0,0,E15/C15) -> 0.24705882 | G15: =F56 -> 424000 | H15: =G56 -> 319200 | I15: =H56 -> 104800 | J15: =IF(G15=0,0,(C15-G15)/G15) -> 0.0023584906 | K15: =IF(I15=0,0,(E15-I15)/IF(I15<0,-I15,I15)) -> 0.0019083969 | L15: =IF(E15>0,"OK","PÉRDIDA") -> OK
B16: Feb | C16: =C57 -> 475000 | D16: =D57 -> 360000 | E16: =E57 -> 115000 | F16: =IF(C16=0,0,E16/C16) -> 0.24210526 | G16: =F57 -> 474000 | H16: =G57 -> 359200 | I16: =H57 -> 114800 | J16: =IF(G16=0,0,(C16-G16)/G16) -> 0.0021097046 | K16: =IF(I16=0,0,(E16-I16)/IF(I16<0,-I16,I16)) -> 0.0017421603 | L16: =IF(E16>0,"OK","PÉRDIDA") -> OK
B17: Mar | C17: =C58 -> 525000 | D17: =D58 -> 400000 | E17: =E58 -> 125000 | F17: =IF(C17=0,0,E17/C17) -> 0.23809524 | G17: =F58 -> 524000 | H17: =G58 -> 399200 | I17: =H58 -> 124800 | J17: =IF(G17=0,0,(C17-G17)/G17) -> 0.0019083969 | K17: =IF(I17=0,0,(E17-I17)/IF(I17<0,-I17,I17)) -> 0.0016025641 | L17: =IF(E17>0,"OK","PÉRDIDA") -> OK
B18: Abr | C18: =C59 -> 0 | D18: =D59 -> 0 | E18: =E59 -> 0 | F18: =IF(C18=0,0,E18/C18) -> 0 | G18: =F59 -> 0 | H18: =G59 -> 0 | I18: =H59 -> 0 | J18: =IF(G18=0,0,(C18-G18)/G18) -> 0 | K18: =IF(I18=0,0,(E18-I18)/IF(I18<0,-I18,I18)) -> 0 | L18: =IF(E18>0,"OK","PÉRDIDA") -> PÉRDIDA
B19: May | C19: =C60 -> 0 | D19: =D60 -> 0 | E19: =E60 -> 0 | F19: =IF(C19=0,0,E19/C19) -> 0 | G19: =F60 -> 0 | H19: =G60 -> 0 | I19: =H60 -> 0 | J19: =IF(G19=0,0,(C19-G19)/G19) -> 0 | K19: =IF(I19=0,0,(E19-I19)/IF(I19<0,-I19,I19)) -> 0 | L19: =IF(E19>0,"OK","PÉRDIDA") -> PÉRDIDA
B20: Jun | C20: =C61 -> 0 | D20: =D61 -> 0 | E20: =E61 -> 0 | F20: =IF(C20=0,0,E20/C20) -> 0 | G20: =F61 -> 0 | H20: =G61 -> 0 | I20: =H61 -> 0 | J20: =IF(G20=0,0,(C20-G20)/G20) -> 0 | K20: =IF(I20=0,0,(E20-I20)/IF(I20<0,-I20,I20)) -> 0 | L20: =IF(E20>0,"OK","PÉRDIDA") -> PÉRDIDA
B21: Jul | C21: =C62 -> 0 | D21: =D62 -> 0 | E21: =E62 -> 0 | F21: =IF(C21=0,0,E21/C21) -> 0 | G21: =F62 -> 0 | H21: =G62 -> 0 | I21: =H62 -> 0 | J21: =IF(G21=0,0,(C21-G21)/G21) -> 0 | K21: =IF(I21=0,0,(E21-I21)/IF(I21<0,-I21,I21)) -> 0 | L21: =IF(E21>0,"OK","PÉRDIDA") -> PÉRDIDA
B22: Ago | C22: =C63 -> 0 | D22: =D63 -> 0 | E22: =E63 -> 0 | F22: =IF(C22=0,0,E22/C22) -> 0 | G22: =F63 -> 0 | H22: =G63 -> 0 | I22: =H63 -> 0 | J22: =IF(G22=0,0,(C22-G22)/G22) -> 0 | K22: =IF(I22=0,0,(E22-I22)/IF(I22<0,-I22,I22)) -> 0 | L22: =IF(E22>0,"OK","PÉRDIDA") -> PÉRDIDA
B23: Sep | C23: =C64 -> 0 | D23: =D64 -> 0 | E23: =E64 -> 0 | F23: =IF(C23=0,0,E23/C23) -> 0 | G23: =F64 -> 0 | H23: =G64 -> 0 | I23: =H64 -> 0 | J23: =IF(G23=0,0,(C23-G23)/G23) -> 0 | K23: =IF(I23=0,0,(E23-I23)/IF(I23<0,-I23,I23)) -> 0 | L23: =IF(E23>0,"OK","PÉRDIDA") -> PÉRDIDA
B24: Oct | C24: =C65 -> 0 | D24: =D65 -> 0 | E24: =E65 -> 0 | F24: =IF(C24=0,0,E24/C24) -> 0 | G24: =F65 -> 0 | H24: =G65 -> 0 | I24: =H65 -> 0 | J24: =IF(G24=0,0,(C24-G24)/G24) -> 0 | K24: =IF(I24=0,0,(E24-I24)/IF(I24<0,-I24,I24)) -> 0 | L24: =IF(E24>0,"OK","PÉRDIDA") -> PÉRDIDA
B25: Nov | C25: =C66 -> 0 | D25: =D66 -> 0 | E25: =E66 -> 0 | F25: =IF(C25=0,0,E25/C25) -> 0 | G25: =F66 -> 0 | H25: =G66 -> 0 | I25: =H66 -> 0 | J25: =IF(G25=0,0,(C25-G25)/G25) -> 0 | K25: =IF(I25=0,0,(E25-I25)/IF(I25<0,-I25,I25)) -> 0 | L25: =IF(E25>0,"OK","PÉRDIDA") -> PÉRDIDA
B26: Dic | C26: =C67 -> 0 | D26: =D67 -> 0 | E26: =E67 -> 0 | F26: =IF(C26=0,0,E26/C26) -> 0 | G26: =F67 -> 0 | H26: =G67 -> 0 | I26: =H67 -> 0 | J26: =IF(G26=0,0,(C26-G26)/G26) -> 0 | K26: =IF(I26=0,0,(E26-I26)/IF(I26<0,-I26,I26)) -> 0 | L26: =IF(E26>0,"OK","PÉRDIDA") -> PÉRDIDA
B27: TOTAL | C27: =SUM(C15:C26) -> 1425000 | D27: =SUM(D15:D26) -> 1080000 | E27: =SUM(E15:E26) -> 345000 | F27: =IF(C27=0,0,E27/C27) -> 0.24210526 | G27: =SUM(G15:G26) -> 1422000 | H27: =SUM(H15:H26) -> 1077600 | I27: =SUM(I15:I26) -> 344400 | J27: =IF(G27=0,0,(C27-G27)/G27) -> 0.0021097046 | K27: =IF(I27=0,0,(E27-I27)/IF(I27<0,-I27,I27)) -> 0.0017421603
C29: EVOLUCIÓN INTER-ANUAL · Resumen por año (datos de todas las tablas)
C30: Año | E30: Ventas | F30: Gastos | G30: Ganancia | H30: Margen % | I30: Crec. Ventas | J30: Crec. Ganancia
C31: 2023 | E31: =SUMIFS('Datos Ventas'!$I$6:$I$605,'Datos Ventas'!$C$6:$C$605,C31) -> 1419000 | F31: =SUMIFS('Datos Gastos'!$G$6:$G$605,'Datos Gastos'!$C$6:$C$605,C31) -> 1075200 | G31: =E31-F31 -> 343800 | H31: =IF(E31=0,0,G31/E31) -> 0.2422833 | I31: - | J31: -
C32: 2024 | E32: =SUMIFS('Datos Ventas'!$I$6:$I$605,'Datos Ventas'!$C$6:$C$605,C32) -> 1422000 | F32: =SUMIFS('Datos Gastos'!$G$6:$G$605,'Datos Gastos'!$C$6:$C$605,C32) -> 1077600 | G32: =E32-F32 -> 344400 | H32: =IF(E32=0,0,G32/E32) -> 0.24219409 | I32: =IF(E31=0,0,(E32-E31)/E31) -> 0.0021141649 | J32: =IF(G31=0,0,(G32-G31)/IF(G31<0,-G31,G31)) -> 0.0017452007
C33: 2025 | E33: =SUMIFS('Datos Ventas'!$I$6:$I$605,'Datos Ventas'!$C$6:$C$605,C33) -> 1425000 | F33: =SUMIFS('Datos Gastos'!$G$6:$G$605,'Datos Gastos'!$C$6:$C$605,C33) -> 1080000 | G33: =E33-F33 -> 345000 | H33: =IF(E33=0,0,G33/E33) -> 0.24210526 | I33: =IF(E32=0,0,(E33-E32)/E32) -> 0.0021097046 | J33: =IF(G32=0,0,(G33-G32)/IF(G32<0,-G32,G32)) -> 0.0017421603
C34: 2026 | E34: =SUMIFS('Datos Ventas'!$I$6:$I$605,'Datos Ventas'!$C$6:$C$605,C34) -> 0 | F34: =SUMIFS('Datos Gastos'!$G$6:$G$605,'Datos Gastos'!$C$6:$C$605,C34) -> 0 | G34: =E34-F34 -> 0 | H34: =IF(E34=0,0,G34/E34) -> 0 | I34: =IF(E33=0,0,(E34-E33)/E33) -> -1 | J34: =IF(G33=0,0,(G34-G33)/IF(G33<0,-G33,G33)) -> -1
C35: 2027 | E35: =SUMIFS('Datos Ventas'!$I$6:$I$605,'Datos Ventas'!$C$6:$C$605,C35) -> 0 | F35: =SUMIFS('Datos Gastos'!$G$6:$G$605,'Datos Gastos'!$C$6:$C$605,C35) -> 0 | G35: =E35-F35 -> 0 | H35: =IF(E35=0,0,G35/E35) -> 0 | I35: =IF(E34=0,0,(E35-E34)/E34) -> 0 | J35: =IF(G34=0,0,(G35-G34)/IF(G34<0,-G34,G34)) -> 0
B49: VENTAS_YR | C49: =SUMIFS('Datos Ventas'!$I$6:$I$605,'Datos Ventas'!$C$6:$C$605,$D$3) -> 1425000
B50: GASTOS_YR | C50: =SUMIFS('Datos Gastos'!$G$6:$G$605,'Datos Gastos'!$C$6:$C$605,$D$3) -> 1080000
B51: GANANCIA_YR | C51: =C49-C50 -> 345000
B52: VENTAS_PREV | C52: =SUMIFS('Datos Ventas'!$I$6:$I$605,'Datos Ventas'!$C$6:$C$605,$D$3-1) -> 1422000
B53: GASTOS_PREV | C53: =SUMIFS('Datos Gastos'!$G$6:$G$605,'Datos Gastos'!$C$6:$C$605,$D$3-1) -> 1077600
B54: GANANCIA_PREV | C54: =C52-C53 -> 344400
B56: Enero | C56: =SUMIFS('Datos Ventas'!$I$6:$I$605,'Datos Ventas'!$C$6:$C$605,$D$3,'Datos Ventas'!$D$6:$D$605,"Enero") -> 425000 | D56: =SUMIFS('Datos Gastos'!$G$6:$G$605,'Datos Gastos'!$C$6:$C$605,$D$3,'Datos Gastos'!$D$6:$D$605,"Enero") -> 320000 | E56: =C56-D56 -> 105000 | F56: =SUMIFS('Datos Ventas'!$I$6:$I$605,'Datos Ventas'!$C$6:$C$605,$D$3-1,'Datos Ventas'!$D$6:$D$605,"Enero") -> 424000 | G56: =SUMIFS('Datos Gastos'!$G$6:$G$605,'Datos Gastos'!$C$6:$C$605,$D$3-1,'Datos Gastos'!$D$6:$D$605,"Enero") -> 319200 | H56: =F56-G56 -> 104800
B57: Febrero | C57: =SUMIFS('Datos Ventas'!$I$6:$I$605,'Datos Ventas'!$C$6:$C$605,$D$3,'Datos Ventas'!$D$6:$D$605,"Febrero") -> 475000 | D57: =SUMIFS('Datos Gastos'!$G$6:$G$605,'Datos Gastos'!$C$6:$C$605,$D$3,'Datos Gastos'!$D$6:$D$605,"Febrero") -> 360000 | E57: =C57-D57 -> 115000 | F57: =SUMIFS('Datos Ventas'!$I$6:$I$605,'Datos Ventas'!$C$6:$C$605,$D$3-1,'Datos Ventas'!$D$6:$D$605,"Febrero") -> 474000 | G57: =SUMIFS('Datos Gastos'!$G$6:$G$605,'Datos Gastos'!$C$6:$C$605,$D$3-1,'Datos Gastos'!$D$6:$D$605,"Febrero") -> 359200 | H57: =F57-G57 -> 114800
B58: Marzo | C58: =SUMIFS('Datos Ventas'!$I$6:$I$605,'Datos Ventas'!$C$6:$C$605,$D$3,'Datos Ventas'!$D$6:$D$605,"Marzo") -> 525000 | D58: =SUMIFS('Datos Gastos'!$G$6:$G$605,'Datos Gastos'!$C$6:$C$605,$D$3,'Datos Gastos'!$D$6:$D$605,"Marzo") -> 400000 | E58: =C58-D58 -> 125000 | F58: =SUMIFS('Datos Ventas'!$I$6:$I$605,'Datos Ventas'!$C$6:$C$605,$D$3-1,'Datos Ventas'!$D$6:$D$605,"Marzo") -> 524000 | G58: =SUMIFS('Datos Gastos'!$G$6:$G$605,'Datos Gastos'!$C$6:$C$605,$D$3-1,'Datos Gastos'!$D$6:$D$605,"Marzo") -> 399200 | H58: =F58-G58 -> 124800
B59: Abril | C59: =SUMIFS('Datos Ventas'!$I$6:$I$605,'Datos Ventas'!$C$6:$C$605,$D$3,'Datos Ventas'!$D$6:$D$605,"Abril") -> 0 | D59: =SUMIFS('Datos Gastos'!$G$6:$G$605,'Datos Gastos'!$C$6:$C$605,$D$3,'Datos Gastos'!$D$6:$D$605,"Abril") -> 0 | E59: =C59-D59 -> 0 | F59: =SUMIFS('Datos Ventas'!$I$6:$I$605,'Datos Ventas'!$C$6:$C$605,$D$3-1,'Datos Ventas'!$D$6:$D$605,"Abril") -> 0 | G59: =SUMIFS('Datos Gastos'!$G$6:$G$605,'Datos Gastos'!$C$6:$C$605,$D$3-1,'Datos Gastos'!$D$6:$D$605,"Abril") -> 0 | H59: =F59-G59 -> 0
B60: Mayo | C60: =SUMIFS('Datos Ventas'!$I$6:$I$605,'Datos Ventas'!$C$6:$C$605,$D$3,'Datos Ventas'!$D$6:$D$605,"Mayo") -> 0 | D60: =SUMIFS('Datos Gastos'!$G$6:$G$605,'Datos Gastos'!$C$6:$C$605,$D$3,'Datos Gastos'!$D$6:$D$605,"Mayo") -> 0 | E60: =C60-D60 -> 0 | F60: =SUMIFS('Datos Ventas'!$I$6:$I$605,'Datos Ventas'!$C$6:$C$605,$D$3-1,'Datos Ventas'!$D$6:$D$605,"Mayo") -> 0 | G60: =SUMIFS('Datos Gastos'!$G$6:$G$605,'Datos Gastos'!$C$6:$C$605,$D$3-1,'Datos Gastos'!$D$6:$D$605,"Mayo") -> 0 | H60: =F60-G60 -> 0
...

Sheet Gráficos
B2: GRÁFICOS DEL DASHBOARD · Visualización Multi-Año
B4: MES | C4: VENTAS | D4: GASTOS | E4: GANANCIA | F4: VENT ANT | G4: GAST ANT | I4: PRODUCTO | J4: VENTAS | L4: REGIÓN | M4: VENTAS | O4: AÑO | P4: VENTAS | Q4: GASTOS | R4: GANANCIA
B5: Ene | C5: =Dashboard!C56 -> 425000 | D5: =Dashboard!D56 -> 320000 | E5: =Dashboard!E56 -> 105000 | F5: =Dashboard!F56 -> 424000 | G5: =Dashboard!G56 -> 319200 | I5: =Configuración!$B$6 -> Producto A | J5: ='Resumen Ventas'!O10 -> 425000 | L5: =Configuración!$D$6 -> Norte | M5: ='Resumen Ventas'!O18 -> 425000 | O5: 2023 | P5: =Dashboard!E31 -> 1419000 | Q5: =Dashboard!F31 -> 1075200 | R5: =Dashboard!G31 -> 343800
B6: Feb | C6: =Dashboard!C57 -> 475000 | D6: =Dashboard!D57 -> 360000 | E6: =Dashboard!E57 -> 115000 | F6: =Dashboard!F57 -> 474000 | G6: =Dashboard!G57 -> 359200 | I6: =Configuración!$B$7 -> Producto B | J6: ='Resumen Ventas'!O11 -> 475000 | L6: =Configuración!$D$7 -> Sur | M6: ='Resumen Ventas'!O19 -> 475000 | O6: 2024 | P6: =Dashboard!E32 -> 1422000 | Q6: =Dashboard!F32 -> 1077600 | R6: =Dashboard!G32 -> 344400
B7: Mar | C7: =Dashboard!C58 -> 525000 | D7: =Dashboard!D58 -> 400000 | E7: =Dashboard!E58 -> 125000 | F7: =Dashboard!F58 -> 524000 | G7: =Dashboard!G58 -> 399200 | I7: =Configuración!$B$8 -> Producto C | J7: ='Resumen Ventas'!O12 -> 525000 | L7: =Configuración!$D$8 -> Centro | M7: ='Resumen Ventas'!O20 -> 525000 | O7: 2025 | P7: =Dashboard!E33 -> 1425000 | Q7: =Dashboard!F33 -> 1080000 | R7: =Dashboard!G33 -> 345000
B8: Abr | C8: =Dashboard!C59 -> 0 | D8: =Dashboard!D59 -> 0 | E8: =Dashboard!E59 -> 0 | F8: =Dashboard!F59 -> 0 | G8: =Dashboard!G59 -> 0 | I8: =Configuración!$B$9 -> Producto D | J8: ='Resumen Ventas'!O13 -> 0 | L8: =Configuración!$D$9 -> Oriente | M8: ='Resumen Ventas'!O21 -> 0 | O8: 2026 | P8: =Dashboard!E34 -> 0 | Q8: =Dashboard!F34 -> 0 | R8: =Dashboard!G34 -> 0
B9: May | C9: =Dashboard!C60 -> 0 | D9: =Dashboard!D60 -> 0 | E9: =Dashboard!E60 -> 0 | F9: =Dashboard!F60 -> 0 | G9: =Dashboard!G60 -> 0 | I9: =Configuración!$B$10 -> Producto E | J9: ='Resumen Ventas'!O14 -> 0 | L9: =Configuración!$D$10 -> Occidente | M9: ='Resumen Ventas'!O22 -> 0 | O9: 2027 | P9: =Dashboard!E35 -> 0 | Q9: =Dashboard!F35 -> 0 | R9: =Dashboard!G35 -> 0
B10: Jun | C10: =Dashboard!C61 -> 0 | D10: =Dashboard!D61 -> 0 | E10: =Dashboard!E61 -> 0 | F10: =Dashboard!F61 -> 0 | G10: =Dashboard!G61 -> 0
B11: Jul | C11: =Dashboard!C62 -> 0 | D11: =Dashboard!D62 -> 0 | E11: =Dashboard!E62 -> 0 | F11: =Dashboard!F62 -> 0 | G11: =Dashboard!G62 -> 0
B12: Ago | C12: =Dashboard!C63 -> 0 | D12: =Dashboard!D63 -> 0 | E12: =Dashboard!E63 -> 0 | F12: =Dashboard!F63 -> 0 | G12: =Dashboard!G63 -> 0
B13: Sep | C13: =Dashboard!C64 -> 0 | D13: =Dashboard!D64 -> 0 | E13: =Dashboard!E64 -> 0 | F13: =Dashboard!F64 -> 0 | G13: =Dashboard!G64 -> 0
B14: Oct | C14: =Dashboard!C65 -> 0 | D14: =Dashboard!D65 -> 0 | E14: =Dashboard!E65 -> 0 | F14: =Dashboard!F65 -> 0 | G14: =Dashboard!G65 -> 0
B15: Nov | C15: =Dashboard!C66 -> 0 | D15: =Dashboard!D66 -> 0 | E15: =Dashboard!E66 -> 0 | F15: =Dashboard!F66 -> 0 | G15: =Dashboard!G66 -> 0
B16: Dic | C16: =Dashboard!C67 -> 0 | D16: =Dashboard!D67 -> 0 | E16: =Dashboard!E67 -> 0 | F16: =Dashboard!F67 -> 0 | G16: =Dashboard!G67 -> 0
